[2024-09-25T21:57:40.340+0000] {processor.py:186} INFO - Started process (PID=68) to work on /opt/airflow/dags/covid_gdp_dag.py
[2024-09-25T21:57:40.349+0000] {processor.py:914} INFO - Processing file /opt/airflow/dags/covid_gdp_dag.py for tasks to queue
[2024-09-25T21:57:40.386+0000] {logging_mixin.py:190} INFO - [2024-09-25T21:57:40.384+0000] {dagbag.py:588} INFO - Filling up the DagBag from /opt/airflow/dags/covid_gdp_dag.py
[2024-09-25T21:57:40.557+0000] {logging_mixin.py:190} INFO - [2024-09-25T21:57:40.542+0000] {dagbag.py:387} ERROR - Failed to import: /opt/airflow/dags/covid_gdp_dag.py
Traceback (most recent call last):
  File "/home/airflow/.local/lib/python3.12/site-packages/airflow/models/dagbag.py", line 383, in parse
    loader.exec_module(new_module)
  File "<frozen importlib._bootstrap_external>", line 995, in exec_module
  File "<frozen importlib._bootstrap>", line 488, in _call_with_frames_removed
  File "/opt/airflow/dags/covid_gdp_dag.py", line 7, in <module>
    from common_data_loader import download_world_bank_data, download_kaggle_dataset, load_covid_data, load_gdp_data
  File "/opt/airflow/dags/common_data_loader.py", line 3, in <module>
    import kaggle
ModuleNotFoundError: No module named 'kaggle'
[2024-09-25T21:57:40.579+0000] {logging_mixin.py:190} WARNING - /opt/airflow/dags/covid_gdp_dag.py:33 SyntaxWarning: invalid escape sequence '\D'
[2024-09-25T21:57:40.582+0000] {logging_mixin.py:190} WARNING - /opt/airflow/dags/covid_gdp_dag.py:33 SyntaxWarning: invalid escape sequence '\D'
[2024-09-25T21:57:40.584+0000] {logging_mixin.py:190} WARNING - /opt/airflow/dags/covid_gdp_dag.py:43 SyntaxWarning: invalid escape sequence '\D'
[2024-09-25T21:57:40.587+0000] {logging_mixin.py:190} WARNING - /opt/airflow/dags/common_data_loader.py:104 SyntaxWarning: invalid escape sequence '\D'
[2024-09-25T21:57:40.590+0000] {logging_mixin.py:190} WARNING - /opt/airflow/dags/common_data_loader.py:105 SyntaxWarning: invalid escape sequence '\D'
[2024-09-25T21:57:40.592+0000] {logging_mixin.py:190} WARNING - /opt/airflow/dags/common_data_loader.py:116 SyntaxWarning: invalid escape sequence '\D'
[2024-09-25T21:57:40.594+0000] {processor.py:927} WARNING - No viable dags retrieved from /opt/airflow/dags/covid_gdp_dag.py
[2024-09-25T21:57:40.882+0000] {processor.py:208} INFO - Processing /opt/airflow/dags/covid_gdp_dag.py took 0.588 seconds
[2024-09-25T21:58:11.104+0000] {processor.py:186} INFO - Started process (PID=131) to work on /opt/airflow/dags/covid_gdp_dag.py
[2024-09-25T21:58:11.106+0000] {processor.py:914} INFO - Processing file /opt/airflow/dags/covid_gdp_dag.py for tasks to queue
[2024-09-25T21:58:11.109+0000] {logging_mixin.py:190} INFO - [2024-09-25T21:58:11.109+0000] {dagbag.py:588} INFO - Filling up the DagBag from /opt/airflow/dags/covid_gdp_dag.py
[2024-09-25T21:58:11.150+0000] {logging_mixin.py:190} INFO - [2024-09-25T21:58:11.138+0000] {dagbag.py:387} ERROR - Failed to import: /opt/airflow/dags/covid_gdp_dag.py
Traceback (most recent call last):
  File "/home/airflow/.local/lib/python3.12/site-packages/airflow/models/dagbag.py", line 383, in parse
    loader.exec_module(new_module)
  File "<frozen importlib._bootstrap_external>", line 995, in exec_module
  File "<frozen importlib._bootstrap>", line 488, in _call_with_frames_removed
  File "/opt/airflow/dags/covid_gdp_dag.py", line 7, in <module>
    from common_data_loader import download_world_bank_data, download_kaggle_dataset, load_covid_data, load_gdp_data
  File "/opt/airflow/dags/common_data_loader.py", line 3, in <module>
    import kaggle
ModuleNotFoundError: No module named 'kaggle'
[2024-09-25T21:58:11.152+0000] {processor.py:927} WARNING - No viable dags retrieved from /opt/airflow/dags/covid_gdp_dag.py
[2024-09-25T21:58:11.179+0000] {processor.py:208} INFO - Processing /opt/airflow/dags/covid_gdp_dag.py took 0.081 seconds
[2024-09-25T21:58:41.874+0000] {processor.py:186} INFO - Started process (PID=194) to work on /opt/airflow/dags/covid_gdp_dag.py
[2024-09-25T21:58:41.876+0000] {processor.py:914} INFO - Processing file /opt/airflow/dags/covid_gdp_dag.py for tasks to queue
[2024-09-25T21:58:41.891+0000] {logging_mixin.py:190} INFO - [2024-09-25T21:58:41.890+0000] {dagbag.py:588} INFO - Filling up the DagBag from /opt/airflow/dags/covid_gdp_dag.py
[2024-09-25T21:58:41.937+0000] {logging_mixin.py:190} INFO - [2024-09-25T21:58:41.928+0000] {dagbag.py:387} ERROR - Failed to import: /opt/airflow/dags/covid_gdp_dag.py
Traceback (most recent call last):
  File "/home/airflow/.local/lib/python3.12/site-packages/airflow/models/dagbag.py", line 383, in parse
    loader.exec_module(new_module)
  File "<frozen importlib._bootstrap_external>", line 995, in exec_module
  File "<frozen importlib._bootstrap>", line 488, in _call_with_frames_removed
  File "/opt/airflow/dags/covid_gdp_dag.py", line 7, in <module>
    from common_data_loader import download_world_bank_data, download_kaggle_dataset, load_covid_data, load_gdp_data
  File "/opt/airflow/dags/common_data_loader.py", line 3, in <module>
    import kaggle
ModuleNotFoundError: No module named 'kaggle'
[2024-09-25T21:58:41.940+0000] {processor.py:927} WARNING - No viable dags retrieved from /opt/airflow/dags/covid_gdp_dag.py
[2024-09-25T21:58:41.997+0000] {processor.py:208} INFO - Processing /opt/airflow/dags/covid_gdp_dag.py took 0.168 seconds
[2024-09-25T21:59:12.044+0000] {processor.py:186} INFO - Started process (PID=257) to work on /opt/airflow/dags/covid_gdp_dag.py
[2024-09-25T21:59:12.046+0000] {processor.py:914} INFO - Processing file /opt/airflow/dags/covid_gdp_dag.py for tasks to queue
[2024-09-25T21:59:12.049+0000] {logging_mixin.py:190} INFO - [2024-09-25T21:59:12.048+0000] {dagbag.py:588} INFO - Filling up the DagBag from /opt/airflow/dags/covid_gdp_dag.py
[2024-09-25T21:59:12.076+0000] {logging_mixin.py:190} INFO - [2024-09-25T21:59:12.069+0000] {dagbag.py:387} ERROR - Failed to import: /opt/airflow/dags/covid_gdp_dag.py
Traceback (most recent call last):
  File "/home/airflow/.local/lib/python3.12/site-packages/airflow/models/dagbag.py", line 383, in parse
    loader.exec_module(new_module)
  File "<frozen importlib._bootstrap_external>", line 995, in exec_module
  File "<frozen importlib._bootstrap>", line 488, in _call_with_frames_removed
  File "/opt/airflow/dags/covid_gdp_dag.py", line 7, in <module>
    from common_data_loader import download_world_bank_data, download_kaggle_dataset, load_covid_data, load_gdp_data
  File "/opt/airflow/dags/common_data_loader.py", line 3, in <module>
    import kaggle
ModuleNotFoundError: No module named 'kaggle'
[2024-09-25T21:59:12.078+0000] {processor.py:927} WARNING - No viable dags retrieved from /opt/airflow/dags/covid_gdp_dag.py
[2024-09-25T21:59:12.101+0000] {processor.py:208} INFO - Processing /opt/airflow/dags/covid_gdp_dag.py took 0.062 seconds
[2024-09-25T21:59:42.269+0000] {processor.py:186} INFO - Started process (PID=320) to work on /opt/airflow/dags/covid_gdp_dag.py
[2024-09-25T21:59:42.270+0000] {processor.py:914} INFO - Processing file /opt/airflow/dags/covid_gdp_dag.py for tasks to queue
[2024-09-25T21:59:42.273+0000] {logging_mixin.py:190} INFO - [2024-09-25T21:59:42.273+0000] {dagbag.py:588} INFO - Filling up the DagBag from /opt/airflow/dags/covid_gdp_dag.py
[2024-09-25T21:59:42.296+0000] {logging_mixin.py:190} INFO - [2024-09-25T21:59:42.291+0000] {dagbag.py:387} ERROR - Failed to import: /opt/airflow/dags/covid_gdp_dag.py
Traceback (most recent call last):
  File "/home/airflow/.local/lib/python3.12/site-packages/airflow/models/dagbag.py", line 383, in parse
    loader.exec_module(new_module)
  File "<frozen importlib._bootstrap_external>", line 995, in exec_module
  File "<frozen importlib._bootstrap>", line 488, in _call_with_frames_removed
  File "/opt/airflow/dags/covid_gdp_dag.py", line 7, in <module>
    from common_data_loader import download_world_bank_data, download_kaggle_dataset, load_covid_data, load_gdp_data
  File "/opt/airflow/dags/common_data_loader.py", line 3, in <module>
    import kaggle
ModuleNotFoundError: No module named 'kaggle'
[2024-09-25T21:59:42.298+0000] {processor.py:927} WARNING - No viable dags retrieved from /opt/airflow/dags/covid_gdp_dag.py
[2024-09-25T21:59:42.319+0000] {processor.py:208} INFO - Processing /opt/airflow/dags/covid_gdp_dag.py took 0.054 seconds
[2024-09-25T22:00:12.445+0000] {processor.py:186} INFO - Started process (PID=383) to work on /opt/airflow/dags/covid_gdp_dag.py
[2024-09-25T22:00:12.446+0000] {processor.py:914} INFO - Processing file /opt/airflow/dags/covid_gdp_dag.py for tasks to queue
[2024-09-25T22:00:12.449+0000] {logging_mixin.py:190} INFO - [2024-09-25T22:00:12.448+0000] {dagbag.py:588} INFO - Filling up the DagBag from /opt/airflow/dags/covid_gdp_dag.py
[2024-09-25T22:00:12.473+0000] {logging_mixin.py:190} INFO - [2024-09-25T22:00:12.466+0000] {dagbag.py:387} ERROR - Failed to import: /opt/airflow/dags/covid_gdp_dag.py
Traceback (most recent call last):
  File "/home/airflow/.local/lib/python3.12/site-packages/airflow/models/dagbag.py", line 383, in parse
    loader.exec_module(new_module)
  File "<frozen importlib._bootstrap_external>", line 995, in exec_module
  File "<frozen importlib._bootstrap>", line 488, in _call_with_frames_removed
  File "/opt/airflow/dags/covid_gdp_dag.py", line 7, in <module>
    from common_data_loader import download_world_bank_data, download_kaggle_dataset, load_covid_data, load_gdp_data
  File "/opt/airflow/dags/common_data_loader.py", line 3, in <module>
    import kaggle
ModuleNotFoundError: No module named 'kaggle'
[2024-09-25T22:00:12.476+0000] {processor.py:927} WARNING - No viable dags retrieved from /opt/airflow/dags/covid_gdp_dag.py
[2024-09-25T22:00:12.501+0000] {processor.py:208} INFO - Processing /opt/airflow/dags/covid_gdp_dag.py took 0.061 seconds
[2024-09-25T22:00:42.674+0000] {processor.py:186} INFO - Started process (PID=446) to work on /opt/airflow/dags/covid_gdp_dag.py
[2024-09-25T22:00:42.675+0000] {processor.py:914} INFO - Processing file /opt/airflow/dags/covid_gdp_dag.py for tasks to queue
[2024-09-25T22:00:42.679+0000] {logging_mixin.py:190} INFO - [2024-09-25T22:00:42.678+0000] {dagbag.py:588} INFO - Filling up the DagBag from /opt/airflow/dags/covid_gdp_dag.py
[2024-09-25T22:00:42.706+0000] {logging_mixin.py:190} INFO - [2024-09-25T22:00:42.697+0000] {dagbag.py:387} ERROR - Failed to import: /opt/airflow/dags/covid_gdp_dag.py
Traceback (most recent call last):
  File "/home/airflow/.local/lib/python3.12/site-packages/airflow/models/dagbag.py", line 383, in parse
    loader.exec_module(new_module)
  File "<frozen importlib._bootstrap_external>", line 995, in exec_module
  File "<frozen importlib._bootstrap>", line 488, in _call_with_frames_removed
  File "/opt/airflow/dags/covid_gdp_dag.py", line 7, in <module>
    from common_data_loader import download_world_bank_data, download_kaggle_dataset, load_covid_data, load_gdp_data
  File "/opt/airflow/dags/common_data_loader.py", line 3, in <module>
    import kaggle
ModuleNotFoundError: No module named 'kaggle'
[2024-09-25T22:00:42.708+0000] {processor.py:927} WARNING - No viable dags retrieved from /opt/airflow/dags/covid_gdp_dag.py
[2024-09-25T22:00:42.731+0000] {processor.py:208} INFO - Processing /opt/airflow/dags/covid_gdp_dag.py took 0.061 seconds
[2024-09-25T22:01:19.295+0000] {processor.py:186} INFO - Started process (PID=500) to work on /opt/airflow/dags/covid_gdp_dag.py
[2024-09-25T22:01:19.297+0000] {processor.py:914} INFO - Processing file /opt/airflow/dags/covid_gdp_dag.py for tasks to queue
[2024-09-25T22:01:19.301+0000] {logging_mixin.py:190} INFO - [2024-09-25T22:01:19.300+0000] {dagbag.py:588} INFO - Filling up the DagBag from /opt/airflow/dags/covid_gdp_dag.py
[2024-09-25T22:01:19.364+0000] {logging_mixin.py:190} INFO - [2024-09-25T22:01:19.348+0000] {dagbag.py:387} ERROR - Failed to import: /opt/airflow/dags/covid_gdp_dag.py
Traceback (most recent call last):
  File "/home/airflow/.local/lib/python3.12/site-packages/airflow/models/dagbag.py", line 383, in parse
    loader.exec_module(new_module)
  File "<frozen importlib._bootstrap_external>", line 995, in exec_module
  File "<frozen importlib._bootstrap>", line 488, in _call_with_frames_removed
  File "/opt/airflow/dags/covid_gdp_dag.py", line 7, in <module>
    from common_data_loader import download_world_bank_data, download_kaggle_dataset, load_covid_data, load_gdp_data
  File "/opt/airflow/dags/common_data_loader.py", line 3, in <module>
    import kaggle
ModuleNotFoundError: No module named 'kaggle'
[2024-09-25T22:01:19.370+0000] {processor.py:927} WARNING - No viable dags retrieved from /opt/airflow/dags/covid_gdp_dag.py
[2024-09-25T22:01:19.417+0000] {processor.py:208} INFO - Processing /opt/airflow/dags/covid_gdp_dag.py took 0.129 seconds
[2024-09-25T22:01:49.850+0000] {processor.py:186} INFO - Started process (PID=560) to work on /opt/airflow/dags/covid_gdp_dag.py
[2024-09-25T22:01:49.852+0000] {processor.py:914} INFO - Processing file /opt/airflow/dags/covid_gdp_dag.py for tasks to queue
[2024-09-25T22:01:49.857+0000] {logging_mixin.py:190} INFO - [2024-09-25T22:01:49.856+0000] {dagbag.py:588} INFO - Filling up the DagBag from /opt/airflow/dags/covid_gdp_dag.py
[2024-09-25T22:01:49.909+0000] {logging_mixin.py:190} INFO - [2024-09-25T22:01:49.895+0000] {dagbag.py:387} ERROR - Failed to import: /opt/airflow/dags/covid_gdp_dag.py
Traceback (most recent call last):
  File "/home/airflow/.local/lib/python3.12/site-packages/airflow/models/dagbag.py", line 383, in parse
    loader.exec_module(new_module)
  File "<frozen importlib._bootstrap_external>", line 995, in exec_module
  File "<frozen importlib._bootstrap>", line 488, in _call_with_frames_removed
  File "/opt/airflow/dags/covid_gdp_dag.py", line 7, in <module>
    from common_data_loader import download_world_bank_data, download_kaggle_dataset, load_covid_data, load_gdp_data
  File "/opt/airflow/dags/common_data_loader.py", line 3, in <module>
    import kaggle
ModuleNotFoundError: No module named 'kaggle'
[2024-09-25T22:01:49.912+0000] {processor.py:927} WARNING - No viable dags retrieved from /opt/airflow/dags/covid_gdp_dag.py
[2024-09-25T22:01:49.979+0000] {processor.py:208} INFO - Processing /opt/airflow/dags/covid_gdp_dag.py took 0.138 seconds
[2024-09-25T22:02:20.785+0000] {processor.py:186} INFO - Started process (PID=623) to work on /opt/airflow/dags/covid_gdp_dag.py
[2024-09-25T22:02:20.786+0000] {processor.py:914} INFO - Processing file /opt/airflow/dags/covid_gdp_dag.py for tasks to queue
[2024-09-25T22:02:20.789+0000] {logging_mixin.py:190} INFO - [2024-09-25T22:02:20.788+0000] {dagbag.py:588} INFO - Filling up the DagBag from /opt/airflow/dags/covid_gdp_dag.py
[2024-09-25T22:02:20.815+0000] {logging_mixin.py:190} INFO - [2024-09-25T22:02:20.808+0000] {dagbag.py:387} ERROR - Failed to import: /opt/airflow/dags/covid_gdp_dag.py
Traceback (most recent call last):
  File "/home/airflow/.local/lib/python3.12/site-packages/airflow/models/dagbag.py", line 383, in parse
    loader.exec_module(new_module)
  File "<frozen importlib._bootstrap_external>", line 995, in exec_module
  File "<frozen importlib._bootstrap>", line 488, in _call_with_frames_removed
  File "/opt/airflow/dags/covid_gdp_dag.py", line 7, in <module>
    from common_data_loader import download_world_bank_data, download_kaggle_dataset, load_covid_data, load_gdp_data
  File "/opt/airflow/dags/common_data_loader.py", line 3, in <module>
    import kaggle
ModuleNotFoundError: No module named 'kaggle'
[2024-09-25T22:02:20.817+0000] {processor.py:927} WARNING - No viable dags retrieved from /opt/airflow/dags/covid_gdp_dag.py
[2024-09-25T22:02:20.842+0000] {processor.py:208} INFO - Processing /opt/airflow/dags/covid_gdp_dag.py took 0.062 seconds
[2024-09-25T22:02:51.318+0000] {processor.py:186} INFO - Started process (PID=686) to work on /opt/airflow/dags/covid_gdp_dag.py
[2024-09-25T22:02:51.319+0000] {processor.py:914} INFO - Processing file /opt/airflow/dags/covid_gdp_dag.py for tasks to queue
[2024-09-25T22:02:51.321+0000] {logging_mixin.py:190} INFO - [2024-09-25T22:02:51.321+0000] {dagbag.py:588} INFO - Filling up the DagBag from /opt/airflow/dags/covid_gdp_dag.py
[2024-09-25T22:02:51.346+0000] {logging_mixin.py:190} INFO - [2024-09-25T22:02:51.338+0000] {dagbag.py:387} ERROR - Failed to import: /opt/airflow/dags/covid_gdp_dag.py
Traceback (most recent call last):
  File "/home/airflow/.local/lib/python3.12/site-packages/airflow/models/dagbag.py", line 383, in parse
    loader.exec_module(new_module)
  File "<frozen importlib._bootstrap_external>", line 995, in exec_module
  File "<frozen importlib._bootstrap>", line 488, in _call_with_frames_removed
  File "/opt/airflow/dags/covid_gdp_dag.py", line 7, in <module>
    from common_data_loader import download_world_bank_data, download_kaggle_dataset, load_covid_data, load_gdp_data
  File "/opt/airflow/dags/common_data_loader.py", line 3, in <module>
    import kaggle
ModuleNotFoundError: No module named 'kaggle'
[2024-09-25T22:02:51.348+0000] {processor.py:927} WARNING - No viable dags retrieved from /opt/airflow/dags/covid_gdp_dag.py
[2024-09-25T22:02:51.369+0000] {processor.py:208} INFO - Processing /opt/airflow/dags/covid_gdp_dag.py took 0.057 seconds
[2024-09-25T22:03:21.861+0000] {processor.py:186} INFO - Started process (PID=749) to work on /opt/airflow/dags/covid_gdp_dag.py
[2024-09-25T22:03:21.862+0000] {processor.py:914} INFO - Processing file /opt/airflow/dags/covid_gdp_dag.py for tasks to queue
[2024-09-25T22:03:21.865+0000] {logging_mixin.py:190} INFO - [2024-09-25T22:03:21.865+0000] {dagbag.py:588} INFO - Filling up the DagBag from /opt/airflow/dags/covid_gdp_dag.py
[2024-09-25T22:03:21.895+0000] {logging_mixin.py:190} INFO - [2024-09-25T22:03:21.886+0000] {dagbag.py:387} ERROR - Failed to import: /opt/airflow/dags/covid_gdp_dag.py
Traceback (most recent call last):
  File "/home/airflow/.local/lib/python3.12/site-packages/airflow/models/dagbag.py", line 383, in parse
    loader.exec_module(new_module)
  File "<frozen importlib._bootstrap_external>", line 995, in exec_module
  File "<frozen importlib._bootstrap>", line 488, in _call_with_frames_removed
  File "/opt/airflow/dags/covid_gdp_dag.py", line 7, in <module>
    from common_data_loader import download_world_bank_data, download_kaggle_dataset, load_covid_data, load_gdp_data
  File "/opt/airflow/dags/common_data_loader.py", line 3, in <module>
    import kaggle
ModuleNotFoundError: No module named 'kaggle'
[2024-09-25T22:03:21.897+0000] {processor.py:927} WARNING - No viable dags retrieved from /opt/airflow/dags/covid_gdp_dag.py
[2024-09-25T22:03:21.925+0000] {processor.py:208} INFO - Processing /opt/airflow/dags/covid_gdp_dag.py took 0.068 seconds
[2024-09-25T22:03:52.255+0000] {processor.py:186} INFO - Started process (PID=813) to work on /opt/airflow/dags/covid_gdp_dag.py
[2024-09-25T22:03:52.256+0000] {processor.py:914} INFO - Processing file /opt/airflow/dags/covid_gdp_dag.py for tasks to queue
[2024-09-25T22:03:52.259+0000] {logging_mixin.py:190} INFO - [2024-09-25T22:03:52.258+0000] {dagbag.py:588} INFO - Filling up the DagBag from /opt/airflow/dags/covid_gdp_dag.py
[2024-09-25T22:03:52.292+0000] {logging_mixin.py:190} INFO - [2024-09-25T22:03:52.280+0000] {dagbag.py:387} ERROR - Failed to import: /opt/airflow/dags/covid_gdp_dag.py
Traceback (most recent call last):
  File "/home/airflow/.local/lib/python3.12/site-packages/airflow/models/dagbag.py", line 383, in parse
    loader.exec_module(new_module)
  File "<frozen importlib._bootstrap_external>", line 995, in exec_module
  File "<frozen importlib._bootstrap>", line 488, in _call_with_frames_removed
  File "/opt/airflow/dags/covid_gdp_dag.py", line 7, in <module>
    from common_data_loader import download_world_bank_data, download_kaggle_dataset, load_covid_data, load_gdp_data
  File "/opt/airflow/dags/common_data_loader.py", line 3, in <module>
    import kaggle
ModuleNotFoundError: No module named 'kaggle'
[2024-09-25T22:03:52.296+0000] {processor.py:927} WARNING - No viable dags retrieved from /opt/airflow/dags/covid_gdp_dag.py
[2024-09-25T22:03:52.329+0000] {processor.py:208} INFO - Processing /opt/airflow/dags/covid_gdp_dag.py took 0.081 seconds
[2024-09-25T22:04:22.662+0000] {processor.py:186} INFO - Started process (PID=876) to work on /opt/airflow/dags/covid_gdp_dag.py
[2024-09-25T22:04:22.664+0000] {processor.py:914} INFO - Processing file /opt/airflow/dags/covid_gdp_dag.py for tasks to queue
[2024-09-25T22:04:22.670+0000] {logging_mixin.py:190} INFO - [2024-09-25T22:04:22.669+0000] {dagbag.py:588} INFO - Filling up the DagBag from /opt/airflow/dags/covid_gdp_dag.py
[2024-09-25T22:04:22.700+0000] {logging_mixin.py:190} INFO - [2024-09-25T22:04:22.693+0000] {dagbag.py:387} ERROR - Failed to import: /opt/airflow/dags/covid_gdp_dag.py
Traceback (most recent call last):
  File "/home/airflow/.local/lib/python3.12/site-packages/airflow/models/dagbag.py", line 383, in parse
    loader.exec_module(new_module)
  File "<frozen importlib._bootstrap_external>", line 995, in exec_module
  File "<frozen importlib._bootstrap>", line 488, in _call_with_frames_removed
  File "/opt/airflow/dags/covid_gdp_dag.py", line 7, in <module>
    from common_data_loader import download_world_bank_data, download_kaggle_dataset, load_covid_data, load_gdp_data
  File "/opt/airflow/dags/common_data_loader.py", line 3, in <module>
    import kaggle
ModuleNotFoundError: No module named 'kaggle'
[2024-09-25T22:04:22.701+0000] {processor.py:927} WARNING - No viable dags retrieved from /opt/airflow/dags/covid_gdp_dag.py
[2024-09-25T22:04:22.725+0000] {processor.py:208} INFO - Processing /opt/airflow/dags/covid_gdp_dag.py took 0.075 seconds
[2024-09-25T22:04:52.897+0000] {processor.py:186} INFO - Started process (PID=939) to work on /opt/airflow/dags/covid_gdp_dag.py
[2024-09-25T22:04:52.898+0000] {processor.py:914} INFO - Processing file /opt/airflow/dags/covid_gdp_dag.py for tasks to queue
[2024-09-25T22:04:52.900+0000] {logging_mixin.py:190} INFO - [2024-09-25T22:04:52.900+0000] {dagbag.py:588} INFO - Filling up the DagBag from /opt/airflow/dags/covid_gdp_dag.py
[2024-09-25T22:04:52.932+0000] {logging_mixin.py:190} INFO - [2024-09-25T22:04:52.924+0000] {dagbag.py:387} ERROR - Failed to import: /opt/airflow/dags/covid_gdp_dag.py
Traceback (most recent call last):
  File "/home/airflow/.local/lib/python3.12/site-packages/airflow/models/dagbag.py", line 383, in parse
    loader.exec_module(new_module)
  File "<frozen importlib._bootstrap_external>", line 995, in exec_module
  File "<frozen importlib._bootstrap>", line 488, in _call_with_frames_removed
  File "/opt/airflow/dags/covid_gdp_dag.py", line 7, in <module>
    from common_data_loader import download_world_bank_data, download_kaggle_dataset, load_covid_data, load_gdp_data
  File "/opt/airflow/dags/common_data_loader.py", line 3, in <module>
    import kaggle
ModuleNotFoundError: No module named 'kaggle'
[2024-09-25T22:04:52.933+0000] {processor.py:927} WARNING - No viable dags retrieved from /opt/airflow/dags/covid_gdp_dag.py
[2024-09-25T22:04:52.956+0000] {processor.py:208} INFO - Processing /opt/airflow/dags/covid_gdp_dag.py took 0.065 seconds
[2024-09-25T22:05:23.728+0000] {processor.py:186} INFO - Started process (PID=1002) to work on /opt/airflow/dags/covid_gdp_dag.py
[2024-09-25T22:05:23.729+0000] {processor.py:914} INFO - Processing file /opt/airflow/dags/covid_gdp_dag.py for tasks to queue
[2024-09-25T22:05:23.732+0000] {logging_mixin.py:190} INFO - [2024-09-25T22:05:23.732+0000] {dagbag.py:588} INFO - Filling up the DagBag from /opt/airflow/dags/covid_gdp_dag.py
[2024-09-25T22:05:23.773+0000] {logging_mixin.py:190} INFO - [2024-09-25T22:05:23.758+0000] {dagbag.py:387} ERROR - Failed to import: /opt/airflow/dags/covid_gdp_dag.py
Traceback (most recent call last):
  File "/home/airflow/.local/lib/python3.12/site-packages/airflow/models/dagbag.py", line 383, in parse
    loader.exec_module(new_module)
  File "<frozen importlib._bootstrap_external>", line 995, in exec_module
  File "<frozen importlib._bootstrap>", line 488, in _call_with_frames_removed
  File "/opt/airflow/dags/covid_gdp_dag.py", line 7, in <module>
    from common_data_loader import download_world_bank_data, download_kaggle_dataset, load_covid_data, load_gdp_data
  File "/opt/airflow/dags/common_data_loader.py", line 3, in <module>
    import kaggle
ModuleNotFoundError: No module named 'kaggle'
[2024-09-25T22:05:23.776+0000] {processor.py:927} WARNING - No viable dags retrieved from /opt/airflow/dags/covid_gdp_dag.py
[2024-09-25T22:05:23.806+0000] {processor.py:208} INFO - Processing /opt/airflow/dags/covid_gdp_dag.py took 0.085 seconds
[2024-09-25T22:05:54.239+0000] {processor.py:186} INFO - Started process (PID=1065) to work on /opt/airflow/dags/covid_gdp_dag.py
[2024-09-25T22:05:54.241+0000] {processor.py:914} INFO - Processing file /opt/airflow/dags/covid_gdp_dag.py for tasks to queue
[2024-09-25T22:05:54.243+0000] {logging_mixin.py:190} INFO - [2024-09-25T22:05:54.243+0000] {dagbag.py:588} INFO - Filling up the DagBag from /opt/airflow/dags/covid_gdp_dag.py
[2024-09-25T22:05:54.273+0000] {logging_mixin.py:190} INFO - [2024-09-25T22:05:54.265+0000] {dagbag.py:387} ERROR - Failed to import: /opt/airflow/dags/covid_gdp_dag.py
Traceback (most recent call last):
  File "/home/airflow/.local/lib/python3.12/site-packages/airflow/models/dagbag.py", line 383, in parse
    loader.exec_module(new_module)
  File "<frozen importlib._bootstrap_external>", line 995, in exec_module
  File "<frozen importlib._bootstrap>", line 488, in _call_with_frames_removed
  File "/opt/airflow/dags/covid_gdp_dag.py", line 7, in <module>
    from common_data_loader import download_world_bank_data, download_kaggle_dataset, load_covid_data, load_gdp_data
  File "/opt/airflow/dags/common_data_loader.py", line 3, in <module>
    import kaggle
ModuleNotFoundError: No module named 'kaggle'
[2024-09-25T22:05:54.276+0000] {processor.py:927} WARNING - No viable dags retrieved from /opt/airflow/dags/covid_gdp_dag.py
[2024-09-25T22:05:54.300+0000] {processor.py:208} INFO - Processing /opt/airflow/dags/covid_gdp_dag.py took 0.066 seconds
[2024-09-25T22:06:24.539+0000] {processor.py:186} INFO - Started process (PID=1129) to work on /opt/airflow/dags/covid_gdp_dag.py
[2024-09-25T22:06:24.540+0000] {processor.py:914} INFO - Processing file /opt/airflow/dags/covid_gdp_dag.py for tasks to queue
[2024-09-25T22:06:24.542+0000] {logging_mixin.py:190} INFO - [2024-09-25T22:06:24.542+0000] {dagbag.py:588} INFO - Filling up the DagBag from /opt/airflow/dags/covid_gdp_dag.py
[2024-09-25T22:06:24.568+0000] {logging_mixin.py:190} INFO - [2024-09-25T22:06:24.560+0000] {dagbag.py:387} ERROR - Failed to import: /opt/airflow/dags/covid_gdp_dag.py
Traceback (most recent call last):
  File "/home/airflow/.local/lib/python3.12/site-packages/airflow/models/dagbag.py", line 383, in parse
    loader.exec_module(new_module)
  File "<frozen importlib._bootstrap_external>", line 995, in exec_module
  File "<frozen importlib._bootstrap>", line 488, in _call_with_frames_removed
  File "/opt/airflow/dags/covid_gdp_dag.py", line 7, in <module>
    from common_data_loader import download_world_bank_data, download_kaggle_dataset, load_covid_data, load_gdp_data
  File "/opt/airflow/dags/common_data_loader.py", line 3, in <module>
    import kaggle
ModuleNotFoundError: No module named 'kaggle'
[2024-09-25T22:06:24.570+0000] {processor.py:927} WARNING - No viable dags retrieved from /opt/airflow/dags/covid_gdp_dag.py
[2024-09-25T22:06:24.595+0000] {processor.py:208} INFO - Processing /opt/airflow/dags/covid_gdp_dag.py took 0.060 seconds
[2024-09-25T22:06:55.471+0000] {processor.py:186} INFO - Started process (PID=1192) to work on /opt/airflow/dags/covid_gdp_dag.py
[2024-09-25T22:06:55.472+0000] {processor.py:914} INFO - Processing file /opt/airflow/dags/covid_gdp_dag.py for tasks to queue
[2024-09-25T22:06:55.475+0000] {logging_mixin.py:190} INFO - [2024-09-25T22:06:55.474+0000] {dagbag.py:588} INFO - Filling up the DagBag from /opt/airflow/dags/covid_gdp_dag.py
[2024-09-25T22:06:55.500+0000] {logging_mixin.py:190} INFO - [2024-09-25T22:06:55.493+0000] {dagbag.py:387} ERROR - Failed to import: /opt/airflow/dags/covid_gdp_dag.py
Traceback (most recent call last):
  File "/home/airflow/.local/lib/python3.12/site-packages/airflow/models/dagbag.py", line 383, in parse
    loader.exec_module(new_module)
  File "<frozen importlib._bootstrap_external>", line 995, in exec_module
  File "<frozen importlib._bootstrap>", line 488, in _call_with_frames_removed
  File "/opt/airflow/dags/covid_gdp_dag.py", line 7, in <module>
    from common_data_loader import download_world_bank_data, download_kaggle_dataset, load_covid_data, load_gdp_data
  File "/opt/airflow/dags/common_data_loader.py", line 3, in <module>
    import kaggle
ModuleNotFoundError: No module named 'kaggle'
[2024-09-25T22:06:55.502+0000] {processor.py:927} WARNING - No viable dags retrieved from /opt/airflow/dags/covid_gdp_dag.py
[2024-09-25T22:06:55.526+0000] {processor.py:208} INFO - Processing /opt/airflow/dags/covid_gdp_dag.py took 0.060 seconds
[2024-09-25T22:07:25.972+0000] {processor.py:186} INFO - Started process (PID=1255) to work on /opt/airflow/dags/covid_gdp_dag.py
[2024-09-25T22:07:25.974+0000] {processor.py:914} INFO - Processing file /opt/airflow/dags/covid_gdp_dag.py for tasks to queue
[2024-09-25T22:07:25.977+0000] {logging_mixin.py:190} INFO - [2024-09-25T22:07:25.977+0000] {dagbag.py:588} INFO - Filling up the DagBag from /opt/airflow/dags/covid_gdp_dag.py
[2024-09-25T22:07:26.007+0000] {logging_mixin.py:190} INFO - [2024-09-25T22:07:25.999+0000] {dagbag.py:387} ERROR - Failed to import: /opt/airflow/dags/covid_gdp_dag.py
Traceback (most recent call last):
  File "/home/airflow/.local/lib/python3.12/site-packages/airflow/models/dagbag.py", line 383, in parse
    loader.exec_module(new_module)
  File "<frozen importlib._bootstrap_external>", line 995, in exec_module
  File "<frozen importlib._bootstrap>", line 488, in _call_with_frames_removed
  File "/opt/airflow/dags/covid_gdp_dag.py", line 7, in <module>
    from common_data_loader import download_world_bank_data, download_kaggle_dataset, load_covid_data, load_gdp_data
  File "/opt/airflow/dags/common_data_loader.py", line 3, in <module>
    import kaggle
ModuleNotFoundError: No module named 'kaggle'
[2024-09-25T22:07:26.009+0000] {processor.py:927} WARNING - No viable dags retrieved from /opt/airflow/dags/covid_gdp_dag.py
[2024-09-25T22:07:26.033+0000] {processor.py:208} INFO - Processing /opt/airflow/dags/covid_gdp_dag.py took 0.065 seconds
[2024-09-25T22:07:56.204+0000] {processor.py:186} INFO - Started process (PID=1319) to work on /opt/airflow/dags/covid_gdp_dag.py
[2024-09-25T22:07:56.207+0000] {processor.py:914} INFO - Processing file /opt/airflow/dags/covid_gdp_dag.py for tasks to queue
[2024-09-25T22:07:56.213+0000] {logging_mixin.py:190} INFO - [2024-09-25T22:07:56.212+0000] {dagbag.py:588} INFO - Filling up the DagBag from /opt/airflow/dags/covid_gdp_dag.py
[2024-09-25T22:07:56.237+0000] {logging_mixin.py:190} INFO - [2024-09-25T22:07:56.231+0000] {dagbag.py:387} ERROR - Failed to import: /opt/airflow/dags/covid_gdp_dag.py
Traceback (most recent call last):
  File "/home/airflow/.local/lib/python3.12/site-packages/airflow/models/dagbag.py", line 383, in parse
    loader.exec_module(new_module)
  File "<frozen importlib._bootstrap_external>", line 995, in exec_module
  File "<frozen importlib._bootstrap>", line 488, in _call_with_frames_removed
  File "/opt/airflow/dags/covid_gdp_dag.py", line 7, in <module>
    from common_data_loader import download_world_bank_data, download_kaggle_dataset, load_covid_data, load_gdp_data
  File "/opt/airflow/dags/common_data_loader.py", line 3, in <module>
    import kaggle
ModuleNotFoundError: No module named 'kaggle'
[2024-09-25T22:07:56.239+0000] {processor.py:927} WARNING - No viable dags retrieved from /opt/airflow/dags/covid_gdp_dag.py
[2024-09-25T22:07:56.262+0000] {processor.py:208} INFO - Processing /opt/airflow/dags/covid_gdp_dag.py took 0.065 seconds
[2024-09-25T22:08:26.524+0000] {processor.py:186} INFO - Started process (PID=1382) to work on /opt/airflow/dags/covid_gdp_dag.py
[2024-09-25T22:08:26.525+0000] {processor.py:914} INFO - Processing file /opt/airflow/dags/covid_gdp_dag.py for tasks to queue
[2024-09-25T22:08:26.528+0000] {logging_mixin.py:190} INFO - [2024-09-25T22:08:26.527+0000] {dagbag.py:588} INFO - Filling up the DagBag from /opt/airflow/dags/covid_gdp_dag.py
[2024-09-25T22:08:26.556+0000] {logging_mixin.py:190} INFO - [2024-09-25T22:08:26.549+0000] {dagbag.py:387} ERROR - Failed to import: /opt/airflow/dags/covid_gdp_dag.py
Traceback (most recent call last):
  File "/home/airflow/.local/lib/python3.12/site-packages/airflow/models/dagbag.py", line 383, in parse
    loader.exec_module(new_module)
  File "<frozen importlib._bootstrap_external>", line 995, in exec_module
  File "<frozen importlib._bootstrap>", line 488, in _call_with_frames_removed
  File "/opt/airflow/dags/covid_gdp_dag.py", line 7, in <module>
    from common_data_loader import download_world_bank_data, download_kaggle_dataset, load_covid_data, load_gdp_data
  File "/opt/airflow/dags/common_data_loader.py", line 3, in <module>
    import kaggle
ModuleNotFoundError: No module named 'kaggle'
[2024-09-25T22:08:26.560+0000] {processor.py:927} WARNING - No viable dags retrieved from /opt/airflow/dags/covid_gdp_dag.py
[2024-09-25T22:08:26.586+0000] {processor.py:208} INFO - Processing /opt/airflow/dags/covid_gdp_dag.py took 0.067 seconds
[2024-09-25T22:10:32.950+0000] {processor.py:186} INFO - Started process (PID=66) to work on /opt/airflow/dags/covid_gdp_dag.py
[2024-09-25T22:10:32.958+0000] {processor.py:914} INFO - Processing file /opt/airflow/dags/covid_gdp_dag.py for tasks to queue
[2024-09-25T22:10:33.112+0000] {logging_mixin.py:190} INFO - [2024-09-25T22:10:33.050+0000] {dagbag.py:588} INFO - Filling up the DagBag from /opt/airflow/dags/covid_gdp_dag.py
[2024-09-25T22:10:33.199+0000] {logging_mixin.py:190} INFO - [2024-09-25T22:10:33.187+0000] {dagbag.py:387} ERROR - Failed to import: /opt/airflow/dags/covid_gdp_dag.py
Traceback (most recent call last):
  File "/home/airflow/.local/lib/python3.12/site-packages/airflow/models/dagbag.py", line 383, in parse
    loader.exec_module(new_module)
  File "<frozen importlib._bootstrap_external>", line 995, in exec_module
  File "<frozen importlib._bootstrap>", line 488, in _call_with_frames_removed
  File "/opt/airflow/dags/covid_gdp_dag.py", line 7, in <module>
    from common_data_loader import download_world_bank_data, download_kaggle_dataset, load_covid_data, load_gdp_data
  File "/opt/airflow/dags/common_data_loader.py", line 3, in <module>
    import kaggle
ModuleNotFoundError: No module named 'kaggle'
[2024-09-25T22:10:33.203+0000] {processor.py:927} WARNING - No viable dags retrieved from /opt/airflow/dags/covid_gdp_dag.py
[2024-09-25T22:10:33.410+0000] {processor.py:208} INFO - Processing /opt/airflow/dags/covid_gdp_dag.py took 0.476 seconds
[2024-09-25T22:11:04.032+0000] {processor.py:186} INFO - Started process (PID=129) to work on /opt/airflow/dags/covid_gdp_dag.py
[2024-09-25T22:11:04.034+0000] {processor.py:914} INFO - Processing file /opt/airflow/dags/covid_gdp_dag.py for tasks to queue
[2024-09-25T22:11:04.036+0000] {logging_mixin.py:190} INFO - [2024-09-25T22:11:04.035+0000] {dagbag.py:588} INFO - Filling up the DagBag from /opt/airflow/dags/covid_gdp_dag.py
[2024-09-25T22:11:04.067+0000] {logging_mixin.py:190} INFO - [2024-09-25T22:11:04.056+0000] {dagbag.py:387} ERROR - Failed to import: /opt/airflow/dags/covid_gdp_dag.py
Traceback (most recent call last):
  File "/home/airflow/.local/lib/python3.12/site-packages/airflow/models/dagbag.py", line 383, in parse
    loader.exec_module(new_module)
  File "<frozen importlib._bootstrap_external>", line 995, in exec_module
  File "<frozen importlib._bootstrap>", line 488, in _call_with_frames_removed
  File "/opt/airflow/dags/covid_gdp_dag.py", line 7, in <module>
    from common_data_loader import download_world_bank_data, download_kaggle_dataset, load_covid_data, load_gdp_data
  File "/opt/airflow/dags/common_data_loader.py", line 3, in <module>
    import kaggle
ModuleNotFoundError: No module named 'kaggle'
[2024-09-25T22:11:04.070+0000] {processor.py:927} WARNING - No viable dags retrieved from /opt/airflow/dags/covid_gdp_dag.py
[2024-09-25T22:11:04.097+0000] {processor.py:208} INFO - Processing /opt/airflow/dags/covid_gdp_dag.py took 0.069 seconds
[2024-09-25T22:11:34.902+0000] {processor.py:186} INFO - Started process (PID=192) to work on /opt/airflow/dags/covid_gdp_dag.py
[2024-09-25T22:11:34.904+0000] {processor.py:914} INFO - Processing file /opt/airflow/dags/covid_gdp_dag.py for tasks to queue
[2024-09-25T22:11:34.910+0000] {logging_mixin.py:190} INFO - [2024-09-25T22:11:34.910+0000] {dagbag.py:588} INFO - Filling up the DagBag from /opt/airflow/dags/covid_gdp_dag.py
[2024-09-25T22:11:34.937+0000] {logging_mixin.py:190} INFO - [2024-09-25T22:11:34.931+0000] {dagbag.py:387} ERROR - Failed to import: /opt/airflow/dags/covid_gdp_dag.py
Traceback (most recent call last):
  File "/home/airflow/.local/lib/python3.12/site-packages/airflow/models/dagbag.py", line 383, in parse
    loader.exec_module(new_module)
  File "<frozen importlib._bootstrap_external>", line 995, in exec_module
  File "<frozen importlib._bootstrap>", line 488, in _call_with_frames_removed
  File "/opt/airflow/dags/covid_gdp_dag.py", line 7, in <module>
    from common_data_loader import download_world_bank_data, download_kaggle_dataset, load_covid_data, load_gdp_data
  File "/opt/airflow/dags/common_data_loader.py", line 3, in <module>
    import kaggle
ModuleNotFoundError: No module named 'kaggle'
[2024-09-25T22:11:34.939+0000] {processor.py:927} WARNING - No viable dags retrieved from /opt/airflow/dags/covid_gdp_dag.py
[2024-09-25T22:11:34.965+0000] {processor.py:208} INFO - Processing /opt/airflow/dags/covid_gdp_dag.py took 0.071 seconds
[2024-09-25T22:12:05.274+0000] {processor.py:186} INFO - Started process (PID=255) to work on /opt/airflow/dags/covid_gdp_dag.py
[2024-09-25T22:12:05.276+0000] {processor.py:914} INFO - Processing file /opt/airflow/dags/covid_gdp_dag.py for tasks to queue
[2024-09-25T22:12:05.279+0000] {logging_mixin.py:190} INFO - [2024-09-25T22:12:05.279+0000] {dagbag.py:588} INFO - Filling up the DagBag from /opt/airflow/dags/covid_gdp_dag.py
[2024-09-25T22:12:05.315+0000] {logging_mixin.py:190} INFO - [2024-09-25T22:12:05.304+0000] {dagbag.py:387} ERROR - Failed to import: /opt/airflow/dags/covid_gdp_dag.py
Traceback (most recent call last):
  File "/home/airflow/.local/lib/python3.12/site-packages/airflow/models/dagbag.py", line 383, in parse
    loader.exec_module(new_module)
  File "<frozen importlib._bootstrap_external>", line 995, in exec_module
  File "<frozen importlib._bootstrap>", line 488, in _call_with_frames_removed
  File "/opt/airflow/dags/covid_gdp_dag.py", line 7, in <module>
    from common_data_loader import download_world_bank_data, download_kaggle_dataset, load_covid_data, load_gdp_data
  File "/opt/airflow/dags/common_data_loader.py", line 3, in <module>
    import kaggle
ModuleNotFoundError: No module named 'kaggle'
[2024-09-25T22:12:05.319+0000] {processor.py:927} WARNING - No viable dags retrieved from /opt/airflow/dags/covid_gdp_dag.py
[2024-09-25T22:12:05.353+0000] {processor.py:208} INFO - Processing /opt/airflow/dags/covid_gdp_dag.py took 0.085 seconds
[2024-09-25T22:12:36.218+0000] {processor.py:186} INFO - Started process (PID=318) to work on /opt/airflow/dags/covid_gdp_dag.py
[2024-09-25T22:12:36.219+0000] {processor.py:914} INFO - Processing file /opt/airflow/dags/covid_gdp_dag.py for tasks to queue
[2024-09-25T22:12:36.221+0000] {logging_mixin.py:190} INFO - [2024-09-25T22:12:36.221+0000] {dagbag.py:588} INFO - Filling up the DagBag from /opt/airflow/dags/covid_gdp_dag.py
[2024-09-25T22:12:36.243+0000] {logging_mixin.py:190} INFO - [2024-09-25T22:12:36.237+0000] {dagbag.py:387} ERROR - Failed to import: /opt/airflow/dags/covid_gdp_dag.py
Traceback (most recent call last):
  File "/home/airflow/.local/lib/python3.12/site-packages/airflow/models/dagbag.py", line 383, in parse
    loader.exec_module(new_module)
  File "<frozen importlib._bootstrap_external>", line 995, in exec_module
  File "<frozen importlib._bootstrap>", line 488, in _call_with_frames_removed
  File "/opt/airflow/dags/covid_gdp_dag.py", line 7, in <module>
    from common_data_loader import download_world_bank_data, download_kaggle_dataset, load_covid_data, load_gdp_data
  File "/opt/airflow/dags/common_data_loader.py", line 3, in <module>
    import kaggle
ModuleNotFoundError: No module named 'kaggle'
[2024-09-25T22:12:36.245+0000] {processor.py:927} WARNING - No viable dags retrieved from /opt/airflow/dags/covid_gdp_dag.py
[2024-09-25T22:12:36.266+0000] {processor.py:208} INFO - Processing /opt/airflow/dags/covid_gdp_dag.py took 0.055 seconds
[2024-09-25T22:13:07.030+0000] {processor.py:186} INFO - Started process (PID=381) to work on /opt/airflow/dags/covid_gdp_dag.py
[2024-09-25T22:13:07.031+0000] {processor.py:914} INFO - Processing file /opt/airflow/dags/covid_gdp_dag.py for tasks to queue
[2024-09-25T22:13:07.033+0000] {logging_mixin.py:190} INFO - [2024-09-25T22:13:07.033+0000] {dagbag.py:588} INFO - Filling up the DagBag from /opt/airflow/dags/covid_gdp_dag.py
[2024-09-25T22:13:07.052+0000] {logging_mixin.py:190} INFO - [2024-09-25T22:13:07.047+0000] {dagbag.py:387} ERROR - Failed to import: /opt/airflow/dags/covid_gdp_dag.py
Traceback (most recent call last):
  File "/home/airflow/.local/lib/python3.12/site-packages/airflow/models/dagbag.py", line 383, in parse
    loader.exec_module(new_module)
  File "<frozen importlib._bootstrap_external>", line 995, in exec_module
  File "<frozen importlib._bootstrap>", line 488, in _call_with_frames_removed
  File "/opt/airflow/dags/covid_gdp_dag.py", line 7, in <module>
    from common_data_loader import download_world_bank_data, download_kaggle_dataset, load_covid_data, load_gdp_data
  File "/opt/airflow/dags/common_data_loader.py", line 3, in <module>
    import kaggle
ModuleNotFoundError: No module named 'kaggle'
[2024-09-25T22:13:07.053+0000] {processor.py:927} WARNING - No viable dags retrieved from /opt/airflow/dags/covid_gdp_dag.py
[2024-09-25T22:13:07.074+0000] {processor.py:208} INFO - Processing /opt/airflow/dags/covid_gdp_dag.py took 0.049 seconds
[2024-09-25T22:13:37.135+0000] {processor.py:186} INFO - Started process (PID=444) to work on /opt/airflow/dags/covid_gdp_dag.py
[2024-09-25T22:13:37.137+0000] {processor.py:914} INFO - Processing file /opt/airflow/dags/covid_gdp_dag.py for tasks to queue
[2024-09-25T22:13:37.140+0000] {logging_mixin.py:190} INFO - [2024-09-25T22:13:37.139+0000] {dagbag.py:588} INFO - Filling up the DagBag from /opt/airflow/dags/covid_gdp_dag.py
[2024-09-25T22:13:37.161+0000] {logging_mixin.py:190} INFO - [2024-09-25T22:13:37.156+0000] {dagbag.py:387} ERROR - Failed to import: /opt/airflow/dags/covid_gdp_dag.py
Traceback (most recent call last):
  File "/home/airflow/.local/lib/python3.12/site-packages/airflow/models/dagbag.py", line 383, in parse
    loader.exec_module(new_module)
  File "<frozen importlib._bootstrap_external>", line 995, in exec_module
  File "<frozen importlib._bootstrap>", line 488, in _call_with_frames_removed
  File "/opt/airflow/dags/covid_gdp_dag.py", line 7, in <module>
    from common_data_loader import download_world_bank_data, download_kaggle_dataset, load_covid_data, load_gdp_data
  File "/opt/airflow/dags/common_data_loader.py", line 3, in <module>
    import kaggle
ModuleNotFoundError: No module named 'kaggle'
[2024-09-25T22:13:37.163+0000] {processor.py:927} WARNING - No viable dags retrieved from /opt/airflow/dags/covid_gdp_dag.py
[2024-09-25T22:13:37.185+0000] {processor.py:208} INFO - Processing /opt/airflow/dags/covid_gdp_dag.py took 0.054 seconds
[2024-09-25T22:14:07.798+0000] {processor.py:186} INFO - Started process (PID=507) to work on /opt/airflow/dags/covid_gdp_dag.py
[2024-09-25T22:14:07.799+0000] {processor.py:914} INFO - Processing file /opt/airflow/dags/covid_gdp_dag.py for tasks to queue
[2024-09-25T22:14:07.802+0000] {logging_mixin.py:190} INFO - [2024-09-25T22:14:07.801+0000] {dagbag.py:588} INFO - Filling up the DagBag from /opt/airflow/dags/covid_gdp_dag.py
[2024-09-25T22:14:07.823+0000] {logging_mixin.py:190} INFO - [2024-09-25T22:14:07.818+0000] {dagbag.py:387} ERROR - Failed to import: /opt/airflow/dags/covid_gdp_dag.py
Traceback (most recent call last):
  File "/home/airflow/.local/lib/python3.12/site-packages/airflow/models/dagbag.py", line 383, in parse
    loader.exec_module(new_module)
  File "<frozen importlib._bootstrap_external>", line 995, in exec_module
  File "<frozen importlib._bootstrap>", line 488, in _call_with_frames_removed
  File "/opt/airflow/dags/covid_gdp_dag.py", line 7, in <module>
    from common_data_loader import download_world_bank_data, download_kaggle_dataset, load_covid_data, load_gdp_data
  File "/opt/airflow/dags/common_data_loader.py", line 3, in <module>
    import kaggle
ModuleNotFoundError: No module named 'kaggle'
[2024-09-25T22:14:07.825+0000] {processor.py:927} WARNING - No viable dags retrieved from /opt/airflow/dags/covid_gdp_dag.py
[2024-09-25T22:14:07.848+0000] {processor.py:208} INFO - Processing /opt/airflow/dags/covid_gdp_dag.py took 0.054 seconds
[2024-09-25T22:14:38.149+0000] {processor.py:186} INFO - Started process (PID=570) to work on /opt/airflow/dags/covid_gdp_dag.py
[2024-09-25T22:14:38.150+0000] {processor.py:914} INFO - Processing file /opt/airflow/dags/covid_gdp_dag.py for tasks to queue
[2024-09-25T22:14:38.153+0000] {logging_mixin.py:190} INFO - [2024-09-25T22:14:38.152+0000] {dagbag.py:588} INFO - Filling up the DagBag from /opt/airflow/dags/covid_gdp_dag.py
[2024-09-25T22:14:38.174+0000] {logging_mixin.py:190} INFO - [2024-09-25T22:14:38.168+0000] {dagbag.py:387} ERROR - Failed to import: /opt/airflow/dags/covid_gdp_dag.py
Traceback (most recent call last):
  File "/home/airflow/.local/lib/python3.12/site-packages/airflow/models/dagbag.py", line 383, in parse
    loader.exec_module(new_module)
  File "<frozen importlib._bootstrap_external>", line 995, in exec_module
  File "<frozen importlib._bootstrap>", line 488, in _call_with_frames_removed
  File "/opt/airflow/dags/covid_gdp_dag.py", line 7, in <module>
    from common_data_loader import download_world_bank_data, download_kaggle_dataset, load_covid_data, load_gdp_data
  File "/opt/airflow/dags/common_data_loader.py", line 3, in <module>
    import kaggle
ModuleNotFoundError: No module named 'kaggle'
[2024-09-25T22:14:38.176+0000] {processor.py:927} WARNING - No viable dags retrieved from /opt/airflow/dags/covid_gdp_dag.py
[2024-09-25T22:14:38.219+0000] {processor.py:208} INFO - Processing /opt/airflow/dags/covid_gdp_dag.py took 0.074 seconds
[2024-09-25T22:15:08.508+0000] {processor.py:186} INFO - Started process (PID=633) to work on /opt/airflow/dags/covid_gdp_dag.py
[2024-09-25T22:15:08.509+0000] {processor.py:914} INFO - Processing file /opt/airflow/dags/covid_gdp_dag.py for tasks to queue
[2024-09-25T22:15:08.512+0000] {logging_mixin.py:190} INFO - [2024-09-25T22:15:08.512+0000] {dagbag.py:588} INFO - Filling up the DagBag from /opt/airflow/dags/covid_gdp_dag.py
[2024-09-25T22:15:08.537+0000] {logging_mixin.py:190} INFO - [2024-09-25T22:15:08.531+0000] {dagbag.py:387} ERROR - Failed to import: /opt/airflow/dags/covid_gdp_dag.py
Traceback (most recent call last):
  File "/home/airflow/.local/lib/python3.12/site-packages/airflow/models/dagbag.py", line 383, in parse
    loader.exec_module(new_module)
  File "<frozen importlib._bootstrap_external>", line 995, in exec_module
  File "<frozen importlib._bootstrap>", line 488, in _call_with_frames_removed
  File "/opt/airflow/dags/covid_gdp_dag.py", line 7, in <module>
    from common_data_loader import download_world_bank_data, download_kaggle_dataset, load_covid_data, load_gdp_data
  File "/opt/airflow/dags/common_data_loader.py", line 3, in <module>
    import kaggle
ModuleNotFoundError: No module named 'kaggle'
[2024-09-25T22:15:08.539+0000] {processor.py:927} WARNING - No viable dags retrieved from /opt/airflow/dags/covid_gdp_dag.py
[2024-09-25T22:15:08.563+0000] {processor.py:208} INFO - Processing /opt/airflow/dags/covid_gdp_dag.py took 0.061 seconds
[2024-09-25T22:15:38.690+0000] {processor.py:186} INFO - Started process (PID=696) to work on /opt/airflow/dags/covid_gdp_dag.py
[2024-09-25T22:15:38.691+0000] {processor.py:914} INFO - Processing file /opt/airflow/dags/covid_gdp_dag.py for tasks to queue
[2024-09-25T22:15:38.694+0000] {logging_mixin.py:190} INFO - [2024-09-25T22:15:38.694+0000] {dagbag.py:588} INFO - Filling up the DagBag from /opt/airflow/dags/covid_gdp_dag.py
[2024-09-25T22:15:38.716+0000] {logging_mixin.py:190} INFO - [2024-09-25T22:15:38.711+0000] {dagbag.py:387} ERROR - Failed to import: /opt/airflow/dags/covid_gdp_dag.py
Traceback (most recent call last):
  File "/home/airflow/.local/lib/python3.12/site-packages/airflow/models/dagbag.py", line 383, in parse
    loader.exec_module(new_module)
  File "<frozen importlib._bootstrap_external>", line 995, in exec_module
  File "<frozen importlib._bootstrap>", line 488, in _call_with_frames_removed
  File "/opt/airflow/dags/covid_gdp_dag.py", line 7, in <module>
    from common_data_loader import download_world_bank_data, download_kaggle_dataset, load_covid_data, load_gdp_data
  File "/opt/airflow/dags/common_data_loader.py", line 3, in <module>
    import kaggle
ModuleNotFoundError: No module named 'kaggle'
[2024-09-25T22:15:38.718+0000] {processor.py:927} WARNING - No viable dags retrieved from /opt/airflow/dags/covid_gdp_dag.py
[2024-09-25T22:15:38.742+0000] {processor.py:208} INFO - Processing /opt/airflow/dags/covid_gdp_dag.py took 0.057 seconds
[2024-09-25T22:16:08.854+0000] {processor.py:186} INFO - Started process (PID=759) to work on /opt/airflow/dags/covid_gdp_dag.py
[2024-09-25T22:16:08.855+0000] {processor.py:914} INFO - Processing file /opt/airflow/dags/covid_gdp_dag.py for tasks to queue
[2024-09-25T22:16:08.858+0000] {logging_mixin.py:190} INFO - [2024-09-25T22:16:08.858+0000] {dagbag.py:588} INFO - Filling up the DagBag from /opt/airflow/dags/covid_gdp_dag.py
[2024-09-25T22:16:08.885+0000] {logging_mixin.py:190} INFO - [2024-09-25T22:16:08.877+0000] {dagbag.py:387} ERROR - Failed to import: /opt/airflow/dags/covid_gdp_dag.py
Traceback (most recent call last):
  File "/home/airflow/.local/lib/python3.12/site-packages/airflow/models/dagbag.py", line 383, in parse
    loader.exec_module(new_module)
  File "<frozen importlib._bootstrap_external>", line 995, in exec_module
  File "<frozen importlib._bootstrap>", line 488, in _call_with_frames_removed
  File "/opt/airflow/dags/covid_gdp_dag.py", line 7, in <module>
    from common_data_loader import download_world_bank_data, download_kaggle_dataset, load_covid_data, load_gdp_data
  File "/opt/airflow/dags/common_data_loader.py", line 3, in <module>
    import kaggle
ModuleNotFoundError: No module named 'kaggle'
[2024-09-25T22:16:08.888+0000] {processor.py:927} WARNING - No viable dags retrieved from /opt/airflow/dags/covid_gdp_dag.py
[2024-09-25T22:16:08.915+0000] {processor.py:208} INFO - Processing /opt/airflow/dags/covid_gdp_dag.py took 0.066 seconds
[2024-09-25T22:16:39.734+0000] {processor.py:186} INFO - Started process (PID=822) to work on /opt/airflow/dags/covid_gdp_dag.py
[2024-09-25T22:16:39.735+0000] {processor.py:914} INFO - Processing file /opt/airflow/dags/covid_gdp_dag.py for tasks to queue
[2024-09-25T22:16:39.737+0000] {logging_mixin.py:190} INFO - [2024-09-25T22:16:39.737+0000] {dagbag.py:588} INFO - Filling up the DagBag from /opt/airflow/dags/covid_gdp_dag.py
[2024-09-25T22:16:39.758+0000] {logging_mixin.py:190} INFO - [2024-09-25T22:16:39.753+0000] {dagbag.py:387} ERROR - Failed to import: /opt/airflow/dags/covid_gdp_dag.py
Traceback (most recent call last):
  File "/home/airflow/.local/lib/python3.12/site-packages/airflow/models/dagbag.py", line 383, in parse
    loader.exec_module(new_module)
  File "<frozen importlib._bootstrap_external>", line 995, in exec_module
  File "<frozen importlib._bootstrap>", line 488, in _call_with_frames_removed
  File "/opt/airflow/dags/covid_gdp_dag.py", line 7, in <module>
    from common_data_loader import download_world_bank_data, download_kaggle_dataset, load_covid_data, load_gdp_data
  File "/opt/airflow/dags/common_data_loader.py", line 3, in <module>
    import kaggle
ModuleNotFoundError: No module named 'kaggle'
[2024-09-25T22:16:39.759+0000] {processor.py:927} WARNING - No viable dags retrieved from /opt/airflow/dags/covid_gdp_dag.py
[2024-09-25T22:16:39.816+0000] {processor.py:208} INFO - Processing /opt/airflow/dags/covid_gdp_dag.py took 0.086 seconds
[2024-09-25T22:17:10.747+0000] {processor.py:186} INFO - Started process (PID=885) to work on /opt/airflow/dags/covid_gdp_dag.py
[2024-09-25T22:17:10.748+0000] {processor.py:914} INFO - Processing file /opt/airflow/dags/covid_gdp_dag.py for tasks to queue
[2024-09-25T22:17:10.751+0000] {logging_mixin.py:190} INFO - [2024-09-25T22:17:10.751+0000] {dagbag.py:588} INFO - Filling up the DagBag from /opt/airflow/dags/covid_gdp_dag.py
[2024-09-25T22:17:10.773+0000] {logging_mixin.py:190} INFO - [2024-09-25T22:17:10.767+0000] {dagbag.py:387} ERROR - Failed to import: /opt/airflow/dags/covid_gdp_dag.py
Traceback (most recent call last):
  File "/home/airflow/.local/lib/python3.12/site-packages/airflow/models/dagbag.py", line 383, in parse
    loader.exec_module(new_module)
  File "<frozen importlib._bootstrap_external>", line 995, in exec_module
  File "<frozen importlib._bootstrap>", line 488, in _call_with_frames_removed
  File "/opt/airflow/dags/covid_gdp_dag.py", line 7, in <module>
    from common_data_loader import download_world_bank_data, download_kaggle_dataset, load_covid_data, load_gdp_data
  File "/opt/airflow/dags/common_data_loader.py", line 3, in <module>
    import kaggle
ModuleNotFoundError: No module named 'kaggle'
[2024-09-25T22:17:10.774+0000] {processor.py:927} WARNING - No viable dags retrieved from /opt/airflow/dags/covid_gdp_dag.py
[2024-09-25T22:17:10.796+0000] {processor.py:208} INFO - Processing /opt/airflow/dags/covid_gdp_dag.py took 0.053 seconds
[2024-09-25T22:17:41.497+0000] {processor.py:186} INFO - Started process (PID=948) to work on /opt/airflow/dags/covid_gdp_dag.py
[2024-09-25T22:17:41.499+0000] {processor.py:914} INFO - Processing file /opt/airflow/dags/covid_gdp_dag.py for tasks to queue
[2024-09-25T22:17:41.501+0000] {logging_mixin.py:190} INFO - [2024-09-25T22:17:41.501+0000] {dagbag.py:588} INFO - Filling up the DagBag from /opt/airflow/dags/covid_gdp_dag.py
[2024-09-25T22:17:41.523+0000] {logging_mixin.py:190} INFO - [2024-09-25T22:17:41.517+0000] {dagbag.py:387} ERROR - Failed to import: /opt/airflow/dags/covid_gdp_dag.py
Traceback (most recent call last):
  File "/home/airflow/.local/lib/python3.12/site-packages/airflow/models/dagbag.py", line 383, in parse
    loader.exec_module(new_module)
  File "<frozen importlib._bootstrap_external>", line 995, in exec_module
  File "<frozen importlib._bootstrap>", line 488, in _call_with_frames_removed
  File "/opt/airflow/dags/covid_gdp_dag.py", line 7, in <module>
    from common_data_loader import download_world_bank_data, download_kaggle_dataset, load_covid_data, load_gdp_data
  File "/opt/airflow/dags/common_data_loader.py", line 3, in <module>
    import kaggle
ModuleNotFoundError: No module named 'kaggle'
[2024-09-25T22:17:41.526+0000] {processor.py:927} WARNING - No viable dags retrieved from /opt/airflow/dags/covid_gdp_dag.py
[2024-09-25T22:17:41.550+0000] {processor.py:208} INFO - Processing /opt/airflow/dags/covid_gdp_dag.py took 0.057 seconds
[2024-09-25T22:18:12.271+0000] {processor.py:186} INFO - Started process (PID=1011) to work on /opt/airflow/dags/covid_gdp_dag.py
[2024-09-25T22:18:12.272+0000] {processor.py:914} INFO - Processing file /opt/airflow/dags/covid_gdp_dag.py for tasks to queue
[2024-09-25T22:18:12.275+0000] {logging_mixin.py:190} INFO - [2024-09-25T22:18:12.274+0000] {dagbag.py:588} INFO - Filling up the DagBag from /opt/airflow/dags/covid_gdp_dag.py
[2024-09-25T22:18:12.301+0000] {logging_mixin.py:190} INFO - [2024-09-25T22:18:12.293+0000] {dagbag.py:387} ERROR - Failed to import: /opt/airflow/dags/covid_gdp_dag.py
Traceback (most recent call last):
  File "/home/airflow/.local/lib/python3.12/site-packages/airflow/models/dagbag.py", line 383, in parse
    loader.exec_module(new_module)
  File "<frozen importlib._bootstrap_external>", line 995, in exec_module
  File "<frozen importlib._bootstrap>", line 488, in _call_with_frames_removed
  File "/opt/airflow/dags/covid_gdp_dag.py", line 7, in <module>
    from common_data_loader import download_world_bank_data, download_kaggle_dataset, load_covid_data, load_gdp_data
  File "/opt/airflow/dags/common_data_loader.py", line 3, in <module>
    import kaggle
ModuleNotFoundError: No module named 'kaggle'
[2024-09-25T22:18:12.304+0000] {processor.py:927} WARNING - No viable dags retrieved from /opt/airflow/dags/covid_gdp_dag.py
[2024-09-25T22:18:12.368+0000] {processor.py:208} INFO - Processing /opt/airflow/dags/covid_gdp_dag.py took 0.103 seconds
[2024-09-25T22:18:43.208+0000] {processor.py:186} INFO - Started process (PID=1074) to work on /opt/airflow/dags/covid_gdp_dag.py
[2024-09-25T22:18:43.210+0000] {processor.py:914} INFO - Processing file /opt/airflow/dags/covid_gdp_dag.py for tasks to queue
[2024-09-25T22:18:43.212+0000] {logging_mixin.py:190} INFO - [2024-09-25T22:18:43.212+0000] {dagbag.py:588} INFO - Filling up the DagBag from /opt/airflow/dags/covid_gdp_dag.py
[2024-09-25T22:18:43.233+0000] {logging_mixin.py:190} INFO - [2024-09-25T22:18:43.228+0000] {dagbag.py:387} ERROR - Failed to import: /opt/airflow/dags/covid_gdp_dag.py
Traceback (most recent call last):
  File "/home/airflow/.local/lib/python3.12/site-packages/airflow/models/dagbag.py", line 383, in parse
    loader.exec_module(new_module)
  File "<frozen importlib._bootstrap_external>", line 995, in exec_module
  File "<frozen importlib._bootstrap>", line 488, in _call_with_frames_removed
  File "/opt/airflow/dags/covid_gdp_dag.py", line 7, in <module>
    from common_data_loader import download_world_bank_data, download_kaggle_dataset, load_covid_data, load_gdp_data
  File "/opt/airflow/dags/common_data_loader.py", line 3, in <module>
    import kaggle
ModuleNotFoundError: No module named 'kaggle'
[2024-09-25T22:18:43.235+0000] {processor.py:927} WARNING - No viable dags retrieved from /opt/airflow/dags/covid_gdp_dag.py
[2024-09-25T22:18:43.300+0000] {processor.py:208} INFO - Processing /opt/airflow/dags/covid_gdp_dag.py took 0.097 seconds
[2024-09-25T22:19:14.042+0000] {processor.py:186} INFO - Started process (PID=1137) to work on /opt/airflow/dags/covid_gdp_dag.py
[2024-09-25T22:19:14.043+0000] {processor.py:914} INFO - Processing file /opt/airflow/dags/covid_gdp_dag.py for tasks to queue
[2024-09-25T22:19:14.045+0000] {logging_mixin.py:190} INFO - [2024-09-25T22:19:14.045+0000] {dagbag.py:588} INFO - Filling up the DagBag from /opt/airflow/dags/covid_gdp_dag.py
[2024-09-25T22:19:14.066+0000] {logging_mixin.py:190} INFO - [2024-09-25T22:19:14.060+0000] {dagbag.py:387} ERROR - Failed to import: /opt/airflow/dags/covid_gdp_dag.py
Traceback (most recent call last):
  File "/home/airflow/.local/lib/python3.12/site-packages/airflow/models/dagbag.py", line 383, in parse
    loader.exec_module(new_module)
  File "<frozen importlib._bootstrap_external>", line 995, in exec_module
  File "<frozen importlib._bootstrap>", line 488, in _call_with_frames_removed
  File "/opt/airflow/dags/covid_gdp_dag.py", line 7, in <module>
    from common_data_loader import download_world_bank_data, download_kaggle_dataset, load_covid_data, load_gdp_data
  File "/opt/airflow/dags/common_data_loader.py", line 3, in <module>
    import kaggle
ModuleNotFoundError: No module named 'kaggle'
[2024-09-25T22:19:14.067+0000] {processor.py:927} WARNING - No viable dags retrieved from /opt/airflow/dags/covid_gdp_dag.py
[2024-09-25T22:19:14.123+0000] {processor.py:208} INFO - Processing /opt/airflow/dags/covid_gdp_dag.py took 0.085 seconds
[2024-09-25T22:19:44.390+0000] {processor.py:186} INFO - Started process (PID=1200) to work on /opt/airflow/dags/covid_gdp_dag.py
[2024-09-25T22:19:44.391+0000] {processor.py:914} INFO - Processing file /opt/airflow/dags/covid_gdp_dag.py for tasks to queue
[2024-09-25T22:19:44.394+0000] {logging_mixin.py:190} INFO - [2024-09-25T22:19:44.393+0000] {dagbag.py:588} INFO - Filling up the DagBag from /opt/airflow/dags/covid_gdp_dag.py
[2024-09-25T22:19:44.417+0000] {logging_mixin.py:190} INFO - [2024-09-25T22:19:44.410+0000] {dagbag.py:387} ERROR - Failed to import: /opt/airflow/dags/covid_gdp_dag.py
Traceback (most recent call last):
  File "/home/airflow/.local/lib/python3.12/site-packages/airflow/models/dagbag.py", line 383, in parse
    loader.exec_module(new_module)
  File "<frozen importlib._bootstrap_external>", line 995, in exec_module
  File "<frozen importlib._bootstrap>", line 488, in _call_with_frames_removed
  File "/opt/airflow/dags/covid_gdp_dag.py", line 7, in <module>
    from common_data_loader import download_world_bank_data, download_kaggle_dataset, load_covid_data, load_gdp_data
  File "/opt/airflow/dags/common_data_loader.py", line 3, in <module>
    import kaggle
ModuleNotFoundError: No module named 'kaggle'
[2024-09-25T22:19:44.420+0000] {processor.py:927} WARNING - No viable dags retrieved from /opt/airflow/dags/covid_gdp_dag.py
[2024-09-25T22:19:44.442+0000] {processor.py:208} INFO - Processing /opt/airflow/dags/covid_gdp_dag.py took 0.057 seconds
[2024-09-25T22:20:14.729+0000] {processor.py:186} INFO - Started process (PID=1263) to work on /opt/airflow/dags/covid_gdp_dag.py
[2024-09-25T22:20:14.730+0000] {processor.py:914} INFO - Processing file /opt/airflow/dags/covid_gdp_dag.py for tasks to queue
[2024-09-25T22:20:14.733+0000] {logging_mixin.py:190} INFO - [2024-09-25T22:20:14.732+0000] {dagbag.py:588} INFO - Filling up the DagBag from /opt/airflow/dags/covid_gdp_dag.py
[2024-09-25T22:20:14.781+0000] {logging_mixin.py:190} INFO - [2024-09-25T22:20:14.749+0000] {dagbag.py:387} ERROR - Failed to import: /opt/airflow/dags/covid_gdp_dag.py
Traceback (most recent call last):
  File "/home/airflow/.local/lib/python3.12/site-packages/airflow/models/dagbag.py", line 383, in parse
    loader.exec_module(new_module)
  File "<frozen importlib._bootstrap_external>", line 995, in exec_module
  File "<frozen importlib._bootstrap>", line 488, in _call_with_frames_removed
  File "/opt/airflow/dags/covid_gdp_dag.py", line 7, in <module>
    from common_data_loader import download_world_bank_data, download_kaggle_dataset, load_covid_data, load_gdp_data
  File "/opt/airflow/dags/common_data_loader.py", line 3, in <module>
    import kaggle
ModuleNotFoundError: No module named 'kaggle'
[2024-09-25T22:20:14.783+0000] {processor.py:927} WARNING - No viable dags retrieved from /opt/airflow/dags/covid_gdp_dag.py
[2024-09-25T22:20:14.805+0000] {processor.py:208} INFO - Processing /opt/airflow/dags/covid_gdp_dag.py took 0.080 seconds
[2024-09-25T22:20:45.499+0000] {processor.py:186} INFO - Started process (PID=1326) to work on /opt/airflow/dags/covid_gdp_dag.py
[2024-09-25T22:20:45.500+0000] {processor.py:914} INFO - Processing file /opt/airflow/dags/covid_gdp_dag.py for tasks to queue
[2024-09-25T22:20:45.503+0000] {logging_mixin.py:190} INFO - [2024-09-25T22:20:45.502+0000] {dagbag.py:588} INFO - Filling up the DagBag from /opt/airflow/dags/covid_gdp_dag.py
[2024-09-25T22:20:45.573+0000] {logging_mixin.py:190} INFO - [2024-09-25T22:20:45.519+0000] {dagbag.py:387} ERROR - Failed to import: /opt/airflow/dags/covid_gdp_dag.py
Traceback (most recent call last):
  File "/home/airflow/.local/lib/python3.12/site-packages/airflow/models/dagbag.py", line 383, in parse
    loader.exec_module(new_module)
  File "<frozen importlib._bootstrap_external>", line 995, in exec_module
  File "<frozen importlib._bootstrap>", line 488, in _call_with_frames_removed
  File "/opt/airflow/dags/covid_gdp_dag.py", line 7, in <module>
    from common_data_loader import download_world_bank_data, download_kaggle_dataset, load_covid_data, load_gdp_data
  File "/opt/airflow/dags/common_data_loader.py", line 3, in <module>
    import kaggle
ModuleNotFoundError: No module named 'kaggle'
[2024-09-25T22:20:45.575+0000] {processor.py:927} WARNING - No viable dags retrieved from /opt/airflow/dags/covid_gdp_dag.py
[2024-09-25T22:20:45.597+0000] {processor.py:208} INFO - Processing /opt/airflow/dags/covid_gdp_dag.py took 0.102 seconds
[2024-09-25T22:21:15.853+0000] {processor.py:186} INFO - Started process (PID=1389) to work on /opt/airflow/dags/covid_gdp_dag.py
[2024-09-25T22:21:15.854+0000] {processor.py:914} INFO - Processing file /opt/airflow/dags/covid_gdp_dag.py for tasks to queue
[2024-09-25T22:21:15.857+0000] {logging_mixin.py:190} INFO - [2024-09-25T22:21:15.856+0000] {dagbag.py:588} INFO - Filling up the DagBag from /opt/airflow/dags/covid_gdp_dag.py
[2024-09-25T22:21:15.879+0000] {logging_mixin.py:190} INFO - [2024-09-25T22:21:15.873+0000] {dagbag.py:387} ERROR - Failed to import: /opt/airflow/dags/covid_gdp_dag.py
Traceback (most recent call last):
  File "/home/airflow/.local/lib/python3.12/site-packages/airflow/models/dagbag.py", line 383, in parse
    loader.exec_module(new_module)
  File "<frozen importlib._bootstrap_external>", line 995, in exec_module
  File "<frozen importlib._bootstrap>", line 488, in _call_with_frames_removed
  File "/opt/airflow/dags/covid_gdp_dag.py", line 7, in <module>
    from common_data_loader import download_world_bank_data, download_kaggle_dataset, load_covid_data, load_gdp_data
  File "/opt/airflow/dags/common_data_loader.py", line 3, in <module>
    import kaggle
ModuleNotFoundError: No module named 'kaggle'
[2024-09-25T22:21:15.881+0000] {processor.py:927} WARNING - No viable dags retrieved from /opt/airflow/dags/covid_gdp_dag.py
[2024-09-25T22:21:15.933+0000] {processor.py:208} INFO - Processing /opt/airflow/dags/covid_gdp_dag.py took 0.085 seconds
[2024-09-25T22:21:46.928+0000] {processor.py:186} INFO - Started process (PID=1452) to work on /opt/airflow/dags/covid_gdp_dag.py
[2024-09-25T22:21:46.930+0000] {processor.py:914} INFO - Processing file /opt/airflow/dags/covid_gdp_dag.py for tasks to queue
[2024-09-25T22:21:46.932+0000] {logging_mixin.py:190} INFO - [2024-09-25T22:21:46.932+0000] {dagbag.py:588} INFO - Filling up the DagBag from /opt/airflow/dags/covid_gdp_dag.py
[2024-09-25T22:21:46.951+0000] {logging_mixin.py:190} INFO - [2024-09-25T22:21:46.947+0000] {dagbag.py:387} ERROR - Failed to import: /opt/airflow/dags/covid_gdp_dag.py
Traceback (most recent call last):
  File "/home/airflow/.local/lib/python3.12/site-packages/airflow/models/dagbag.py", line 383, in parse
    loader.exec_module(new_module)
  File "<frozen importlib._bootstrap_external>", line 995, in exec_module
  File "<frozen importlib._bootstrap>", line 488, in _call_with_frames_removed
  File "/opt/airflow/dags/covid_gdp_dag.py", line 7, in <module>
    from common_data_loader import download_world_bank_data, download_kaggle_dataset, load_covid_data, load_gdp_data
  File "/opt/airflow/dags/common_data_loader.py", line 3, in <module>
    import kaggle
ModuleNotFoundError: No module named 'kaggle'
[2024-09-25T22:21:46.953+0000] {processor.py:927} WARNING - No viable dags retrieved from /opt/airflow/dags/covid_gdp_dag.py
[2024-09-25T22:21:46.974+0000] {processor.py:208} INFO - Processing /opt/airflow/dags/covid_gdp_dag.py took 0.050 seconds
[2024-09-25T22:22:17.332+0000] {processor.py:186} INFO - Started process (PID=1515) to work on /opt/airflow/dags/covid_gdp_dag.py
[2024-09-25T22:22:17.333+0000] {processor.py:914} INFO - Processing file /opt/airflow/dags/covid_gdp_dag.py for tasks to queue
[2024-09-25T22:22:17.335+0000] {logging_mixin.py:190} INFO - [2024-09-25T22:22:17.335+0000] {dagbag.py:588} INFO - Filling up the DagBag from /opt/airflow/dags/covid_gdp_dag.py
[2024-09-25T22:22:17.359+0000] {logging_mixin.py:190} INFO - [2024-09-25T22:22:17.353+0000] {dagbag.py:387} ERROR - Failed to import: /opt/airflow/dags/covid_gdp_dag.py
Traceback (most recent call last):
  File "/home/airflow/.local/lib/python3.12/site-packages/airflow/models/dagbag.py", line 383, in parse
    loader.exec_module(new_module)
  File "<frozen importlib._bootstrap_external>", line 995, in exec_module
  File "<frozen importlib._bootstrap>", line 488, in _call_with_frames_removed
  File "/opt/airflow/dags/covid_gdp_dag.py", line 7, in <module>
    from common_data_loader import download_world_bank_data, download_kaggle_dataset, load_covid_data, load_gdp_data
  File "/opt/airflow/dags/common_data_loader.py", line 3, in <module>
    import kaggle
ModuleNotFoundError: No module named 'kaggle'
[2024-09-25T22:22:17.367+0000] {processor.py:927} WARNING - No viable dags retrieved from /opt/airflow/dags/covid_gdp_dag.py
[2024-09-25T22:22:17.424+0000] {processor.py:208} INFO - Processing /opt/airflow/dags/covid_gdp_dag.py took 0.100 seconds
[2024-09-25T22:22:47.539+0000] {processor.py:186} INFO - Started process (PID=1578) to work on /opt/airflow/dags/covid_gdp_dag.py
[2024-09-25T22:22:47.540+0000] {processor.py:914} INFO - Processing file /opt/airflow/dags/covid_gdp_dag.py for tasks to queue
[2024-09-25T22:22:47.543+0000] {logging_mixin.py:190} INFO - [2024-09-25T22:22:47.542+0000] {dagbag.py:588} INFO - Filling up the DagBag from /opt/airflow/dags/covid_gdp_dag.py
[2024-09-25T22:22:47.569+0000] {logging_mixin.py:190} INFO - [2024-09-25T22:22:47.563+0000] {dagbag.py:387} ERROR - Failed to import: /opt/airflow/dags/covid_gdp_dag.py
Traceback (most recent call last):
  File "/home/airflow/.local/lib/python3.12/site-packages/airflow/models/dagbag.py", line 383, in parse
    loader.exec_module(new_module)
  File "<frozen importlib._bootstrap_external>", line 995, in exec_module
  File "<frozen importlib._bootstrap>", line 488, in _call_with_frames_removed
  File "/opt/airflow/dags/covid_gdp_dag.py", line 7, in <module>
    from common_data_loader import download_world_bank_data, download_kaggle_dataset, load_covid_data, load_gdp_data
  File "/opt/airflow/dags/common_data_loader.py", line 3, in <module>
    import kaggle
ModuleNotFoundError: No module named 'kaggle'
[2024-09-25T22:22:47.571+0000] {processor.py:927} WARNING - No viable dags retrieved from /opt/airflow/dags/covid_gdp_dag.py
[2024-09-25T22:22:47.635+0000] {processor.py:208} INFO - Processing /opt/airflow/dags/covid_gdp_dag.py took 0.101 seconds
[2024-09-25T22:23:17.823+0000] {processor.py:186} INFO - Started process (PID=1641) to work on /opt/airflow/dags/covid_gdp_dag.py
[2024-09-25T22:23:17.824+0000] {processor.py:914} INFO - Processing file /opt/airflow/dags/covid_gdp_dag.py for tasks to queue
[2024-09-25T22:23:17.828+0000] {logging_mixin.py:190} INFO - [2024-09-25T22:23:17.827+0000] {dagbag.py:588} INFO - Filling up the DagBag from /opt/airflow/dags/covid_gdp_dag.py
[2024-09-25T22:23:17.857+0000] {logging_mixin.py:190} INFO - [2024-09-25T22:23:17.850+0000] {dagbag.py:387} ERROR - Failed to import: /opt/airflow/dags/covid_gdp_dag.py
Traceback (most recent call last):
  File "/home/airflow/.local/lib/python3.12/site-packages/airflow/models/dagbag.py", line 383, in parse
    loader.exec_module(new_module)
  File "<frozen importlib._bootstrap_external>", line 995, in exec_module
  File "<frozen importlib._bootstrap>", line 488, in _call_with_frames_removed
  File "/opt/airflow/dags/covid_gdp_dag.py", line 7, in <module>
    from common_data_loader import download_world_bank_data, download_kaggle_dataset, load_covid_data, load_gdp_data
  File "/opt/airflow/dags/common_data_loader.py", line 3, in <module>
    import kaggle
ModuleNotFoundError: No module named 'kaggle'
[2024-09-25T22:23:17.860+0000] {processor.py:927} WARNING - No viable dags retrieved from /opt/airflow/dags/covid_gdp_dag.py
[2024-09-25T22:23:17.925+0000] {processor.py:208} INFO - Processing /opt/airflow/dags/covid_gdp_dag.py took 0.109 seconds
[2024-09-25T22:23:48.197+0000] {processor.py:186} INFO - Started process (PID=1704) to work on /opt/airflow/dags/covid_gdp_dag.py
[2024-09-25T22:23:48.198+0000] {processor.py:914} INFO - Processing file /opt/airflow/dags/covid_gdp_dag.py for tasks to queue
[2024-09-25T22:23:48.202+0000] {logging_mixin.py:190} INFO - [2024-09-25T22:23:48.201+0000] {dagbag.py:588} INFO - Filling up the DagBag from /opt/airflow/dags/covid_gdp_dag.py
[2024-09-25T22:23:48.244+0000] {logging_mixin.py:190} INFO - [2024-09-25T22:23:48.233+0000] {dagbag.py:387} ERROR - Failed to import: /opt/airflow/dags/covid_gdp_dag.py
Traceback (most recent call last):
  File "/home/airflow/.local/lib/python3.12/site-packages/airflow/models/dagbag.py", line 383, in parse
    loader.exec_module(new_module)
  File "<frozen importlib._bootstrap_external>", line 995, in exec_module
  File "<frozen importlib._bootstrap>", line 488, in _call_with_frames_removed
  File "/opt/airflow/dags/covid_gdp_dag.py", line 7, in <module>
    from common_data_loader import download_world_bank_data, download_kaggle_dataset, load_covid_data, load_gdp_data
  File "/opt/airflow/dags/common_data_loader.py", line 3, in <module>
    import kaggle
ModuleNotFoundError: No module named 'kaggle'
[2024-09-25T22:23:48.249+0000] {processor.py:927} WARNING - No viable dags retrieved from /opt/airflow/dags/covid_gdp_dag.py
[2024-09-25T22:23:48.287+0000] {processor.py:208} INFO - Processing /opt/airflow/dags/covid_gdp_dag.py took 0.099 seconds
[2024-09-25T22:24:18.565+0000] {processor.py:186} INFO - Started process (PID=1768) to work on /opt/airflow/dags/covid_gdp_dag.py
[2024-09-25T22:24:18.566+0000] {processor.py:914} INFO - Processing file /opt/airflow/dags/covid_gdp_dag.py for tasks to queue
[2024-09-25T22:24:18.569+0000] {logging_mixin.py:190} INFO - [2024-09-25T22:24:18.569+0000] {dagbag.py:588} INFO - Filling up the DagBag from /opt/airflow/dags/covid_gdp_dag.py
[2024-09-25T22:24:18.591+0000] {logging_mixin.py:190} INFO - [2024-09-25T22:24:18.586+0000] {dagbag.py:387} ERROR - Failed to import: /opt/airflow/dags/covid_gdp_dag.py
Traceback (most recent call last):
  File "/home/airflow/.local/lib/python3.12/site-packages/airflow/models/dagbag.py", line 383, in parse
    loader.exec_module(new_module)
  File "<frozen importlib._bootstrap_external>", line 995, in exec_module
  File "<frozen importlib._bootstrap>", line 488, in _call_with_frames_removed
  File "/opt/airflow/dags/covid_gdp_dag.py", line 7, in <module>
    from common_data_loader import download_world_bank_data, download_kaggle_dataset, load_covid_data, load_gdp_data
  File "/opt/airflow/dags/common_data_loader.py", line 3, in <module>
    import kaggle
ModuleNotFoundError: No module named 'kaggle'
[2024-09-25T22:24:18.593+0000] {processor.py:927} WARNING - No viable dags retrieved from /opt/airflow/dags/covid_gdp_dag.py
[2024-09-25T22:24:18.653+0000] {processor.py:208} INFO - Processing /opt/airflow/dags/covid_gdp_dag.py took 0.093 seconds
[2024-09-25T22:24:49.428+0000] {processor.py:186} INFO - Started process (PID=1831) to work on /opt/airflow/dags/covid_gdp_dag.py
[2024-09-25T22:24:49.430+0000] {processor.py:914} INFO - Processing file /opt/airflow/dags/covid_gdp_dag.py for tasks to queue
[2024-09-25T22:24:49.433+0000] {logging_mixin.py:190} INFO - [2024-09-25T22:24:49.432+0000] {dagbag.py:588} INFO - Filling up the DagBag from /opt/airflow/dags/covid_gdp_dag.py
[2024-09-25T22:24:49.465+0000] {logging_mixin.py:190} INFO - [2024-09-25T22:24:49.454+0000] {dagbag.py:387} ERROR - Failed to import: /opt/airflow/dags/covid_gdp_dag.py
Traceback (most recent call last):
  File "/home/airflow/.local/lib/python3.12/site-packages/airflow/models/dagbag.py", line 383, in parse
    loader.exec_module(new_module)
  File "<frozen importlib._bootstrap_external>", line 995, in exec_module
  File "<frozen importlib._bootstrap>", line 488, in _call_with_frames_removed
  File "/opt/airflow/dags/covid_gdp_dag.py", line 7, in <module>
    from common_data_loader import download_world_bank_data, download_kaggle_dataset, load_covid_data, load_gdp_data
  File "/opt/airflow/dags/common_data_loader.py", line 3, in <module>
    import kaggle
ModuleNotFoundError: No module named 'kaggle'
[2024-09-25T22:24:49.468+0000] {processor.py:927} WARNING - No viable dags retrieved from /opt/airflow/dags/covid_gdp_dag.py
[2024-09-25T22:24:49.510+0000] {processor.py:208} INFO - Processing /opt/airflow/dags/covid_gdp_dag.py took 0.107 seconds
[2024-09-25T22:25:19.622+0000] {processor.py:186} INFO - Started process (PID=1894) to work on /opt/airflow/dags/covid_gdp_dag.py
[2024-09-25T22:25:19.624+0000] {processor.py:914} INFO - Processing file /opt/airflow/dags/covid_gdp_dag.py for tasks to queue
[2024-09-25T22:25:19.628+0000] {logging_mixin.py:190} INFO - [2024-09-25T22:25:19.628+0000] {dagbag.py:588} INFO - Filling up the DagBag from /opt/airflow/dags/covid_gdp_dag.py
[2024-09-25T22:25:19.660+0000] {logging_mixin.py:190} INFO - [2024-09-25T22:25:19.652+0000] {dagbag.py:387} ERROR - Failed to import: /opt/airflow/dags/covid_gdp_dag.py
Traceback (most recent call last):
  File "/home/airflow/.local/lib/python3.12/site-packages/airflow/models/dagbag.py", line 383, in parse
    loader.exec_module(new_module)
  File "<frozen importlib._bootstrap_external>", line 995, in exec_module
  File "<frozen importlib._bootstrap>", line 488, in _call_with_frames_removed
  File "/opt/airflow/dags/covid_gdp_dag.py", line 7, in <module>
    from common_data_loader import download_world_bank_data, download_kaggle_dataset, load_covid_data, load_gdp_data
  File "/opt/airflow/dags/common_data_loader.py", line 3, in <module>
    import kaggle
ModuleNotFoundError: No module named 'kaggle'
[2024-09-25T22:25:19.664+0000] {processor.py:927} WARNING - No viable dags retrieved from /opt/airflow/dags/covid_gdp_dag.py
[2024-09-25T22:25:19.698+0000] {processor.py:208} INFO - Processing /opt/airflow/dags/covid_gdp_dag.py took 0.084 seconds
[2024-09-25T22:25:50.104+0000] {processor.py:186} INFO - Started process (PID=1957) to work on /opt/airflow/dags/covid_gdp_dag.py
[2024-09-25T22:25:50.105+0000] {processor.py:914} INFO - Processing file /opt/airflow/dags/covid_gdp_dag.py for tasks to queue
[2024-09-25T22:25:50.107+0000] {logging_mixin.py:190} INFO - [2024-09-25T22:25:50.107+0000] {dagbag.py:588} INFO - Filling up the DagBag from /opt/airflow/dags/covid_gdp_dag.py
[2024-09-25T22:25:50.133+0000] {logging_mixin.py:190} INFO - [2024-09-25T22:25:50.125+0000] {dagbag.py:387} ERROR - Failed to import: /opt/airflow/dags/covid_gdp_dag.py
Traceback (most recent call last):
  File "/home/airflow/.local/lib/python3.12/site-packages/airflow/models/dagbag.py", line 383, in parse
    loader.exec_module(new_module)
  File "<frozen importlib._bootstrap_external>", line 995, in exec_module
  File "<frozen importlib._bootstrap>", line 488, in _call_with_frames_removed
  File "/opt/airflow/dags/covid_gdp_dag.py", line 7, in <module>
    from common_data_loader import download_world_bank_data, download_kaggle_dataset, load_covid_data, load_gdp_data
  File "/opt/airflow/dags/common_data_loader.py", line 3, in <module>
    import kaggle
ModuleNotFoundError: No module named 'kaggle'
[2024-09-25T22:25:50.135+0000] {processor.py:927} WARNING - No viable dags retrieved from /opt/airflow/dags/covid_gdp_dag.py
[2024-09-25T22:25:50.158+0000] {processor.py:208} INFO - Processing /opt/airflow/dags/covid_gdp_dag.py took 0.058 seconds
[2024-09-25T22:26:20.420+0000] {processor.py:186} INFO - Started process (PID=2020) to work on /opt/airflow/dags/covid_gdp_dag.py
[2024-09-25T22:26:20.421+0000] {processor.py:914} INFO - Processing file /opt/airflow/dags/covid_gdp_dag.py for tasks to queue
[2024-09-25T22:26:20.423+0000] {logging_mixin.py:190} INFO - [2024-09-25T22:26:20.423+0000] {dagbag.py:588} INFO - Filling up the DagBag from /opt/airflow/dags/covid_gdp_dag.py
[2024-09-25T22:26:20.449+0000] {logging_mixin.py:190} INFO - [2024-09-25T22:26:20.440+0000] {dagbag.py:387} ERROR - Failed to import: /opt/airflow/dags/covid_gdp_dag.py
Traceback (most recent call last):
  File "/home/airflow/.local/lib/python3.12/site-packages/airflow/models/dagbag.py", line 383, in parse
    loader.exec_module(new_module)
  File "<frozen importlib._bootstrap_external>", line 995, in exec_module
  File "<frozen importlib._bootstrap>", line 488, in _call_with_frames_removed
  File "/opt/airflow/dags/covid_gdp_dag.py", line 7, in <module>
    from common_data_loader import download_world_bank_data, download_kaggle_dataset, load_covid_data, load_gdp_data
  File "/opt/airflow/dags/common_data_loader.py", line 3, in <module>
    import kaggle
ModuleNotFoundError: No module named 'kaggle'
[2024-09-25T22:26:20.452+0000] {processor.py:927} WARNING - No viable dags retrieved from /opt/airflow/dags/covid_gdp_dag.py
[2024-09-25T22:26:20.475+0000] {processor.py:208} INFO - Processing /opt/airflow/dags/covid_gdp_dag.py took 0.060 seconds
[2024-09-25T22:26:51.431+0000] {processor.py:186} INFO - Started process (PID=2082) to work on /opt/airflow/dags/covid_gdp_dag.py
[2024-09-25T22:26:51.442+0000] {processor.py:914} INFO - Processing file /opt/airflow/dags/covid_gdp_dag.py for tasks to queue
[2024-09-25T22:26:51.457+0000] {logging_mixin.py:190} INFO - [2024-09-25T22:26:51.449+0000] {dagbag.py:588} INFO - Filling up the DagBag from /opt/airflow/dags/covid_gdp_dag.py
[2024-09-25T22:26:51.725+0000] {logging_mixin.py:190} INFO - [2024-09-25T22:26:51.532+0000] {dagbag.py:387} ERROR - Failed to import: /opt/airflow/dags/covid_gdp_dag.py
Traceback (most recent call last):
  File "/home/airflow/.local/lib/python3.12/site-packages/airflow/models/dagbag.py", line 383, in parse
    loader.exec_module(new_module)
  File "<frozen importlib._bootstrap_external>", line 995, in exec_module
  File "<frozen importlib._bootstrap>", line 488, in _call_with_frames_removed
  File "/opt/airflow/dags/covid_gdp_dag.py", line 7, in <module>
    from common_data_loader import download_world_bank_data, download_kaggle_dataset, load_covid_data, load_gdp_data
  File "/opt/airflow/dags/common_data_loader.py", line 3, in <module>
    import kaggle
ModuleNotFoundError: No module named 'kaggle'
[2024-09-25T22:26:51.871+0000] {processor.py:927} WARNING - No viable dags retrieved from /opt/airflow/dags/covid_gdp_dag.py
[2024-09-25T22:27:09.737+0000] {processor.py:211} ERROR - Got an exception! Propagating...
Traceback (most recent call last):
  File "/home/airflow/.local/lib/python3.12/site-packages/sqlalchemy/engine/base.py", line 3371, in _wrap_pool_connect
    return fn()
           ^^^^
  File "/home/airflow/.local/lib/python3.12/site-packages/sqlalchemy/pool/base.py", line 327, in connect
    return _ConnectionFairy._checkout(self)
           ^^^^^^^^^^^^^^^^^^^^^^^^^^^^^^^^
  File "/home/airflow/.local/lib/python3.12/site-packages/sqlalchemy/pool/base.py", line 894, in _checkout
    fairy = _ConnectionRecord.checkout(pool)
            ^^^^^^^^^^^^^^^^^^^^^^^^^^^^^^^^
  File "/home/airflow/.local/lib/python3.12/site-packages/sqlalchemy/pool/base.py", line 493, in checkout
    rec = pool._do_get()
          ^^^^^^^^^^^^^^
  File "/home/airflow/.local/lib/python3.12/site-packages/sqlalchemy/pool/impl.py", line 145, in _do_get
    with util.safe_reraise():
         ^^^^^^^^^^^^^^^^^^^
  File "/home/airflow/.local/lib/python3.12/site-packages/sqlalchemy/util/langhelpers.py", line 70, in __exit__
    compat.raise_(
  File "/home/airflow/.local/lib/python3.12/site-packages/sqlalchemy/util/compat.py", line 211, in raise_
    raise exception
  File "/home/airflow/.local/lib/python3.12/site-packages/sqlalchemy/pool/impl.py", line 143, in _do_get
    return self._create_connection()
           ^^^^^^^^^^^^^^^^^^^^^^^^^
  File "/home/airflow/.local/lib/python3.12/site-packages/sqlalchemy/pool/base.py", line 273, in _create_connection
    return _ConnectionRecord(self)
           ^^^^^^^^^^^^^^^^^^^^^^^
  File "/home/airflow/.local/lib/python3.12/site-packages/sqlalchemy/pool/base.py", line 388, in __init__
    self.__connect()
  File "/home/airflow/.local/lib/python3.12/site-packages/sqlalchemy/pool/base.py", line 690, in __connect
    with util.safe_reraise():
         ^^^^^^^^^^^^^^^^^^^
  File "/home/airflow/.local/lib/python3.12/site-packages/sqlalchemy/util/langhelpers.py", line 70, in __exit__
    compat.raise_(
  File "/home/airflow/.local/lib/python3.12/site-packages/sqlalchemy/util/compat.py", line 211, in raise_
    raise exception
  File "/home/airflow/.local/lib/python3.12/site-packages/sqlalchemy/pool/base.py", line 686, in __connect
    self.dbapi_connection = connection = pool._invoke_creator(self)
                                         ^^^^^^^^^^^^^^^^^^^^^^^^^^
  File "/home/airflow/.local/lib/python3.12/site-packages/sqlalchemy/engine/create.py", line 574, in connect
    return dialect.connect(*cargs, **cparams)
           ^^^^^^^^^^^^^^^^^^^^^^^^^^^^^^^^^^
  File "/home/airflow/.local/lib/python3.12/site-packages/sqlalchemy/engine/default.py", line 598, in connect
    return self.dbapi.connect(*cargs, **cparams)
           ^^^^^^^^^^^^^^^^^^^^^^^^^^^^^^^^^^^^^
  File "/home/airflow/.local/lib/python3.12/site-packages/psycopg2/__init__.py", line 122, in connect
    conn = _connect(dsn, connection_factory=connection_factory, **kwasync)
           ^^^^^^^^^^^^^^^^^^^^^^^^^^^^^^^^^^^^^^^^^^^^^^^^^^^^^^^^^^^^^^^
psycopg2.OperationalError: could not translate host name "postgres" to address: Temporary failure in name resolution


The above exception was the direct cause of the following exception:

Traceback (most recent call last):
  File "/home/airflow/.local/lib/python3.12/site-packages/airflow/dag_processing/processor.py", line 207, in _run_file_processor
    _handle_dag_file_processing()
  File "/home/airflow/.local/lib/python3.12/site-packages/airflow/dag_processing/processor.py", line 188, in _handle_dag_file_processing
    result: tuple[int, int, int] = dag_file_processor.process_file(
                                   ^^^^^^^^^^^^^^^^^^^^^^^^^^^^^^^^
  File "/home/airflow/.local/lib/python3.12/site-packages/airflow/utils/session.py", line 97, in wrapper
    return func(*args, session=session, **kwargs)
           ^^^^^^^^^^^^^^^^^^^^^^^^^^^^^^^^^^^^^^
  File "/home/airflow/.local/lib/python3.12/site-packages/airflow/dag_processing/processor.py", line 928, in process_file
    DagFileProcessor.update_import_errors(
  File "/home/airflow/.local/lib/python3.12/site-packages/airflow/api_internal/internal_api_call.py", line 139, in wrapper
    return func(*args, **kwargs)
           ^^^^^^^^^^^^^^^^^^^^^
  File "/home/airflow/.local/lib/python3.12/site-packages/airflow/utils/session.py", line 97, in wrapper
    return func(*args, session=session, **kwargs)
           ^^^^^^^^^^^^^^^^^^^^^^^^^^^^^^^^^^^^^^
  File "/home/airflow/.local/lib/python3.12/site-packages/airflow/dag_processing/processor.py", line 648, in update_import_errors
    existing_import_error_files = [x.filename for x in session.query(ParseImportError.filename).all()]
                                                       ^^^^^^^^^^^^^^^^^^^^^^^^^^^^^^^^^^^^^^^^^^^^^^
  File "/home/airflow/.local/lib/python3.12/site-packages/sqlalchemy/orm/query.py", line 2773, in all
    return self._iter().all()
           ^^^^^^^^^^^^
  File "/home/airflow/.local/lib/python3.12/site-packages/sqlalchemy/orm/query.py", line 2916, in _iter
    result = self.session.execute(
             ^^^^^^^^^^^^^^^^^^^^^
  File "/home/airflow/.local/lib/python3.12/site-packages/sqlalchemy/orm/session.py", line 1716, in execute
    conn = self._connection_for_bind(bind)
           ^^^^^^^^^^^^^^^^^^^^^^^^^^^^^^^
  File "/home/airflow/.local/lib/python3.12/site-packages/sqlalchemy/orm/session.py", line 1555, in _connection_for_bind
    return self._transaction._connection_for_bind(
           ^^^^^^^^^^^^^^^^^^^^^^^^^^^^^^^^^^^^^^^
  File "/home/airflow/.local/lib/python3.12/site-packages/sqlalchemy/orm/session.py", line 750, in _connection_for_bind
    conn = bind.connect()
           ^^^^^^^^^^^^^^
  File "/home/airflow/.local/lib/python3.12/site-packages/sqlalchemy/future/engine.py", line 412, in connect
    return super(Engine, self).connect()
           ^^^^^^^^^^^^^^^^^^^^^^^^^^^^^
  File "/home/airflow/.local/lib/python3.12/site-packages/sqlalchemy/engine/base.py", line 3325, in connect
    return self._connection_cls(self, close_with_result=close_with_result)
           ^^^^^^^^^^^^^^^^^^^^^^^^^^^^^^^^^^^^^^^^^^^^^^^^^^^^^^^^^^^^^^^
  File "/home/airflow/.local/lib/python3.12/site-packages/sqlalchemy/engine/base.py", line 96, in __init__
    else engine.raw_connection()
         ^^^^^^^^^^^^^^^^^^^^^^^
  File "/home/airflow/.local/lib/python3.12/site-packages/sqlalchemy/engine/base.py", line 3404, in raw_connection
    return self._wrap_pool_connect(self.pool.connect, _connection)
           ^^^^^^^^^^^^^^^^^^^^^^^^^^^^^^^^^^^^^^^^^^^^^^^^^^^^^^^
  File "/home/airflow/.local/lib/python3.12/site-packages/sqlalchemy/engine/base.py", line 3374, in _wrap_pool_connect
    Connection._handle_dbapi_exception_noconnection(
  File "/home/airflow/.local/lib/python3.12/site-packages/sqlalchemy/engine/base.py", line 2208, in _handle_dbapi_exception_noconnection
    util.raise_(
  File "/home/airflow/.local/lib/python3.12/site-packages/sqlalchemy/util/compat.py", line 211, in raise_
    raise exception
  File "/home/airflow/.local/lib/python3.12/site-packages/sqlalchemy/engine/base.py", line 3371, in _wrap_pool_connect
    return fn()
           ^^^^
  File "/home/airflow/.local/lib/python3.12/site-packages/sqlalchemy/pool/base.py", line 327, in connect
    return _ConnectionFairy._checkout(self)
           ^^^^^^^^^^^^^^^^^^^^^^^^^^^^^^^^
  File "/home/airflow/.local/lib/python3.12/site-packages/sqlalchemy/pool/base.py", line 894, in _checkout
    fairy = _ConnectionRecord.checkout(pool)
            ^^^^^^^^^^^^^^^^^^^^^^^^^^^^^^^^
  File "/home/airflow/.local/lib/python3.12/site-packages/sqlalchemy/pool/base.py", line 493, in checkout
    rec = pool._do_get()
          ^^^^^^^^^^^^^^
  File "/home/airflow/.local/lib/python3.12/site-packages/sqlalchemy/pool/impl.py", line 145, in _do_get
    with util.safe_reraise():
         ^^^^^^^^^^^^^^^^^^^
  File "/home/airflow/.local/lib/python3.12/site-packages/sqlalchemy/util/langhelpers.py", line 70, in __exit__
    compat.raise_(
  File "/home/airflow/.local/lib/python3.12/site-packages/sqlalchemy/util/compat.py", line 211, in raise_
    raise exception
  File "/home/airflow/.local/lib/python3.12/site-packages/sqlalchemy/pool/impl.py", line 143, in _do_get
    return self._create_connection()
           ^^^^^^^^^^^^^^^^^^^^^^^^^
  File "/home/airflow/.local/lib/python3.12/site-packages/sqlalchemy/pool/base.py", line 273, in _create_connection
    return _ConnectionRecord(self)
           ^^^^^^^^^^^^^^^^^^^^^^^
  File "/home/airflow/.local/lib/python3.12/site-packages/sqlalchemy/pool/base.py", line 388, in __init__
    self.__connect()
  File "/home/airflow/.local/lib/python3.12/site-packages/sqlalchemy/pool/base.py", line 690, in __connect
    with util.safe_reraise():
         ^^^^^^^^^^^^^^^^^^^
  File "/home/airflow/.local/lib/python3.12/site-packages/sqlalchemy/util/langhelpers.py", line 70, in __exit__
    compat.raise_(
  File "/home/airflow/.local/lib/python3.12/site-packages/sqlalchemy/util/compat.py", line 211, in raise_
    raise exception
  File "/home/airflow/.local/lib/python3.12/site-packages/sqlalchemy/pool/base.py", line 686, in __connect
    self.dbapi_connection = connection = pool._invoke_creator(self)
                                         ^^^^^^^^^^^^^^^^^^^^^^^^^^
  File "/home/airflow/.local/lib/python3.12/site-packages/sqlalchemy/engine/create.py", line 574, in connect
    return dialect.connect(*cargs, **cparams)
           ^^^^^^^^^^^^^^^^^^^^^^^^^^^^^^^^^^
  File "/home/airflow/.local/lib/python3.12/site-packages/sqlalchemy/engine/default.py", line 598, in connect
    return self.dbapi.connect(*cargs, **cparams)
           ^^^^^^^^^^^^^^^^^^^^^^^^^^^^^^^^^^^^^
  File "/home/airflow/.local/lib/python3.12/site-packages/psycopg2/__init__.py", line 122, in connect
    conn = _connect(dsn, connection_factory=connection_factory, **kwasync)
           ^^^^^^^^^^^^^^^^^^^^^^^^^^^^^^^^^^^^^^^^^^^^^^^^^^^^^^^^^^^^^^^
sqlalchemy.exc.OperationalError: (psycopg2.OperationalError) could not translate host name "postgres" to address: Temporary failure in name resolution

(Background on this error at: https://sqlalche.me/e/14/e3q8)
[2024-09-25T22:27:40.746+0000] {processor.py:186} INFO - Started process (PID=2146) to work on /opt/airflow/dags/covid_gdp_dag.py
[2024-09-25T22:27:40.747+0000] {processor.py:914} INFO - Processing file /opt/airflow/dags/covid_gdp_dag.py for tasks to queue
[2024-09-25T22:27:40.750+0000] {logging_mixin.py:190} INFO - [2024-09-25T22:27:40.749+0000] {dagbag.py:588} INFO - Filling up the DagBag from /opt/airflow/dags/covid_gdp_dag.py
[2024-09-25T22:27:40.776+0000] {logging_mixin.py:190} INFO - [2024-09-25T22:27:40.767+0000] {dagbag.py:387} ERROR - Failed to import: /opt/airflow/dags/covid_gdp_dag.py
Traceback (most recent call last):
  File "/home/airflow/.local/lib/python3.12/site-packages/airflow/models/dagbag.py", line 383, in parse
    loader.exec_module(new_module)
  File "<frozen importlib._bootstrap_external>", line 995, in exec_module
  File "<frozen importlib._bootstrap>", line 488, in _call_with_frames_removed
  File "/opt/airflow/dags/covid_gdp_dag.py", line 7, in <module>
    from common_data_loader import download_world_bank_data, download_kaggle_dataset, load_covid_data, load_gdp_data
  File "/opt/airflow/dags/common_data_loader.py", line 3, in <module>
    import kaggle
ModuleNotFoundError: No module named 'kaggle'
[2024-09-25T22:27:40.778+0000] {processor.py:927} WARNING - No viable dags retrieved from /opt/airflow/dags/covid_gdp_dag.py
[2024-09-25T22:27:40.799+0000] {processor.py:208} INFO - Processing /opt/airflow/dags/covid_gdp_dag.py took 0.058 seconds
[2024-09-25T22:28:14.183+0000] {processor.py:186} INFO - Started process (PID=2169) to work on /opt/airflow/dags/covid_gdp_dag.py
[2024-09-25T22:28:14.196+0000] {processor.py:914} INFO - Processing file /opt/airflow/dags/covid_gdp_dag.py for tasks to queue
[2024-09-25T22:28:14.202+0000] {logging_mixin.py:190} INFO - [2024-09-25T22:28:14.201+0000] {dagbag.py:588} INFO - Filling up the DagBag from /opt/airflow/dags/covid_gdp_dag.py
[2024-09-25T22:28:14.376+0000] {logging_mixin.py:190} INFO - [2024-09-25T22:28:14.350+0000] {dagbag.py:387} ERROR - Failed to import: /opt/airflow/dags/covid_gdp_dag.py
Traceback (most recent call last):
  File "/home/airflow/.local/lib/python3.12/site-packages/airflow/models/dagbag.py", line 383, in parse
    loader.exec_module(new_module)
  File "<frozen importlib._bootstrap_external>", line 995, in exec_module
  File "<frozen importlib._bootstrap>", line 488, in _call_with_frames_removed
  File "/opt/airflow/dags/covid_gdp_dag.py", line 7, in <module>
    from common_data_loader import download_world_bank_data, download_kaggle_dataset, load_covid_data, load_gdp_data
  File "/opt/airflow/dags/common_data_loader.py", line 3, in <module>
    import kaggle
ModuleNotFoundError: No module named 'kaggle'
[2024-09-25T22:28:14.380+0000] {processor.py:927} WARNING - No viable dags retrieved from /opt/airflow/dags/covid_gdp_dag.py
[2024-09-25T22:28:14.823+0000] {processor.py:208} INFO - Processing /opt/airflow/dags/covid_gdp_dag.py took 0.665 seconds
[2024-09-25T22:28:45.436+0000] {processor.py:186} INFO - Started process (PID=2230) to work on /opt/airflow/dags/covid_gdp_dag.py
[2024-09-25T22:28:45.438+0000] {processor.py:914} INFO - Processing file /opt/airflow/dags/covid_gdp_dag.py for tasks to queue
[2024-09-25T22:28:45.442+0000] {logging_mixin.py:190} INFO - [2024-09-25T22:28:45.441+0000] {dagbag.py:588} INFO - Filling up the DagBag from /opt/airflow/dags/covid_gdp_dag.py
[2024-09-25T22:28:45.487+0000] {logging_mixin.py:190} INFO - [2024-09-25T22:28:45.474+0000] {dagbag.py:387} ERROR - Failed to import: /opt/airflow/dags/covid_gdp_dag.py
Traceback (most recent call last):
  File "/home/airflow/.local/lib/python3.12/site-packages/airflow/models/dagbag.py", line 383, in parse
    loader.exec_module(new_module)
  File "<frozen importlib._bootstrap_external>", line 995, in exec_module
  File "<frozen importlib._bootstrap>", line 488, in _call_with_frames_removed
  File "/opt/airflow/dags/covid_gdp_dag.py", line 7, in <module>
    from common_data_loader import download_world_bank_data, download_kaggle_dataset, load_covid_data, load_gdp_data
  File "/opt/airflow/dags/common_data_loader.py", line 3, in <module>
    import kaggle
ModuleNotFoundError: No module named 'kaggle'
[2024-09-25T22:28:45.491+0000] {processor.py:927} WARNING - No viable dags retrieved from /opt/airflow/dags/covid_gdp_dag.py
[2024-09-25T22:28:45.522+0000] {processor.py:208} INFO - Processing /opt/airflow/dags/covid_gdp_dag.py took 0.094 seconds
[2024-09-25T22:29:15.712+0000] {processor.py:186} INFO - Started process (PID=2291) to work on /opt/airflow/dags/covid_gdp_dag.py
[2024-09-25T22:29:15.713+0000] {processor.py:914} INFO - Processing file /opt/airflow/dags/covid_gdp_dag.py for tasks to queue
[2024-09-25T22:29:15.716+0000] {logging_mixin.py:190} INFO - [2024-09-25T22:29:15.715+0000] {dagbag.py:588} INFO - Filling up the DagBag from /opt/airflow/dags/covid_gdp_dag.py
[2024-09-25T22:29:15.743+0000] {logging_mixin.py:190} INFO - [2024-09-25T22:29:15.736+0000] {dagbag.py:387} ERROR - Failed to import: /opt/airflow/dags/covid_gdp_dag.py
Traceback (most recent call last):
  File "/home/airflow/.local/lib/python3.12/site-packages/airflow/models/dagbag.py", line 383, in parse
    loader.exec_module(new_module)
  File "<frozen importlib._bootstrap_external>", line 995, in exec_module
  File "<frozen importlib._bootstrap>", line 488, in _call_with_frames_removed
  File "/opt/airflow/dags/covid_gdp_dag.py", line 7, in <module>
    from common_data_loader import download_world_bank_data, download_kaggle_dataset, load_covid_data, load_gdp_data
  File "/opt/airflow/dags/common_data_loader.py", line 3, in <module>
    import kaggle
ModuleNotFoundError: No module named 'kaggle'
[2024-09-25T22:29:15.746+0000] {processor.py:927} WARNING - No viable dags retrieved from /opt/airflow/dags/covid_gdp_dag.py
[2024-09-25T22:29:15.772+0000] {processor.py:208} INFO - Processing /opt/airflow/dags/covid_gdp_dag.py took 0.066 seconds
[2024-09-25T22:29:46.253+0000] {processor.py:186} INFO - Started process (PID=2354) to work on /opt/airflow/dags/covid_gdp_dag.py
[2024-09-25T22:29:46.254+0000] {processor.py:914} INFO - Processing file /opt/airflow/dags/covid_gdp_dag.py for tasks to queue
[2024-09-25T22:29:46.262+0000] {logging_mixin.py:190} INFO - [2024-09-25T22:29:46.261+0000] {dagbag.py:588} INFO - Filling up the DagBag from /opt/airflow/dags/covid_gdp_dag.py
[2024-09-25T22:29:46.303+0000] {logging_mixin.py:190} INFO - [2024-09-25T22:29:46.291+0000] {dagbag.py:387} ERROR - Failed to import: /opt/airflow/dags/covid_gdp_dag.py
Traceback (most recent call last):
  File "/home/airflow/.local/lib/python3.12/site-packages/airflow/models/dagbag.py", line 383, in parse
    loader.exec_module(new_module)
  File "<frozen importlib._bootstrap_external>", line 995, in exec_module
  File "<frozen importlib._bootstrap>", line 488, in _call_with_frames_removed
  File "/opt/airflow/dags/covid_gdp_dag.py", line 7, in <module>
    from common_data_loader import download_world_bank_data, download_kaggle_dataset, load_covid_data, load_gdp_data
  File "/opt/airflow/dags/common_data_loader.py", line 3, in <module>
    import kaggle
ModuleNotFoundError: No module named 'kaggle'
[2024-09-25T22:29:46.305+0000] {processor.py:927} WARNING - No viable dags retrieved from /opt/airflow/dags/covid_gdp_dag.py
[2024-09-25T22:29:46.337+0000] {processor.py:208} INFO - Processing /opt/airflow/dags/covid_gdp_dag.py took 0.089 seconds
[2024-09-25T22:30:17.008+0000] {processor.py:186} INFO - Started process (PID=2423) to work on /opt/airflow/dags/covid_gdp_dag.py
[2024-09-25T22:30:17.009+0000] {processor.py:914} INFO - Processing file /opt/airflow/dags/covid_gdp_dag.py for tasks to queue
[2024-09-25T22:30:17.013+0000] {logging_mixin.py:190} INFO - [2024-09-25T22:30:17.012+0000] {dagbag.py:588} INFO - Filling up the DagBag from /opt/airflow/dags/covid_gdp_dag.py
[2024-09-25T22:30:17.051+0000] {logging_mixin.py:190} INFO - [2024-09-25T22:30:17.040+0000] {dagbag.py:387} ERROR - Failed to import: /opt/airflow/dags/covid_gdp_dag.py
Traceback (most recent call last):
  File "/home/airflow/.local/lib/python3.12/site-packages/airflow/models/dagbag.py", line 383, in parse
    loader.exec_module(new_module)
  File "<frozen importlib._bootstrap_external>", line 995, in exec_module
  File "<frozen importlib._bootstrap>", line 488, in _call_with_frames_removed
  File "/opt/airflow/dags/covid_gdp_dag.py", line 7, in <module>
    from common_data_loader import download_world_bank_data, download_kaggle_dataset, load_covid_data, load_gdp_data
  File "/opt/airflow/dags/common_data_loader.py", line 3, in <module>
    import kaggle
ModuleNotFoundError: No module named 'kaggle'
[2024-09-25T22:30:17.055+0000] {processor.py:927} WARNING - No viable dags retrieved from /opt/airflow/dags/covid_gdp_dag.py
[2024-09-25T22:30:17.116+0000] {processor.py:208} INFO - Processing /opt/airflow/dags/covid_gdp_dag.py took 0.114 seconds
[2024-09-25T22:30:47.452+0000] {processor.py:186} INFO - Started process (PID=2486) to work on /opt/airflow/dags/covid_gdp_dag.py
[2024-09-25T22:30:47.454+0000] {processor.py:914} INFO - Processing file /opt/airflow/dags/covid_gdp_dag.py for tasks to queue
[2024-09-25T22:30:47.458+0000] {logging_mixin.py:190} INFO - [2024-09-25T22:30:47.457+0000] {dagbag.py:588} INFO - Filling up the DagBag from /opt/airflow/dags/covid_gdp_dag.py
[2024-09-25T22:30:47.492+0000] {logging_mixin.py:190} INFO - [2024-09-25T22:30:47.485+0000] {dagbag.py:387} ERROR - Failed to import: /opt/airflow/dags/covid_gdp_dag.py
Traceback (most recent call last):
  File "/home/airflow/.local/lib/python3.12/site-packages/airflow/models/dagbag.py", line 383, in parse
    loader.exec_module(new_module)
  File "<frozen importlib._bootstrap_external>", line 995, in exec_module
  File "<frozen importlib._bootstrap>", line 488, in _call_with_frames_removed
  File "/opt/airflow/dags/covid_gdp_dag.py", line 7, in <module>
    from common_data_loader import download_world_bank_data, download_kaggle_dataset, load_covid_data, load_gdp_data
  File "/opt/airflow/dags/common_data_loader.py", line 3, in <module>
    import kaggle
ModuleNotFoundError: No module named 'kaggle'
[2024-09-25T22:30:47.495+0000] {processor.py:927} WARNING - No viable dags retrieved from /opt/airflow/dags/covid_gdp_dag.py
[2024-09-25T22:30:47.528+0000] {processor.py:208} INFO - Processing /opt/airflow/dags/covid_gdp_dag.py took 0.088 seconds
[2024-09-25T22:31:18.321+0000] {processor.py:186} INFO - Started process (PID=2549) to work on /opt/airflow/dags/covid_gdp_dag.py
[2024-09-25T22:31:18.322+0000] {processor.py:914} INFO - Processing file /opt/airflow/dags/covid_gdp_dag.py for tasks to queue
[2024-09-25T22:31:18.325+0000] {logging_mixin.py:190} INFO - [2024-09-25T22:31:18.325+0000] {dagbag.py:588} INFO - Filling up the DagBag from /opt/airflow/dags/covid_gdp_dag.py
[2024-09-25T22:31:18.348+0000] {logging_mixin.py:190} INFO - [2024-09-25T22:31:18.341+0000] {dagbag.py:387} ERROR - Failed to import: /opt/airflow/dags/covid_gdp_dag.py
Traceback (most recent call last):
  File "/home/airflow/.local/lib/python3.12/site-packages/airflow/models/dagbag.py", line 383, in parse
    loader.exec_module(new_module)
  File "<frozen importlib._bootstrap_external>", line 995, in exec_module
  File "<frozen importlib._bootstrap>", line 488, in _call_with_frames_removed
  File "/opt/airflow/dags/covid_gdp_dag.py", line 7, in <module>
    from common_data_loader import download_world_bank_data, download_kaggle_dataset, load_covid_data, load_gdp_data
  File "/opt/airflow/dags/common_data_loader.py", line 3, in <module>
    import kaggle
ModuleNotFoundError: No module named 'kaggle'
[2024-09-25T22:31:18.350+0000] {processor.py:927} WARNING - No viable dags retrieved from /opt/airflow/dags/covid_gdp_dag.py
[2024-09-25T22:31:18.370+0000] {processor.py:208} INFO - Processing /opt/airflow/dags/covid_gdp_dag.py took 0.054 seconds
[2024-09-25T22:31:48.597+0000] {processor.py:186} INFO - Started process (PID=2612) to work on /opt/airflow/dags/covid_gdp_dag.py
[2024-09-25T22:31:48.598+0000] {processor.py:914} INFO - Processing file /opt/airflow/dags/covid_gdp_dag.py for tasks to queue
[2024-09-25T22:31:48.601+0000] {logging_mixin.py:190} INFO - [2024-09-25T22:31:48.601+0000] {dagbag.py:588} INFO - Filling up the DagBag from /opt/airflow/dags/covid_gdp_dag.py
[2024-09-25T22:31:48.625+0000] {logging_mixin.py:190} INFO - [2024-09-25T22:31:48.618+0000] {dagbag.py:387} ERROR - Failed to import: /opt/airflow/dags/covid_gdp_dag.py
Traceback (most recent call last):
  File "/home/airflow/.local/lib/python3.12/site-packages/airflow/models/dagbag.py", line 383, in parse
    loader.exec_module(new_module)
  File "<frozen importlib._bootstrap_external>", line 995, in exec_module
  File "<frozen importlib._bootstrap>", line 488, in _call_with_frames_removed
  File "/opt/airflow/dags/covid_gdp_dag.py", line 7, in <module>
    from common_data_loader import download_world_bank_data, download_kaggle_dataset, load_covid_data, load_gdp_data
  File "/opt/airflow/dags/common_data_loader.py", line 3, in <module>
    import kaggle
ModuleNotFoundError: No module named 'kaggle'
[2024-09-25T22:31:48.626+0000] {processor.py:927} WARNING - No viable dags retrieved from /opt/airflow/dags/covid_gdp_dag.py
[2024-09-25T22:31:48.651+0000] {processor.py:208} INFO - Processing /opt/airflow/dags/covid_gdp_dag.py took 0.059 seconds
[2024-09-25T22:32:18.827+0000] {processor.py:186} INFO - Started process (PID=2675) to work on /opt/airflow/dags/covid_gdp_dag.py
[2024-09-25T22:32:18.828+0000] {processor.py:914} INFO - Processing file /opt/airflow/dags/covid_gdp_dag.py for tasks to queue
[2024-09-25T22:32:18.831+0000] {logging_mixin.py:190} INFO - [2024-09-25T22:32:18.831+0000] {dagbag.py:588} INFO - Filling up the DagBag from /opt/airflow/dags/covid_gdp_dag.py
[2024-09-25T22:32:18.861+0000] {logging_mixin.py:190} INFO - [2024-09-25T22:32:18.853+0000] {dagbag.py:387} ERROR - Failed to import: /opt/airflow/dags/covid_gdp_dag.py
Traceback (most recent call last):
  File "/home/airflow/.local/lib/python3.12/site-packages/airflow/models/dagbag.py", line 383, in parse
    loader.exec_module(new_module)
  File "<frozen importlib._bootstrap_external>", line 995, in exec_module
  File "<frozen importlib._bootstrap>", line 488, in _call_with_frames_removed
  File "/opt/airflow/dags/covid_gdp_dag.py", line 7, in <module>
    from common_data_loader import download_world_bank_data, download_kaggle_dataset, load_covid_data, load_gdp_data
  File "/opt/airflow/dags/common_data_loader.py", line 3, in <module>
    import kaggle
ModuleNotFoundError: No module named 'kaggle'
[2024-09-25T22:32:18.864+0000] {processor.py:927} WARNING - No viable dags retrieved from /opt/airflow/dags/covid_gdp_dag.py
[2024-09-25T22:32:18.941+0000] {processor.py:208} INFO - Processing /opt/airflow/dags/covid_gdp_dag.py took 0.120 seconds
[2024-09-25T22:32:49.532+0000] {processor.py:186} INFO - Started process (PID=2738) to work on /opt/airflow/dags/covid_gdp_dag.py
[2024-09-25T22:32:49.534+0000] {processor.py:914} INFO - Processing file /opt/airflow/dags/covid_gdp_dag.py for tasks to queue
[2024-09-25T22:32:49.537+0000] {logging_mixin.py:190} INFO - [2024-09-25T22:32:49.536+0000] {dagbag.py:588} INFO - Filling up the DagBag from /opt/airflow/dags/covid_gdp_dag.py
[2024-09-25T22:32:49.559+0000] {logging_mixin.py:190} INFO - [2024-09-25T22:32:49.552+0000] {dagbag.py:387} ERROR - Failed to import: /opt/airflow/dags/covid_gdp_dag.py
Traceback (most recent call last):
  File "/home/airflow/.local/lib/python3.12/site-packages/airflow/models/dagbag.py", line 383, in parse
    loader.exec_module(new_module)
  File "<frozen importlib._bootstrap_external>", line 995, in exec_module
  File "<frozen importlib._bootstrap>", line 488, in _call_with_frames_removed
  File "/opt/airflow/dags/covid_gdp_dag.py", line 7, in <module>
    from common_data_loader import download_world_bank_data, download_kaggle_dataset, load_covid_data, load_gdp_data
  File "/opt/airflow/dags/common_data_loader.py", line 3, in <module>
    import kaggle
ModuleNotFoundError: No module named 'kaggle'
[2024-09-25T22:32:49.561+0000] {processor.py:927} WARNING - No viable dags retrieved from /opt/airflow/dags/covid_gdp_dag.py
[2024-09-25T22:32:49.590+0000] {processor.py:208} INFO - Processing /opt/airflow/dags/covid_gdp_dag.py took 0.064 seconds
[2024-09-25T22:33:19.638+0000] {processor.py:186} INFO - Started process (PID=2801) to work on /opt/airflow/dags/covid_gdp_dag.py
[2024-09-25T22:33:19.639+0000] {processor.py:914} INFO - Processing file /opt/airflow/dags/covid_gdp_dag.py for tasks to queue
[2024-09-25T22:33:19.641+0000] {logging_mixin.py:190} INFO - [2024-09-25T22:33:19.641+0000] {dagbag.py:588} INFO - Filling up the DagBag from /opt/airflow/dags/covid_gdp_dag.py
[2024-09-25T22:33:19.666+0000] {logging_mixin.py:190} INFO - [2024-09-25T22:33:19.659+0000] {dagbag.py:387} ERROR - Failed to import: /opt/airflow/dags/covid_gdp_dag.py
Traceback (most recent call last):
  File "/home/airflow/.local/lib/python3.12/site-packages/airflow/models/dagbag.py", line 383, in parse
    loader.exec_module(new_module)
  File "<frozen importlib._bootstrap_external>", line 995, in exec_module
  File "<frozen importlib._bootstrap>", line 488, in _call_with_frames_removed
  File "/opt/airflow/dags/covid_gdp_dag.py", line 7, in <module>
    from common_data_loader import download_world_bank_data, download_kaggle_dataset, load_covid_data, load_gdp_data
  File "/opt/airflow/dags/common_data_loader.py", line 3, in <module>
    import kaggle
ModuleNotFoundError: No module named 'kaggle'
[2024-09-25T22:33:19.668+0000] {processor.py:927} WARNING - No viable dags retrieved from /opt/airflow/dags/covid_gdp_dag.py
[2024-09-25T22:33:19.692+0000] {processor.py:208} INFO - Processing /opt/airflow/dags/covid_gdp_dag.py took 0.059 seconds
[2024-09-25T22:33:50.244+0000] {processor.py:186} INFO - Started process (PID=2865) to work on /opt/airflow/dags/covid_gdp_dag.py
[2024-09-25T22:33:50.246+0000] {processor.py:914} INFO - Processing file /opt/airflow/dags/covid_gdp_dag.py for tasks to queue
[2024-09-25T22:33:50.248+0000] {logging_mixin.py:190} INFO - [2024-09-25T22:33:50.248+0000] {dagbag.py:588} INFO - Filling up the DagBag from /opt/airflow/dags/covid_gdp_dag.py
[2024-09-25T22:33:50.269+0000] {logging_mixin.py:190} INFO - [2024-09-25T22:33:50.262+0000] {dagbag.py:387} ERROR - Failed to import: /opt/airflow/dags/covid_gdp_dag.py
Traceback (most recent call last):
  File "/home/airflow/.local/lib/python3.12/site-packages/airflow/models/dagbag.py", line 383, in parse
    loader.exec_module(new_module)
  File "<frozen importlib._bootstrap_external>", line 995, in exec_module
  File "<frozen importlib._bootstrap>", line 488, in _call_with_frames_removed
  File "/opt/airflow/dags/covid_gdp_dag.py", line 7, in <module>
    from common_data_loader import download_world_bank_data, download_kaggle_dataset, load_covid_data, load_gdp_data
  File "/opt/airflow/dags/common_data_loader.py", line 3, in <module>
    import kaggle
ModuleNotFoundError: No module named 'kaggle'
[2024-09-25T22:33:50.271+0000] {processor.py:927} WARNING - No viable dags retrieved from /opt/airflow/dags/covid_gdp_dag.py
[2024-09-25T22:33:50.294+0000] {processor.py:208} INFO - Processing /opt/airflow/dags/covid_gdp_dag.py took 0.055 seconds
[2024-09-25T22:34:20.664+0000] {processor.py:186} INFO - Started process (PID=2928) to work on /opt/airflow/dags/covid_gdp_dag.py
[2024-09-25T22:34:20.665+0000] {processor.py:914} INFO - Processing file /opt/airflow/dags/covid_gdp_dag.py for tasks to queue
[2024-09-25T22:34:20.667+0000] {logging_mixin.py:190} INFO - [2024-09-25T22:34:20.667+0000] {dagbag.py:588} INFO - Filling up the DagBag from /opt/airflow/dags/covid_gdp_dag.py
[2024-09-25T22:34:20.688+0000] {logging_mixin.py:190} INFO - [2024-09-25T22:34:20.683+0000] {dagbag.py:387} ERROR - Failed to import: /opt/airflow/dags/covid_gdp_dag.py
Traceback (most recent call last):
  File "/home/airflow/.local/lib/python3.12/site-packages/airflow/models/dagbag.py", line 383, in parse
    loader.exec_module(new_module)
  File "<frozen importlib._bootstrap_external>", line 995, in exec_module
  File "<frozen importlib._bootstrap>", line 488, in _call_with_frames_removed
  File "/opt/airflow/dags/covid_gdp_dag.py", line 7, in <module>
    from common_data_loader import download_world_bank_data, download_kaggle_dataset, load_covid_data, load_gdp_data
  File "/opt/airflow/dags/common_data_loader.py", line 3, in <module>
    import kaggle
ModuleNotFoundError: No module named 'kaggle'
[2024-09-25T22:34:20.690+0000] {processor.py:927} WARNING - No viable dags retrieved from /opt/airflow/dags/covid_gdp_dag.py
[2024-09-25T22:34:20.739+0000] {processor.py:208} INFO - Processing /opt/airflow/dags/covid_gdp_dag.py took 0.079 seconds
[2024-09-25T22:34:51.047+0000] {processor.py:186} INFO - Started process (PID=2991) to work on /opt/airflow/dags/covid_gdp_dag.py
[2024-09-25T22:34:51.049+0000] {processor.py:914} INFO - Processing file /opt/airflow/dags/covid_gdp_dag.py for tasks to queue
[2024-09-25T22:34:51.051+0000] {logging_mixin.py:190} INFO - [2024-09-25T22:34:51.051+0000] {dagbag.py:588} INFO - Filling up the DagBag from /opt/airflow/dags/covid_gdp_dag.py
[2024-09-25T22:34:51.072+0000] {logging_mixin.py:190} INFO - [2024-09-25T22:34:51.067+0000] {dagbag.py:387} ERROR - Failed to import: /opt/airflow/dags/covid_gdp_dag.py
Traceback (most recent call last):
  File "/home/airflow/.local/lib/python3.12/site-packages/airflow/models/dagbag.py", line 383, in parse
    loader.exec_module(new_module)
  File "<frozen importlib._bootstrap_external>", line 995, in exec_module
  File "<frozen importlib._bootstrap>", line 488, in _call_with_frames_removed
  File "/opt/airflow/dags/covid_gdp_dag.py", line 7, in <module>
    from common_data_loader import download_world_bank_data, download_kaggle_dataset, load_covid_data, load_gdp_data
  File "/opt/airflow/dags/common_data_loader.py", line 3, in <module>
    import kaggle
ModuleNotFoundError: No module named 'kaggle'
[2024-09-25T22:34:51.075+0000] {processor.py:927} WARNING - No viable dags retrieved from /opt/airflow/dags/covid_gdp_dag.py
[2024-09-25T22:34:51.097+0000] {processor.py:208} INFO - Processing /opt/airflow/dags/covid_gdp_dag.py took 0.055 seconds
[2024-09-25T22:35:21.524+0000] {processor.py:186} INFO - Started process (PID=3054) to work on /opt/airflow/dags/covid_gdp_dag.py
[2024-09-25T22:35:21.525+0000] {processor.py:914} INFO - Processing file /opt/airflow/dags/covid_gdp_dag.py for tasks to queue
[2024-09-25T22:35:21.527+0000] {logging_mixin.py:190} INFO - [2024-09-25T22:35:21.527+0000] {dagbag.py:588} INFO - Filling up the DagBag from /opt/airflow/dags/covid_gdp_dag.py
[2024-09-25T22:35:21.549+0000] {logging_mixin.py:190} INFO - [2024-09-25T22:35:21.542+0000] {dagbag.py:387} ERROR - Failed to import: /opt/airflow/dags/covid_gdp_dag.py
Traceback (most recent call last):
  File "/home/airflow/.local/lib/python3.12/site-packages/airflow/models/dagbag.py", line 383, in parse
    loader.exec_module(new_module)
  File "<frozen importlib._bootstrap_external>", line 995, in exec_module
  File "<frozen importlib._bootstrap>", line 488, in _call_with_frames_removed
  File "/opt/airflow/dags/covid_gdp_dag.py", line 7, in <module>
    from common_data_loader import download_world_bank_data, download_kaggle_dataset, load_covid_data, load_gdp_data
  File "/opt/airflow/dags/common_data_loader.py", line 3, in <module>
    import kaggle
ModuleNotFoundError: No module named 'kaggle'
[2024-09-25T22:35:21.550+0000] {processor.py:927} WARNING - No viable dags retrieved from /opt/airflow/dags/covid_gdp_dag.py
[2024-09-25T22:35:21.572+0000] {processor.py:208} INFO - Processing /opt/airflow/dags/covid_gdp_dag.py took 0.053 seconds
[2024-09-25T22:35:52.509+0000] {processor.py:186} INFO - Started process (PID=3117) to work on /opt/airflow/dags/covid_gdp_dag.py
[2024-09-25T22:35:52.510+0000] {processor.py:914} INFO - Processing file /opt/airflow/dags/covid_gdp_dag.py for tasks to queue
[2024-09-25T22:35:52.514+0000] {logging_mixin.py:190} INFO - [2024-09-25T22:35:52.513+0000] {dagbag.py:588} INFO - Filling up the DagBag from /opt/airflow/dags/covid_gdp_dag.py
[2024-09-25T22:35:52.584+0000] {logging_mixin.py:190} INFO - [2024-09-25T22:35:52.565+0000] {dagbag.py:387} ERROR - Failed to import: /opt/airflow/dags/covid_gdp_dag.py
Traceback (most recent call last):
  File "/home/airflow/.local/lib/python3.12/site-packages/airflow/models/dagbag.py", line 383, in parse
    loader.exec_module(new_module)
  File "<frozen importlib._bootstrap_external>", line 995, in exec_module
  File "<frozen importlib._bootstrap>", line 488, in _call_with_frames_removed
  File "/opt/airflow/dags/covid_gdp_dag.py", line 7, in <module>
    from common_data_loader import download_world_bank_data, download_kaggle_dataset, load_covid_data, load_gdp_data
  File "/opt/airflow/dags/common_data_loader.py", line 3, in <module>
    import kaggle
ModuleNotFoundError: No module named 'kaggle'
[2024-09-25T22:35:52.589+0000] {processor.py:927} WARNING - No viable dags retrieved from /opt/airflow/dags/covid_gdp_dag.py
[2024-09-25T22:35:52.627+0000] {processor.py:208} INFO - Processing /opt/airflow/dags/covid_gdp_dag.py took 0.129 seconds
[2024-09-25T22:48:33.396+0000] {processor.py:186} INFO - Started process (PID=3140) to work on /opt/airflow/dags/covid_gdp_dag.py
[2024-09-25T22:48:33.409+0000] {processor.py:914} INFO - Processing file /opt/airflow/dags/covid_gdp_dag.py for tasks to queue
[2024-09-25T22:48:33.413+0000] {logging_mixin.py:190} INFO - [2024-09-25T22:48:33.412+0000] {dagbag.py:588} INFO - Filling up the DagBag from /opt/airflow/dags/covid_gdp_dag.py
[2024-09-25T22:48:33.483+0000] {logging_mixin.py:190} INFO - [2024-09-25T22:48:33.468+0000] {dagbag.py:387} ERROR - Failed to import: /opt/airflow/dags/covid_gdp_dag.py
Traceback (most recent call last):
  File "/home/airflow/.local/lib/python3.12/site-packages/airflow/models/dagbag.py", line 383, in parse
    loader.exec_module(new_module)
  File "<frozen importlib._bootstrap_external>", line 995, in exec_module
  File "<frozen importlib._bootstrap>", line 488, in _call_with_frames_removed
  File "/opt/airflow/dags/covid_gdp_dag.py", line 7, in <module>
    from common_data_loader import download_world_bank_data, download_kaggle_dataset, load_covid_data, load_gdp_data
  File "/opt/airflow/dags/common_data_loader.py", line 3, in <module>
    import kaggle
ModuleNotFoundError: No module named 'kaggle'
[2024-09-25T22:48:33.491+0000] {processor.py:927} WARNING - No viable dags retrieved from /opt/airflow/dags/covid_gdp_dag.py
[2024-09-25T22:48:33.549+0000] {processor.py:208} INFO - Processing /opt/airflow/dags/covid_gdp_dag.py took 0.181 seconds
[2024-09-25T22:50:27.318+0000] {processor.py:186} INFO - Started process (PID=3194) to work on /opt/airflow/dags/covid_gdp_dag.py
[2024-09-25T22:50:27.320+0000] {processor.py:914} INFO - Processing file /opt/airflow/dags/covid_gdp_dag.py for tasks to queue
[2024-09-25T22:50:27.321+0000] {logging_mixin.py:190} INFO - [2024-09-25T22:50:27.321+0000] {dagbag.py:588} INFO - Filling up the DagBag from /opt/airflow/dags/covid_gdp_dag.py
[2024-09-25T22:50:27.348+0000] {logging_mixin.py:190} INFO - [2024-09-25T22:50:27.342+0000] {dagbag.py:387} ERROR - Failed to import: /opt/airflow/dags/covid_gdp_dag.py
Traceback (most recent call last):
  File "/home/airflow/.local/lib/python3.12/site-packages/airflow/models/dagbag.py", line 383, in parse
    loader.exec_module(new_module)
  File "<frozen importlib._bootstrap_external>", line 995, in exec_module
  File "<frozen importlib._bootstrap>", line 488, in _call_with_frames_removed
  File "/opt/airflow/dags/covid_gdp_dag.py", line 7, in <module>
    from common_data_loader import download_world_bank_data, download_kaggle_dataset, load_covid_data, load_gdp_data
  File "/opt/airflow/dags/common_data_loader.py", line 3, in <module>
    import kaggle
ModuleNotFoundError: No module named 'kaggle'
[2024-09-25T22:50:27.352+0000] {processor.py:927} WARNING - No viable dags retrieved from /opt/airflow/dags/covid_gdp_dag.py
[2024-09-25T22:50:27.399+0000] {processor.py:208} INFO - Processing /opt/airflow/dags/covid_gdp_dag.py took 0.086 seconds
[2024-09-25T22:52:36.988+0000] {processor.py:186} INFO - Started process (PID=67) to work on /opt/airflow/dags/covid_gdp_dag.py
[2024-09-25T22:52:37.000+0000] {processor.py:914} INFO - Processing file /opt/airflow/dags/covid_gdp_dag.py for tasks to queue
[2024-09-25T22:52:37.038+0000] {logging_mixin.py:190} INFO - [2024-09-25T22:52:37.034+0000] {dagbag.py:588} INFO - Filling up the DagBag from /opt/airflow/dags/covid_gdp_dag.py
[2024-09-25T22:52:37.195+0000] {logging_mixin.py:190} INFO - [2024-09-25T22:52:37.174+0000] {dagbag.py:387} ERROR - Failed to import: /opt/airflow/dags/covid_gdp_dag.py
Traceback (most recent call last):
  File "/home/airflow/.local/lib/python3.12/site-packages/airflow/models/dagbag.py", line 383, in parse
    loader.exec_module(new_module)
  File "<frozen importlib._bootstrap_external>", line 995, in exec_module
  File "<frozen importlib._bootstrap>", line 488, in _call_with_frames_removed
  File "/opt/airflow/dags/covid_gdp_dag.py", line 7, in <module>
    from common_data_loader import download_world_bank_data, download_kaggle_dataset, load_covid_data, load_gdp_data
  File "/opt/airflow/dags/common_data_loader.py", line 3, in <module>
    import kaggle
ModuleNotFoundError: No module named 'kaggle'
[2024-09-25T22:52:37.199+0000] {processor.py:927} WARNING - No viable dags retrieved from /opt/airflow/dags/covid_gdp_dag.py
[2024-09-25T22:52:37.471+0000] {processor.py:208} INFO - Processing /opt/airflow/dags/covid_gdp_dag.py took 0.768 seconds
[2024-09-25T22:53:08.268+0000] {processor.py:186} INFO - Started process (PID=129) to work on /opt/airflow/dags/covid_gdp_dag.py
[2024-09-25T22:53:08.269+0000] {processor.py:914} INFO - Processing file /opt/airflow/dags/covid_gdp_dag.py for tasks to queue
[2024-09-25T22:53:08.272+0000] {logging_mixin.py:190} INFO - [2024-09-25T22:53:08.272+0000] {dagbag.py:588} INFO - Filling up the DagBag from /opt/airflow/dags/covid_gdp_dag.py
[2024-09-25T22:53:08.297+0000] {logging_mixin.py:190} INFO - [2024-09-25T22:53:08.290+0000] {dagbag.py:387} ERROR - Failed to import: /opt/airflow/dags/covid_gdp_dag.py
Traceback (most recent call last):
  File "/home/airflow/.local/lib/python3.12/site-packages/airflow/models/dagbag.py", line 383, in parse
    loader.exec_module(new_module)
  File "<frozen importlib._bootstrap_external>", line 995, in exec_module
  File "<frozen importlib._bootstrap>", line 488, in _call_with_frames_removed
  File "/opt/airflow/dags/covid_gdp_dag.py", line 7, in <module>
    from common_data_loader import download_world_bank_data, download_kaggle_dataset, load_covid_data, load_gdp_data
  File "/opt/airflow/dags/common_data_loader.py", line 3, in <module>
    import kaggle
ModuleNotFoundError: No module named 'kaggle'
[2024-09-25T22:53:08.298+0000] {processor.py:927} WARNING - No viable dags retrieved from /opt/airflow/dags/covid_gdp_dag.py
[2024-09-25T22:53:08.336+0000] {processor.py:208} INFO - Processing /opt/airflow/dags/covid_gdp_dag.py took 0.072 seconds
[2024-09-25T22:53:38.393+0000] {processor.py:186} INFO - Started process (PID=193) to work on /opt/airflow/dags/covid_gdp_dag.py
[2024-09-25T22:53:38.395+0000] {processor.py:914} INFO - Processing file /opt/airflow/dags/covid_gdp_dag.py for tasks to queue
[2024-09-25T22:53:38.402+0000] {logging_mixin.py:190} INFO - [2024-09-25T22:53:38.401+0000] {dagbag.py:588} INFO - Filling up the DagBag from /opt/airflow/dags/covid_gdp_dag.py
[2024-09-25T22:53:38.433+0000] {logging_mixin.py:190} INFO - [2024-09-25T22:53:38.427+0000] {dagbag.py:387} ERROR - Failed to import: /opt/airflow/dags/covid_gdp_dag.py
Traceback (most recent call last):
  File "/home/airflow/.local/lib/python3.12/site-packages/airflow/models/dagbag.py", line 383, in parse
    loader.exec_module(new_module)
  File "<frozen importlib._bootstrap_external>", line 995, in exec_module
  File "<frozen importlib._bootstrap>", line 488, in _call_with_frames_removed
  File "/opt/airflow/dags/covid_gdp_dag.py", line 7, in <module>
    from common_data_loader import download_world_bank_data, download_kaggle_dataset, load_covid_data, load_gdp_data
  File "/opt/airflow/dags/common_data_loader.py", line 3, in <module>
    import kaggle
ModuleNotFoundError: No module named 'kaggle'
[2024-09-25T22:53:38.435+0000] {processor.py:927} WARNING - No viable dags retrieved from /opt/airflow/dags/covid_gdp_dag.py
[2024-09-25T22:53:38.462+0000] {processor.py:208} INFO - Processing /opt/airflow/dags/covid_gdp_dag.py took 0.074 seconds
[2024-09-25T22:54:08.938+0000] {processor.py:186} INFO - Started process (PID=257) to work on /opt/airflow/dags/covid_gdp_dag.py
[2024-09-25T22:54:08.939+0000] {processor.py:914} INFO - Processing file /opt/airflow/dags/covid_gdp_dag.py for tasks to queue
[2024-09-25T22:54:08.942+0000] {logging_mixin.py:190} INFO - [2024-09-25T22:54:08.941+0000] {dagbag.py:588} INFO - Filling up the DagBag from /opt/airflow/dags/covid_gdp_dag.py
[2024-09-25T22:54:08.967+0000] {logging_mixin.py:190} INFO - [2024-09-25T22:54:08.958+0000] {dagbag.py:387} ERROR - Failed to import: /opt/airflow/dags/covid_gdp_dag.py
Traceback (most recent call last):
  File "/home/airflow/.local/lib/python3.12/site-packages/airflow/models/dagbag.py", line 383, in parse
    loader.exec_module(new_module)
  File "<frozen importlib._bootstrap_external>", line 995, in exec_module
  File "<frozen importlib._bootstrap>", line 488, in _call_with_frames_removed
  File "/opt/airflow/dags/covid_gdp_dag.py", line 7, in <module>
    from common_data_loader import download_world_bank_data, download_kaggle_dataset, load_covid_data, load_gdp_data
  File "/opt/airflow/dags/common_data_loader.py", line 3, in <module>
    import kaggle
ModuleNotFoundError: No module named 'kaggle'
[2024-09-25T22:54:08.969+0000] {processor.py:927} WARNING - No viable dags retrieved from /opt/airflow/dags/covid_gdp_dag.py
[2024-09-25T22:54:08.989+0000] {processor.py:208} INFO - Processing /opt/airflow/dags/covid_gdp_dag.py took 0.057 seconds
[2024-09-25T22:54:40.949+0000] {processor.py:186} INFO - Started process (PID=320) to work on /opt/airflow/dags/covid_gdp_dag.py
[2024-09-25T22:54:40.965+0000] {processor.py:914} INFO - Processing file /opt/airflow/dags/covid_gdp_dag.py for tasks to queue
[2024-09-25T22:54:40.988+0000] {logging_mixin.py:190} INFO - [2024-09-25T22:54:40.987+0000] {dagbag.py:588} INFO - Filling up the DagBag from /opt/airflow/dags/covid_gdp_dag.py
[2024-09-25T22:54:41.185+0000] {logging_mixin.py:190} INFO - [2024-09-25T22:54:41.161+0000] {dagbag.py:387} ERROR - Failed to import: /opt/airflow/dags/covid_gdp_dag.py
Traceback (most recent call last):
  File "/home/airflow/.local/lib/python3.12/site-packages/airflow/models/dagbag.py", line 383, in parse
    loader.exec_module(new_module)
  File "<frozen importlib._bootstrap_external>", line 995, in exec_module
  File "<frozen importlib._bootstrap>", line 488, in _call_with_frames_removed
  File "/opt/airflow/dags/covid_gdp_dag.py", line 7, in <module>
    from common_data_loader import download_world_bank_data, download_kaggle_dataset, load_covid_data, load_gdp_data
  File "/opt/airflow/dags/common_data_loader.py", line 3, in <module>
    import kaggle
ModuleNotFoundError: No module named 'kaggle'
[2024-09-25T22:54:41.192+0000] {processor.py:927} WARNING - No viable dags retrieved from /opt/airflow/dags/covid_gdp_dag.py
[2024-09-25T22:54:41.308+0000] {processor.py:208} INFO - Processing /opt/airflow/dags/covid_gdp_dag.py took 0.391 seconds
[2024-09-25T22:55:11.543+0000] {processor.py:186} INFO - Started process (PID=383) to work on /opt/airflow/dags/covid_gdp_dag.py
[2024-09-25T22:55:11.544+0000] {processor.py:914} INFO - Processing file /opt/airflow/dags/covid_gdp_dag.py for tasks to queue
[2024-09-25T22:55:11.547+0000] {logging_mixin.py:190} INFO - [2024-09-25T22:55:11.546+0000] {dagbag.py:588} INFO - Filling up the DagBag from /opt/airflow/dags/covid_gdp_dag.py
[2024-09-25T22:55:11.576+0000] {logging_mixin.py:190} INFO - [2024-09-25T22:55:11.569+0000] {dagbag.py:387} ERROR - Failed to import: /opt/airflow/dags/covid_gdp_dag.py
Traceback (most recent call last):
  File "/home/airflow/.local/lib/python3.12/site-packages/airflow/models/dagbag.py", line 383, in parse
    loader.exec_module(new_module)
  File "<frozen importlib._bootstrap_external>", line 995, in exec_module
  File "<frozen importlib._bootstrap>", line 488, in _call_with_frames_removed
  File "/opt/airflow/dags/covid_gdp_dag.py", line 7, in <module>
    from common_data_loader import download_world_bank_data, download_kaggle_dataset, load_covid_data, load_gdp_data
  File "/opt/airflow/dags/common_data_loader.py", line 3, in <module>
    import kaggle
ModuleNotFoundError: No module named 'kaggle'
[2024-09-25T22:55:11.578+0000] {processor.py:927} WARNING - No viable dags retrieved from /opt/airflow/dags/covid_gdp_dag.py
[2024-09-25T22:55:11.601+0000] {processor.py:208} INFO - Processing /opt/airflow/dags/covid_gdp_dag.py took 0.064 seconds
[2024-09-25T22:57:22.143+0000] {processor.py:186} INFO - Started process (PID=67) to work on /opt/airflow/dags/covid_gdp_dag.py
[2024-09-25T22:57:22.145+0000] {processor.py:914} INFO - Processing file /opt/airflow/dags/covid_gdp_dag.py for tasks to queue
[2024-09-25T22:57:22.149+0000] {logging_mixin.py:190} INFO - [2024-09-25T22:57:22.148+0000] {dagbag.py:588} INFO - Filling up the DagBag from /opt/airflow/dags/covid_gdp_dag.py
[2024-09-25T22:57:22.273+0000] {logging_mixin.py:190} INFO - [2024-09-25T22:57:22.263+0000] {dagbag.py:387} ERROR - Failed to import: /opt/airflow/dags/covid_gdp_dag.py
Traceback (most recent call last):
  File "/home/airflow/.local/lib/python3.12/site-packages/airflow/models/dagbag.py", line 383, in parse
    loader.exec_module(new_module)
  File "<frozen importlib._bootstrap_external>", line 995, in exec_module
  File "<frozen importlib._bootstrap>", line 488, in _call_with_frames_removed
  File "/opt/airflow/dags/covid_gdp_dag.py", line 7, in <module>
    from common_data_loader import download_world_bank_data, download_kaggle_dataset, load_covid_data, load_gdp_data
  File "/opt/airflow/dags/common_data_loader.py", line 3, in <module>
    import kaggle
ModuleNotFoundError: No module named 'kaggle'
[2024-09-25T22:57:22.279+0000] {processor.py:927} WARNING - No viable dags retrieved from /opt/airflow/dags/covid_gdp_dag.py
[2024-09-25T22:57:22.430+0000] {processor.py:208} INFO - Processing /opt/airflow/dags/covid_gdp_dag.py took 0.297 seconds
[2024-09-25T22:57:53.508+0000] {processor.py:186} INFO - Started process (PID=130) to work on /opt/airflow/dags/covid_gdp_dag.py
[2024-09-25T22:57:53.514+0000] {processor.py:914} INFO - Processing file /opt/airflow/dags/covid_gdp_dag.py for tasks to queue
[2024-09-25T22:57:53.529+0000] {logging_mixin.py:190} INFO - [2024-09-25T22:57:53.528+0000] {dagbag.py:588} INFO - Filling up the DagBag from /opt/airflow/dags/covid_gdp_dag.py
[2024-09-25T22:57:53.576+0000] {logging_mixin.py:190} INFO - [2024-09-25T22:57:53.564+0000] {dagbag.py:387} ERROR - Failed to import: /opt/airflow/dags/covid_gdp_dag.py
Traceback (most recent call last):
  File "/home/airflow/.local/lib/python3.12/site-packages/airflow/models/dagbag.py", line 383, in parse
    loader.exec_module(new_module)
  File "<frozen importlib._bootstrap_external>", line 995, in exec_module
  File "<frozen importlib._bootstrap>", line 488, in _call_with_frames_removed
  File "/opt/airflow/dags/covid_gdp_dag.py", line 7, in <module>
    from common_data_loader import download_world_bank_data, download_kaggle_dataset, load_covid_data, load_gdp_data
  File "/opt/airflow/dags/common_data_loader.py", line 3, in <module>
    import kaggle
ModuleNotFoundError: No module named 'kaggle'
[2024-09-25T22:57:53.579+0000] {processor.py:927} WARNING - No viable dags retrieved from /opt/airflow/dags/covid_gdp_dag.py
[2024-09-25T22:57:53.661+0000] {processor.py:208} INFO - Processing /opt/airflow/dags/covid_gdp_dag.py took 0.182 seconds
[2024-09-25T22:58:23.826+0000] {processor.py:186} INFO - Started process (PID=193) to work on /opt/airflow/dags/covid_gdp_dag.py
[2024-09-25T22:58:23.827+0000] {processor.py:914} INFO - Processing file /opt/airflow/dags/covid_gdp_dag.py for tasks to queue
[2024-09-25T22:58:23.831+0000] {logging_mixin.py:190} INFO - [2024-09-25T22:58:23.830+0000] {dagbag.py:588} INFO - Filling up the DagBag from /opt/airflow/dags/covid_gdp_dag.py
[2024-09-25T22:58:23.861+0000] {logging_mixin.py:190} INFO - [2024-09-25T22:58:23.852+0000] {dagbag.py:387} ERROR - Failed to import: /opt/airflow/dags/covid_gdp_dag.py
Traceback (most recent call last):
  File "/home/airflow/.local/lib/python3.12/site-packages/airflow/models/dagbag.py", line 383, in parse
    loader.exec_module(new_module)
  File "<frozen importlib._bootstrap_external>", line 995, in exec_module
  File "<frozen importlib._bootstrap>", line 488, in _call_with_frames_removed
  File "/opt/airflow/dags/covid_gdp_dag.py", line 7, in <module>
    from common_data_loader import download_world_bank_data, download_kaggle_dataset, load_covid_data, load_gdp_data
  File "/opt/airflow/dags/common_data_loader.py", line 3, in <module>
    import kaggle
ModuleNotFoundError: No module named 'kaggle'
[2024-09-25T22:58:23.864+0000] {processor.py:927} WARNING - No viable dags retrieved from /opt/airflow/dags/covid_gdp_dag.py
[2024-09-25T22:58:23.891+0000] {processor.py:208} INFO - Processing /opt/airflow/dags/covid_gdp_dag.py took 0.071 seconds
[2024-09-25T22:58:54.340+0000] {processor.py:186} INFO - Started process (PID=256) to work on /opt/airflow/dags/covid_gdp_dag.py
[2024-09-25T22:58:54.341+0000] {processor.py:914} INFO - Processing file /opt/airflow/dags/covid_gdp_dag.py for tasks to queue
[2024-09-25T22:58:54.343+0000] {logging_mixin.py:190} INFO - [2024-09-25T22:58:54.343+0000] {dagbag.py:588} INFO - Filling up the DagBag from /opt/airflow/dags/covid_gdp_dag.py
[2024-09-25T22:58:54.414+0000] {logging_mixin.py:190} INFO - [2024-09-25T22:58:54.405+0000] {dagbag.py:387} ERROR - Failed to import: /opt/airflow/dags/covid_gdp_dag.py
Traceback (most recent call last):
  File "/home/airflow/.local/lib/python3.12/site-packages/airflow/models/dagbag.py", line 383, in parse
    loader.exec_module(new_module)
  File "<frozen importlib._bootstrap_external>", line 995, in exec_module
  File "<frozen importlib._bootstrap>", line 488, in _call_with_frames_removed
  File "/opt/airflow/dags/covid_gdp_dag.py", line 7, in <module>
    from common_data_loader import download_world_bank_data, download_kaggle_dataset, load_covid_data, load_gdp_data
  File "/opt/airflow/dags/common_data_loader.py", line 3, in <module>
    import kaggle
ModuleNotFoundError: No module named 'kaggle'
[2024-09-25T22:58:54.416+0000] {processor.py:927} WARNING - No viable dags retrieved from /opt/airflow/dags/covid_gdp_dag.py
[2024-09-25T22:58:54.446+0000] {processor.py:208} INFO - Processing /opt/airflow/dags/covid_gdp_dag.py took 0.110 seconds
[2024-09-25T22:59:25.164+0000] {processor.py:186} INFO - Started process (PID=319) to work on /opt/airflow/dags/covid_gdp_dag.py
[2024-09-25T22:59:25.165+0000] {processor.py:914} INFO - Processing file /opt/airflow/dags/covid_gdp_dag.py for tasks to queue
[2024-09-25T22:59:25.168+0000] {logging_mixin.py:190} INFO - [2024-09-25T22:59:25.167+0000] {dagbag.py:588} INFO - Filling up the DagBag from /opt/airflow/dags/covid_gdp_dag.py
[2024-09-25T22:59:25.193+0000] {logging_mixin.py:190} INFO - [2024-09-25T22:59:25.187+0000] {dagbag.py:387} ERROR - Failed to import: /opt/airflow/dags/covid_gdp_dag.py
Traceback (most recent call last):
  File "/home/airflow/.local/lib/python3.12/site-packages/airflow/models/dagbag.py", line 383, in parse
    loader.exec_module(new_module)
  File "<frozen importlib._bootstrap_external>", line 995, in exec_module
  File "<frozen importlib._bootstrap>", line 488, in _call_with_frames_removed
  File "/opt/airflow/dags/covid_gdp_dag.py", line 7, in <module>
    from common_data_loader import download_world_bank_data, download_kaggle_dataset, load_covid_data, load_gdp_data
  File "/opt/airflow/dags/common_data_loader.py", line 3, in <module>
    import kaggle
ModuleNotFoundError: No module named 'kaggle'
[2024-09-25T22:59:25.196+0000] {processor.py:927} WARNING - No viable dags retrieved from /opt/airflow/dags/covid_gdp_dag.py
[2024-09-25T22:59:25.220+0000] {processor.py:208} INFO - Processing /opt/airflow/dags/covid_gdp_dag.py took 0.063 seconds
[2024-09-25T22:59:55.608+0000] {processor.py:186} INFO - Started process (PID=382) to work on /opt/airflow/dags/covid_gdp_dag.py
[2024-09-25T22:59:55.609+0000] {processor.py:914} INFO - Processing file /opt/airflow/dags/covid_gdp_dag.py for tasks to queue
[2024-09-25T22:59:55.620+0000] {logging_mixin.py:190} INFO - [2024-09-25T22:59:55.620+0000] {dagbag.py:588} INFO - Filling up the DagBag from /opt/airflow/dags/covid_gdp_dag.py
[2024-09-25T22:59:55.648+0000] {logging_mixin.py:190} INFO - [2024-09-25T22:59:55.638+0000] {dagbag.py:387} ERROR - Failed to import: /opt/airflow/dags/covid_gdp_dag.py
Traceback (most recent call last):
  File "/home/airflow/.local/lib/python3.12/site-packages/airflow/models/dagbag.py", line 383, in parse
    loader.exec_module(new_module)
  File "<frozen importlib._bootstrap_external>", line 995, in exec_module
  File "<frozen importlib._bootstrap>", line 488, in _call_with_frames_removed
  File "/opt/airflow/dags/covid_gdp_dag.py", line 7, in <module>
    from common_data_loader import download_world_bank_data, download_kaggle_dataset, load_covid_data, load_gdp_data
  File "/opt/airflow/dags/common_data_loader.py", line 3, in <module>
    import kaggle
ModuleNotFoundError: No module named 'kaggle'
[2024-09-25T22:59:55.650+0000] {processor.py:927} WARNING - No viable dags retrieved from /opt/airflow/dags/covid_gdp_dag.py
[2024-09-25T22:59:55.676+0000] {processor.py:208} INFO - Processing /opt/airflow/dags/covid_gdp_dag.py took 0.074 seconds
[2024-09-25T23:00:26.458+0000] {processor.py:186} INFO - Started process (PID=445) to work on /opt/airflow/dags/covid_gdp_dag.py
[2024-09-25T23:00:26.459+0000] {processor.py:914} INFO - Processing file /opt/airflow/dags/covid_gdp_dag.py for tasks to queue
[2024-09-25T23:00:26.461+0000] {logging_mixin.py:190} INFO - [2024-09-25T23:00:26.461+0000] {dagbag.py:588} INFO - Filling up the DagBag from /opt/airflow/dags/covid_gdp_dag.py
[2024-09-25T23:00:26.490+0000] {logging_mixin.py:190} INFO - [2024-09-25T23:00:26.483+0000] {dagbag.py:387} ERROR - Failed to import: /opt/airflow/dags/covid_gdp_dag.py
Traceback (most recent call last):
  File "/home/airflow/.local/lib/python3.12/site-packages/airflow/models/dagbag.py", line 383, in parse
    loader.exec_module(new_module)
  File "<frozen importlib._bootstrap_external>", line 995, in exec_module
  File "<frozen importlib._bootstrap>", line 488, in _call_with_frames_removed
  File "/opt/airflow/dags/covid_gdp_dag.py", line 7, in <module>
    from common_data_loader import download_world_bank_data, download_kaggle_dataset, load_covid_data, load_gdp_data
  File "/opt/airflow/dags/common_data_loader.py", line 3, in <module>
    import kaggle
ModuleNotFoundError: No module named 'kaggle'
[2024-09-25T23:00:26.494+0000] {processor.py:927} WARNING - No viable dags retrieved from /opt/airflow/dags/covid_gdp_dag.py
[2024-09-25T23:00:26.530+0000] {processor.py:208} INFO - Processing /opt/airflow/dags/covid_gdp_dag.py took 0.079 seconds
[2024-09-25T23:00:56.873+0000] {processor.py:186} INFO - Started process (PID=508) to work on /opt/airflow/dags/covid_gdp_dag.py
[2024-09-25T23:00:56.874+0000] {processor.py:914} INFO - Processing file /opt/airflow/dags/covid_gdp_dag.py for tasks to queue
[2024-09-25T23:00:56.877+0000] {logging_mixin.py:190} INFO - [2024-09-25T23:00:56.877+0000] {dagbag.py:588} INFO - Filling up the DagBag from /opt/airflow/dags/covid_gdp_dag.py
[2024-09-25T23:00:56.901+0000] {logging_mixin.py:190} INFO - [2024-09-25T23:00:56.894+0000] {dagbag.py:387} ERROR - Failed to import: /opt/airflow/dags/covid_gdp_dag.py
Traceback (most recent call last):
  File "/home/airflow/.local/lib/python3.12/site-packages/airflow/models/dagbag.py", line 383, in parse
    loader.exec_module(new_module)
  File "<frozen importlib._bootstrap_external>", line 995, in exec_module
  File "<frozen importlib._bootstrap>", line 488, in _call_with_frames_removed
  File "/opt/airflow/dags/covid_gdp_dag.py", line 7, in <module>
    from common_data_loader import download_world_bank_data, download_kaggle_dataset, load_covid_data, load_gdp_data
  File "/opt/airflow/dags/common_data_loader.py", line 3, in <module>
    import kaggle
ModuleNotFoundError: No module named 'kaggle'
[2024-09-25T23:00:56.903+0000] {processor.py:927} WARNING - No viable dags retrieved from /opt/airflow/dags/covid_gdp_dag.py
[2024-09-25T23:00:56.925+0000] {processor.py:208} INFO - Processing /opt/airflow/dags/covid_gdp_dag.py took 0.057 seconds
[2024-09-25T23:01:27.142+0000] {processor.py:186} INFO - Started process (PID=571) to work on /opt/airflow/dags/covid_gdp_dag.py
[2024-09-25T23:01:27.143+0000] {processor.py:914} INFO - Processing file /opt/airflow/dags/covid_gdp_dag.py for tasks to queue
[2024-09-25T23:01:27.146+0000] {logging_mixin.py:190} INFO - [2024-09-25T23:01:27.145+0000] {dagbag.py:588} INFO - Filling up the DagBag from /opt/airflow/dags/covid_gdp_dag.py
[2024-09-25T23:01:27.171+0000] {logging_mixin.py:190} INFO - [2024-09-25T23:01:27.164+0000] {dagbag.py:387} ERROR - Failed to import: /opt/airflow/dags/covid_gdp_dag.py
Traceback (most recent call last):
  File "/home/airflow/.local/lib/python3.12/site-packages/airflow/models/dagbag.py", line 383, in parse
    loader.exec_module(new_module)
  File "<frozen importlib._bootstrap_external>", line 995, in exec_module
  File "<frozen importlib._bootstrap>", line 488, in _call_with_frames_removed
  File "/opt/airflow/dags/covid_gdp_dag.py", line 7, in <module>
    from common_data_loader import download_world_bank_data, download_kaggle_dataset, load_covid_data, load_gdp_data
  File "/opt/airflow/dags/common_data_loader.py", line 3, in <module>
    import kaggle
ModuleNotFoundError: No module named 'kaggle'
[2024-09-25T23:01:27.174+0000] {processor.py:927} WARNING - No viable dags retrieved from /opt/airflow/dags/covid_gdp_dag.py
[2024-09-25T23:01:27.201+0000] {processor.py:208} INFO - Processing /opt/airflow/dags/covid_gdp_dag.py took 0.065 seconds
[2024-09-25T23:01:57.694+0000] {processor.py:186} INFO - Started process (PID=634) to work on /opt/airflow/dags/covid_gdp_dag.py
[2024-09-25T23:01:57.695+0000] {processor.py:914} INFO - Processing file /opt/airflow/dags/covid_gdp_dag.py for tasks to queue
[2024-09-25T23:01:57.697+0000] {logging_mixin.py:190} INFO - [2024-09-25T23:01:57.697+0000] {dagbag.py:588} INFO - Filling up the DagBag from /opt/airflow/dags/covid_gdp_dag.py
[2024-09-25T23:01:57.752+0000] {logging_mixin.py:190} INFO - [2024-09-25T23:01:57.744+0000] {dagbag.py:387} ERROR - Failed to import: /opt/airflow/dags/covid_gdp_dag.py
Traceback (most recent call last):
  File "/home/airflow/.local/lib/python3.12/site-packages/airflow/models/dagbag.py", line 383, in parse
    loader.exec_module(new_module)
  File "<frozen importlib._bootstrap_external>", line 995, in exec_module
  File "<frozen importlib._bootstrap>", line 488, in _call_with_frames_removed
  File "/opt/airflow/dags/covid_gdp_dag.py", line 7, in <module>
    from common_data_loader import download_world_bank_data, download_kaggle_dataset, load_covid_data, load_gdp_data
  File "/opt/airflow/dags/common_data_loader.py", line 3, in <module>
    import kaggle
ModuleNotFoundError: No module named 'kaggle'
[2024-09-25T23:01:57.754+0000] {processor.py:927} WARNING - No viable dags retrieved from /opt/airflow/dags/covid_gdp_dag.py
[2024-09-25T23:01:57.777+0000] {processor.py:208} INFO - Processing /opt/airflow/dags/covid_gdp_dag.py took 0.088 seconds
[2024-09-25T23:02:28.200+0000] {processor.py:186} INFO - Started process (PID=697) to work on /opt/airflow/dags/covid_gdp_dag.py
[2024-09-25T23:02:28.202+0000] {processor.py:914} INFO - Processing file /opt/airflow/dags/covid_gdp_dag.py for tasks to queue
[2024-09-25T23:02:28.205+0000] {logging_mixin.py:190} INFO - [2024-09-25T23:02:28.205+0000] {dagbag.py:588} INFO - Filling up the DagBag from /opt/airflow/dags/covid_gdp_dag.py
[2024-09-25T23:02:28.232+0000] {logging_mixin.py:190} INFO - [2024-09-25T23:02:28.227+0000] {dagbag.py:387} ERROR - Failed to import: /opt/airflow/dags/covid_gdp_dag.py
Traceback (most recent call last):
  File "/home/airflow/.local/lib/python3.12/site-packages/airflow/models/dagbag.py", line 383, in parse
    loader.exec_module(new_module)
  File "<frozen importlib._bootstrap_external>", line 995, in exec_module
  File "<frozen importlib._bootstrap>", line 488, in _call_with_frames_removed
  File "/opt/airflow/dags/covid_gdp_dag.py", line 7, in <module>
    from common_data_loader import download_world_bank_data, download_kaggle_dataset, load_covid_data, load_gdp_data
  File "/opt/airflow/dags/common_data_loader.py", line 3, in <module>
    import kaggle
ModuleNotFoundError: No module named 'kaggle'
[2024-09-25T23:02:28.234+0000] {processor.py:927} WARNING - No viable dags retrieved from /opt/airflow/dags/covid_gdp_dag.py
[2024-09-25T23:02:28.259+0000] {processor.py:208} INFO - Processing /opt/airflow/dags/covid_gdp_dag.py took 0.064 seconds
[2024-09-25T23:25:07.323+0000] {processor.py:186} INFO - Started process (PID=754) to work on /opt/airflow/dags/covid_gdp_dag.py
[2024-09-25T23:25:07.335+0000] {processor.py:914} INFO - Processing file /opt/airflow/dags/covid_gdp_dag.py for tasks to queue
[2024-09-25T23:25:07.351+0000] {logging_mixin.py:190} INFO - [2024-09-25T23:25:07.350+0000] {dagbag.py:588} INFO - Filling up the DagBag from /opt/airflow/dags/covid_gdp_dag.py
[2024-09-25T23:25:07.495+0000] {logging_mixin.py:190} INFO - [2024-09-25T23:25:07.475+0000] {dagbag.py:387} ERROR - Failed to import: /opt/airflow/dags/covid_gdp_dag.py
Traceback (most recent call last):
  File "/home/airflow/.local/lib/python3.12/site-packages/airflow/models/dagbag.py", line 383, in parse
    loader.exec_module(new_module)
  File "<frozen importlib._bootstrap_external>", line 995, in exec_module
  File "<frozen importlib._bootstrap>", line 488, in _call_with_frames_removed
  File "/opt/airflow/dags/covid_gdp_dag.py", line 7, in <module>
    from common_data_loader import download_world_bank_data, download_kaggle_dataset, load_covid_data, load_gdp_data
  File "/opt/airflow/dags/common_data_loader.py", line 3, in <module>
    import kaggle
ModuleNotFoundError: No module named 'kaggle'
[2024-09-25T23:25:07.499+0000] {processor.py:927} WARNING - No viable dags retrieved from /opt/airflow/dags/covid_gdp_dag.py
[2024-09-25T23:25:07.577+0000] {processor.py:208} INFO - Processing /opt/airflow/dags/covid_gdp_dag.py took 0.278 seconds
[2024-09-25T23:26:02.971+0000] {processor.py:186} INFO - Started process (PID=817) to work on /opt/airflow/dags/covid_gdp_dag.py
[2024-09-25T23:26:02.973+0000] {processor.py:914} INFO - Processing file /opt/airflow/dags/covid_gdp_dag.py for tasks to queue
[2024-09-25T23:26:02.985+0000] {logging_mixin.py:190} INFO - [2024-09-25T23:26:02.984+0000] {dagbag.py:588} INFO - Filling up the DagBag from /opt/airflow/dags/covid_gdp_dag.py
[2024-09-25T23:26:03.041+0000] {logging_mixin.py:190} INFO - [2024-09-25T23:26:03.023+0000] {dagbag.py:387} ERROR - Failed to import: /opt/airflow/dags/covid_gdp_dag.py
Traceback (most recent call last):
  File "/home/airflow/.local/lib/python3.12/site-packages/airflow/models/dagbag.py", line 383, in parse
    loader.exec_module(new_module)
  File "<frozen importlib._bootstrap_external>", line 995, in exec_module
  File "<frozen importlib._bootstrap>", line 488, in _call_with_frames_removed
  File "/opt/airflow/dags/covid_gdp_dag.py", line 7, in <module>
    from common_data_loader import download_world_bank_data, download_kaggle_dataset, load_covid_data, load_gdp_data
  File "/opt/airflow/dags/common_data_loader.py", line 3, in <module>
    import kaggle
ModuleNotFoundError: No module named 'kaggle'
[2024-09-25T23:26:03.044+0000] {processor.py:927} WARNING - No viable dags retrieved from /opt/airflow/dags/covid_gdp_dag.py
[2024-09-25T23:26:03.087+0000] {processor.py:208} INFO - Processing /opt/airflow/dags/covid_gdp_dag.py took 0.128 seconds
[2024-09-25T23:26:33.959+0000] {processor.py:186} INFO - Started process (PID=864) to work on /opt/airflow/dags/covid_gdp_dag.py
[2024-09-25T23:26:33.962+0000] {processor.py:914} INFO - Processing file /opt/airflow/dags/covid_gdp_dag.py for tasks to queue
[2024-09-25T23:26:33.965+0000] {logging_mixin.py:190} INFO - [2024-09-25T23:26:33.965+0000] {dagbag.py:588} INFO - Filling up the DagBag from /opt/airflow/dags/covid_gdp_dag.py
[2024-09-25T23:26:34.004+0000] {logging_mixin.py:190} INFO - [2024-09-25T23:26:33.994+0000] {dagbag.py:387} ERROR - Failed to import: /opt/airflow/dags/covid_gdp_dag.py
Traceback (most recent call last):
  File "/home/airflow/.local/lib/python3.12/site-packages/airflow/models/dagbag.py", line 383, in parse
    loader.exec_module(new_module)
  File "<frozen importlib._bootstrap_external>", line 995, in exec_module
  File "<frozen importlib._bootstrap>", line 488, in _call_with_frames_removed
  File "/opt/airflow/dags/covid_gdp_dag.py", line 7, in <module>
    from common_data_loader import download_world_bank_data, download_kaggle_dataset, load_covid_data, load_gdp_data
  File "/opt/airflow/dags/common_data_loader.py", line 3, in <module>
    import kaggle
ModuleNotFoundError: No module named 'kaggle'
[2024-09-25T23:26:34.008+0000] {processor.py:927} WARNING - No viable dags retrieved from /opt/airflow/dags/covid_gdp_dag.py
[2024-09-25T23:26:34.062+0000] {processor.py:208} INFO - Processing /opt/airflow/dags/covid_gdp_dag.py took 0.111 seconds
[2024-09-25T23:27:04.637+0000] {processor.py:186} INFO - Started process (PID=923) to work on /opt/airflow/dags/covid_gdp_dag.py
[2024-09-25T23:27:04.638+0000] {processor.py:914} INFO - Processing file /opt/airflow/dags/covid_gdp_dag.py for tasks to queue
[2024-09-25T23:27:04.640+0000] {logging_mixin.py:190} INFO - [2024-09-25T23:27:04.640+0000] {dagbag.py:588} INFO - Filling up the DagBag from /opt/airflow/dags/covid_gdp_dag.py
[2024-09-25T23:27:04.664+0000] {logging_mixin.py:190} INFO - [2024-09-25T23:27:04.657+0000] {dagbag.py:387} ERROR - Failed to import: /opt/airflow/dags/covid_gdp_dag.py
Traceback (most recent call last):
  File "/home/airflow/.local/lib/python3.12/site-packages/airflow/models/dagbag.py", line 383, in parse
    loader.exec_module(new_module)
  File "<frozen importlib._bootstrap_external>", line 995, in exec_module
  File "<frozen importlib._bootstrap>", line 488, in _call_with_frames_removed
  File "/opt/airflow/dags/covid_gdp_dag.py", line 7, in <module>
    from common_data_loader import download_world_bank_data, download_kaggle_dataset, load_covid_data, load_gdp_data
  File "/opt/airflow/dags/common_data_loader.py", line 3, in <module>
    import kaggle
ModuleNotFoundError: No module named 'kaggle'
[2024-09-25T23:27:04.667+0000] {processor.py:927} WARNING - No viable dags retrieved from /opt/airflow/dags/covid_gdp_dag.py
[2024-09-25T23:27:04.694+0000] {processor.py:208} INFO - Processing /opt/airflow/dags/covid_gdp_dag.py took 0.062 seconds
[2024-09-25T23:28:10.364+0000] {processor.py:186} INFO - Started process (PID=62) to work on /opt/airflow/dags/covid_gdp_dag.py
[2024-09-25T23:28:10.373+0000] {processor.py:914} INFO - Processing file /opt/airflow/dags/covid_gdp_dag.py for tasks to queue
[2024-09-25T23:28:10.416+0000] {logging_mixin.py:190} INFO - [2024-09-25T23:28:10.411+0000] {dagbag.py:588} INFO - Filling up the DagBag from /opt/airflow/dags/covid_gdp_dag.py
[2024-09-25T23:28:10.931+0000] {logging_mixin.py:190} INFO - [2024-09-25T23:28:10.887+0000] {dagbag.py:387} ERROR - Failed to import: /opt/airflow/dags/covid_gdp_dag.py
Traceback (most recent call last):
  File "/home/airflow/.local/lib/python3.12/site-packages/airflow/models/dagbag.py", line 383, in parse
    loader.exec_module(new_module)
  File "<frozen importlib._bootstrap_external>", line 995, in exec_module
  File "<frozen importlib._bootstrap>", line 488, in _call_with_frames_removed
  File "/opt/airflow/dags/covid_gdp_dag.py", line 7, in <module>
    from common_data_loader import download_world_bank_data, download_kaggle_dataset, load_covid_data, load_gdp_data
  File "/opt/airflow/dags/common_data_loader.py", line 3, in <module>
    import kaggle
ModuleNotFoundError: No module named 'kaggle'
[2024-09-25T23:28:10.940+0000] {processor.py:927} WARNING - No viable dags retrieved from /opt/airflow/dags/covid_gdp_dag.py
[2024-09-25T23:28:11.284+0000] {processor.py:208} INFO - Processing /opt/airflow/dags/covid_gdp_dag.py took 0.978 seconds
[2024-09-25T23:28:41.840+0000] {processor.py:186} INFO - Started process (PID=132) to work on /opt/airflow/dags/covid_gdp_dag.py
[2024-09-25T23:28:41.842+0000] {processor.py:914} INFO - Processing file /opt/airflow/dags/covid_gdp_dag.py for tasks to queue
[2024-09-25T23:28:41.847+0000] {logging_mixin.py:190} INFO - [2024-09-25T23:28:41.846+0000] {dagbag.py:588} INFO - Filling up the DagBag from /opt/airflow/dags/covid_gdp_dag.py
[2024-09-25T23:28:41.878+0000] {logging_mixin.py:190} INFO - [2024-09-25T23:28:41.870+0000] {dagbag.py:387} ERROR - Failed to import: /opt/airflow/dags/covid_gdp_dag.py
Traceback (most recent call last):
  File "/home/airflow/.local/lib/python3.12/site-packages/airflow/models/dagbag.py", line 383, in parse
    loader.exec_module(new_module)
  File "<frozen importlib._bootstrap_external>", line 995, in exec_module
  File "<frozen importlib._bootstrap>", line 488, in _call_with_frames_removed
  File "/opt/airflow/dags/covid_gdp_dag.py", line 7, in <module>
    from common_data_loader import download_world_bank_data, download_kaggle_dataset, load_covid_data, load_gdp_data
  File "/opt/airflow/dags/common_data_loader.py", line 3, in <module>
    import kaggle
ModuleNotFoundError: No module named 'kaggle'
[2024-09-25T23:28:41.880+0000] {processor.py:927} WARNING - No viable dags retrieved from /opt/airflow/dags/covid_gdp_dag.py
[2024-09-25T23:28:41.911+0000] {processor.py:208} INFO - Processing /opt/airflow/dags/covid_gdp_dag.py took 0.082 seconds
[2024-09-25T23:29:12.153+0000] {processor.py:186} INFO - Started process (PID=195) to work on /opt/airflow/dags/covid_gdp_dag.py
[2024-09-25T23:29:12.155+0000] {processor.py:914} INFO - Processing file /opt/airflow/dags/covid_gdp_dag.py for tasks to queue
[2024-09-25T23:29:12.158+0000] {logging_mixin.py:190} INFO - [2024-09-25T23:29:12.157+0000] {dagbag.py:588} INFO - Filling up the DagBag from /opt/airflow/dags/covid_gdp_dag.py
[2024-09-25T23:29:12.186+0000] {logging_mixin.py:190} INFO - [2024-09-25T23:29:12.180+0000] {dagbag.py:387} ERROR - Failed to import: /opt/airflow/dags/covid_gdp_dag.py
Traceback (most recent call last):
  File "/home/airflow/.local/lib/python3.12/site-packages/airflow/models/dagbag.py", line 383, in parse
    loader.exec_module(new_module)
  File "<frozen importlib._bootstrap_external>", line 995, in exec_module
  File "<frozen importlib._bootstrap>", line 488, in _call_with_frames_removed
  File "/opt/airflow/dags/covid_gdp_dag.py", line 7, in <module>
    from common_data_loader import download_world_bank_data, download_kaggle_dataset, load_covid_data, load_gdp_data
  File "/opt/airflow/dags/common_data_loader.py", line 3, in <module>
    import kaggle
ModuleNotFoundError: No module named 'kaggle'
[2024-09-25T23:29:12.188+0000] {processor.py:927} WARNING - No viable dags retrieved from /opt/airflow/dags/covid_gdp_dag.py
[2024-09-25T23:29:12.217+0000] {processor.py:208} INFO - Processing /opt/airflow/dags/covid_gdp_dag.py took 0.069 seconds
[2024-09-25T23:29:42.771+0000] {processor.py:186} INFO - Started process (PID=258) to work on /opt/airflow/dags/covid_gdp_dag.py
[2024-09-25T23:29:42.772+0000] {processor.py:914} INFO - Processing file /opt/airflow/dags/covid_gdp_dag.py for tasks to queue
[2024-09-25T23:29:42.774+0000] {logging_mixin.py:190} INFO - [2024-09-25T23:29:42.774+0000] {dagbag.py:588} INFO - Filling up the DagBag from /opt/airflow/dags/covid_gdp_dag.py
[2024-09-25T23:29:42.858+0000] {logging_mixin.py:190} INFO - [2024-09-25T23:29:42.846+0000] {dagbag.py:387} ERROR - Failed to import: /opt/airflow/dags/covid_gdp_dag.py
Traceback (most recent call last):
  File "/home/airflow/.local/lib/python3.12/site-packages/airflow/models/dagbag.py", line 383, in parse
    loader.exec_module(new_module)
  File "<frozen importlib._bootstrap_external>", line 995, in exec_module
  File "<frozen importlib._bootstrap>", line 488, in _call_with_frames_removed
  File "/opt/airflow/dags/covid_gdp_dag.py", line 7, in <module>
    from common_data_loader import download_world_bank_data, download_kaggle_dataset, load_covid_data, load_gdp_data
  File "/opt/airflow/dags/common_data_loader.py", line 3, in <module>
    import kaggle
ModuleNotFoundError: No module named 'kaggle'
[2024-09-25T23:29:42.860+0000] {processor.py:927} WARNING - No viable dags retrieved from /opt/airflow/dags/covid_gdp_dag.py
[2024-09-25T23:29:42.890+0000] {processor.py:208} INFO - Processing /opt/airflow/dags/covid_gdp_dag.py took 0.124 seconds
[2024-09-25T23:30:13.086+0000] {processor.py:186} INFO - Started process (PID=321) to work on /opt/airflow/dags/covid_gdp_dag.py
[2024-09-25T23:30:13.087+0000] {processor.py:914} INFO - Processing file /opt/airflow/dags/covid_gdp_dag.py for tasks to queue
[2024-09-25T23:30:13.090+0000] {logging_mixin.py:190} INFO - [2024-09-25T23:30:13.090+0000] {dagbag.py:588} INFO - Filling up the DagBag from /opt/airflow/dags/covid_gdp_dag.py
[2024-09-25T23:30:13.118+0000] {logging_mixin.py:190} INFO - [2024-09-25T23:30:13.112+0000] {dagbag.py:387} ERROR - Failed to import: /opt/airflow/dags/covid_gdp_dag.py
Traceback (most recent call last):
  File "/home/airflow/.local/lib/python3.12/site-packages/airflow/models/dagbag.py", line 383, in parse
    loader.exec_module(new_module)
  File "<frozen importlib._bootstrap_external>", line 995, in exec_module
  File "<frozen importlib._bootstrap>", line 488, in _call_with_frames_removed
  File "/opt/airflow/dags/covid_gdp_dag.py", line 7, in <module>
    from common_data_loader import download_world_bank_data, download_kaggle_dataset, load_covid_data, load_gdp_data
  File "/opt/airflow/dags/common_data_loader.py", line 3, in <module>
    import kaggle
ModuleNotFoundError: No module named 'kaggle'
[2024-09-25T23:30:13.120+0000] {processor.py:927} WARNING - No viable dags retrieved from /opt/airflow/dags/covid_gdp_dag.py
[2024-09-25T23:30:13.143+0000] {processor.py:208} INFO - Processing /opt/airflow/dags/covid_gdp_dag.py took 0.062 seconds
[2024-09-25T23:30:43.330+0000] {processor.py:186} INFO - Started process (PID=384) to work on /opt/airflow/dags/covid_gdp_dag.py
[2024-09-25T23:30:43.331+0000] {processor.py:914} INFO - Processing file /opt/airflow/dags/covid_gdp_dag.py for tasks to queue
[2024-09-25T23:30:43.333+0000] {logging_mixin.py:190} INFO - [2024-09-25T23:30:43.332+0000] {dagbag.py:588} INFO - Filling up the DagBag from /opt/airflow/dags/covid_gdp_dag.py
[2024-09-25T23:30:43.352+0000] {logging_mixin.py:190} INFO - [2024-09-25T23:30:43.347+0000] {dagbag.py:387} ERROR - Failed to import: /opt/airflow/dags/covid_gdp_dag.py
Traceback (most recent call last):
  File "/home/airflow/.local/lib/python3.12/site-packages/airflow/models/dagbag.py", line 383, in parse
    loader.exec_module(new_module)
  File "<frozen importlib._bootstrap_external>", line 995, in exec_module
  File "<frozen importlib._bootstrap>", line 488, in _call_with_frames_removed
  File "/opt/airflow/dags/covid_gdp_dag.py", line 7, in <module>
    from common_data_loader import download_world_bank_data, download_kaggle_dataset, load_covid_data, load_gdp_data
  File "/opt/airflow/dags/common_data_loader.py", line 3, in <module>
    import kaggle
ModuleNotFoundError: No module named 'kaggle'
[2024-09-25T23:30:43.354+0000] {processor.py:927} WARNING - No viable dags retrieved from /opt/airflow/dags/covid_gdp_dag.py
[2024-09-25T23:30:43.377+0000] {processor.py:208} INFO - Processing /opt/airflow/dags/covid_gdp_dag.py took 0.052 seconds
[2024-09-25T23:31:13.955+0000] {processor.py:186} INFO - Started process (PID=447) to work on /opt/airflow/dags/covid_gdp_dag.py
[2024-09-25T23:31:13.957+0000] {processor.py:914} INFO - Processing file /opt/airflow/dags/covid_gdp_dag.py for tasks to queue
[2024-09-25T23:31:13.960+0000] {logging_mixin.py:190} INFO - [2024-09-25T23:31:13.959+0000] {dagbag.py:588} INFO - Filling up the DagBag from /opt/airflow/dags/covid_gdp_dag.py
[2024-09-25T23:31:13.988+0000] {logging_mixin.py:190} INFO - [2024-09-25T23:31:13.983+0000] {dagbag.py:387} ERROR - Failed to import: /opt/airflow/dags/covid_gdp_dag.py
Traceback (most recent call last):
  File "/home/airflow/.local/lib/python3.12/site-packages/airflow/models/dagbag.py", line 383, in parse
    loader.exec_module(new_module)
  File "<frozen importlib._bootstrap_external>", line 995, in exec_module
  File "<frozen importlib._bootstrap>", line 488, in _call_with_frames_removed
  File "/opt/airflow/dags/covid_gdp_dag.py", line 7, in <module>
    from common_data_loader import download_world_bank_data, download_kaggle_dataset, load_covid_data, load_gdp_data
  File "/opt/airflow/dags/common_data_loader.py", line 3, in <module>
    import kaggle
ModuleNotFoundError: No module named 'kaggle'
[2024-09-25T23:31:13.990+0000] {processor.py:927} WARNING - No viable dags retrieved from /opt/airflow/dags/covid_gdp_dag.py
[2024-09-25T23:31:14.044+0000] {processor.py:208} INFO - Processing /opt/airflow/dags/covid_gdp_dag.py took 0.094 seconds
[2024-09-25T23:31:44.364+0000] {processor.py:186} INFO - Started process (PID=510) to work on /opt/airflow/dags/covid_gdp_dag.py
[2024-09-25T23:31:44.365+0000] {processor.py:914} INFO - Processing file /opt/airflow/dags/covid_gdp_dag.py for tasks to queue
[2024-09-25T23:31:44.367+0000] {logging_mixin.py:190} INFO - [2024-09-25T23:31:44.366+0000] {dagbag.py:588} INFO - Filling up the DagBag from /opt/airflow/dags/covid_gdp_dag.py
[2024-09-25T23:31:44.388+0000] {logging_mixin.py:190} INFO - [2024-09-25T23:31:44.382+0000] {dagbag.py:387} ERROR - Failed to import: /opt/airflow/dags/covid_gdp_dag.py
Traceback (most recent call last):
  File "/home/airflow/.local/lib/python3.12/site-packages/airflow/models/dagbag.py", line 383, in parse
    loader.exec_module(new_module)
  File "<frozen importlib._bootstrap_external>", line 995, in exec_module
  File "<frozen importlib._bootstrap>", line 488, in _call_with_frames_removed
  File "/opt/airflow/dags/covid_gdp_dag.py", line 7, in <module>
    from common_data_loader import download_world_bank_data, download_kaggle_dataset, load_covid_data, load_gdp_data
  File "/opt/airflow/dags/common_data_loader.py", line 3, in <module>
    import kaggle
ModuleNotFoundError: No module named 'kaggle'
[2024-09-25T23:31:44.390+0000] {processor.py:927} WARNING - No viable dags retrieved from /opt/airflow/dags/covid_gdp_dag.py
[2024-09-25T23:31:44.410+0000] {processor.py:208} INFO - Processing /opt/airflow/dags/covid_gdp_dag.py took 0.051 seconds
[2024-09-25T23:32:14.790+0000] {processor.py:186} INFO - Started process (PID=573) to work on /opt/airflow/dags/covid_gdp_dag.py
[2024-09-25T23:32:14.791+0000] {processor.py:914} INFO - Processing file /opt/airflow/dags/covid_gdp_dag.py for tasks to queue
[2024-09-25T23:32:14.794+0000] {logging_mixin.py:190} INFO - [2024-09-25T23:32:14.794+0000] {dagbag.py:588} INFO - Filling up the DagBag from /opt/airflow/dags/covid_gdp_dag.py
[2024-09-25T23:32:14.817+0000] {logging_mixin.py:190} INFO - [2024-09-25T23:32:14.811+0000] {dagbag.py:387} ERROR - Failed to import: /opt/airflow/dags/covid_gdp_dag.py
Traceback (most recent call last):
  File "/home/airflow/.local/lib/python3.12/site-packages/airflow/models/dagbag.py", line 383, in parse
    loader.exec_module(new_module)
  File "<frozen importlib._bootstrap_external>", line 995, in exec_module
  File "<frozen importlib._bootstrap>", line 488, in _call_with_frames_removed
  File "/opt/airflow/dags/covid_gdp_dag.py", line 7, in <module>
    from common_data_loader import download_world_bank_data, download_kaggle_dataset, load_covid_data, load_gdp_data
  File "/opt/airflow/dags/common_data_loader.py", line 3, in <module>
    import kaggle
ModuleNotFoundError: No module named 'kaggle'
[2024-09-25T23:32:14.820+0000] {processor.py:927} WARNING - No viable dags retrieved from /opt/airflow/dags/covid_gdp_dag.py
[2024-09-25T23:32:14.873+0000] {processor.py:208} INFO - Processing /opt/airflow/dags/covid_gdp_dag.py took 0.090 seconds
[2024-09-25T23:32:45.048+0000] {processor.py:186} INFO - Started process (PID=636) to work on /opt/airflow/dags/covid_gdp_dag.py
[2024-09-25T23:32:45.049+0000] {processor.py:914} INFO - Processing file /opt/airflow/dags/covid_gdp_dag.py for tasks to queue
[2024-09-25T23:32:45.052+0000] {logging_mixin.py:190} INFO - [2024-09-25T23:32:45.051+0000] {dagbag.py:588} INFO - Filling up the DagBag from /opt/airflow/dags/covid_gdp_dag.py
[2024-09-25T23:32:45.074+0000] {logging_mixin.py:190} INFO - [2024-09-25T23:32:45.068+0000] {dagbag.py:387} ERROR - Failed to import: /opt/airflow/dags/covid_gdp_dag.py
Traceback (most recent call last):
  File "/home/airflow/.local/lib/python3.12/site-packages/airflow/models/dagbag.py", line 383, in parse
    loader.exec_module(new_module)
  File "<frozen importlib._bootstrap_external>", line 995, in exec_module
  File "<frozen importlib._bootstrap>", line 488, in _call_with_frames_removed
  File "/opt/airflow/dags/covid_gdp_dag.py", line 7, in <module>
    from common_data_loader import download_world_bank_data, download_kaggle_dataset, load_covid_data, load_gdp_data
  File "/opt/airflow/dags/common_data_loader.py", line 3, in <module>
    import kaggle
ModuleNotFoundError: No module named 'kaggle'
[2024-09-25T23:32:45.076+0000] {processor.py:927} WARNING - No viable dags retrieved from /opt/airflow/dags/covid_gdp_dag.py
[2024-09-25T23:32:45.101+0000] {processor.py:208} INFO - Processing /opt/airflow/dags/covid_gdp_dag.py took 0.057 seconds
