[2024-09-28T02:18:53.772+0000] {processor.py:186} INFO - Started process (PID=67) to work on /opt/airflow/dags/covid_gdp_dag.py
[2024-09-28T02:18:53.811+0000] {processor.py:914} INFO - Processing file /opt/airflow/dags/covid_gdp_dag.py for tasks to queue
[2024-09-28T02:18:53.868+0000] {logging_mixin.py:190} INFO - [2024-09-28T02:18:53.860+0000] {dagbag.py:588} INFO - Filling up the DagBag from /opt/airflow/dags/covid_gdp_dag.py
[2024-09-28T02:18:54.066+0000] {logging_mixin.py:190} INFO - [2024-09-28T02:18:54.043+0000] {dagbag.py:387} ERROR - Failed to import: /opt/airflow/dags/covid_gdp_dag.py
Traceback (most recent call last):
  File "/home/airflow/.local/lib/python3.12/site-packages/airflow/models/dagbag.py", line 383, in parse
    loader.exec_module(new_module)
  File "<frozen importlib._bootstrap_external>", line 995, in exec_module
  File "<frozen importlib._bootstrap>", line 488, in _call_with_frames_removed
  File "/opt/airflow/dags/covid_gdp_dag.py", line 7, in <module>
    from common_data_loader import download_world_bank_data, download_kaggle_dataset, load_covid_data, load_gdp_data
  File "/opt/airflow/dags/common_data_loader.py", line 3, in <module>
    import kaggle
ModuleNotFoundError: No module named 'kaggle'
[2024-09-28T02:18:54.073+0000] {processor.py:927} WARNING - No viable dags retrieved from /opt/airflow/dags/covid_gdp_dag.py
[2024-09-28T02:18:54.286+0000] {processor.py:208} INFO - Processing /opt/airflow/dags/covid_gdp_dag.py took 0.613 seconds
[2024-09-28T02:19:24.453+0000] {processor.py:186} INFO - Started process (PID=130) to work on /opt/airflow/dags/covid_gdp_dag.py
[2024-09-28T02:19:24.454+0000] {processor.py:914} INFO - Processing file /opt/airflow/dags/covid_gdp_dag.py for tasks to queue
[2024-09-28T02:19:24.457+0000] {logging_mixin.py:190} INFO - [2024-09-28T02:19:24.456+0000] {dagbag.py:588} INFO - Filling up the DagBag from /opt/airflow/dags/covid_gdp_dag.py
[2024-09-28T02:19:24.478+0000] {logging_mixin.py:190} INFO - [2024-09-28T02:19:24.470+0000] {dagbag.py:387} ERROR - Failed to import: /opt/airflow/dags/covid_gdp_dag.py
Traceback (most recent call last):
  File "/home/airflow/.local/lib/python3.12/site-packages/airflow/models/dagbag.py", line 383, in parse
    loader.exec_module(new_module)
  File "<frozen importlib._bootstrap_external>", line 995, in exec_module
  File "<frozen importlib._bootstrap>", line 488, in _call_with_frames_removed
  File "/opt/airflow/dags/covid_gdp_dag.py", line 7, in <module>
    from common_data_loader import download_world_bank_data, download_kaggle_dataset, load_covid_data, load_gdp_data
  File "/opt/airflow/dags/common_data_loader.py", line 3, in <module>
    import kaggle
ModuleNotFoundError: No module named 'kaggle'
[2024-09-28T02:19:24.480+0000] {processor.py:927} WARNING - No viable dags retrieved from /opt/airflow/dags/covid_gdp_dag.py
[2024-09-28T02:19:24.504+0000] {processor.py:208} INFO - Processing /opt/airflow/dags/covid_gdp_dag.py took 0.056 seconds
[2024-09-28T02:19:55.414+0000] {processor.py:186} INFO - Started process (PID=193) to work on /opt/airflow/dags/covid_gdp_dag.py
[2024-09-28T02:19:55.415+0000] {processor.py:914} INFO - Processing file /opt/airflow/dags/covid_gdp_dag.py for tasks to queue
[2024-09-28T02:19:55.418+0000] {logging_mixin.py:190} INFO - [2024-09-28T02:19:55.417+0000] {dagbag.py:588} INFO - Filling up the DagBag from /opt/airflow/dags/covid_gdp_dag.py
[2024-09-28T02:19:55.445+0000] {logging_mixin.py:190} INFO - [2024-09-28T02:19:55.435+0000] {dagbag.py:387} ERROR - Failed to import: /opt/airflow/dags/covid_gdp_dag.py
Traceback (most recent call last):
  File "/home/airflow/.local/lib/python3.12/site-packages/airflow/models/dagbag.py", line 383, in parse
    loader.exec_module(new_module)
  File "<frozen importlib._bootstrap_external>", line 995, in exec_module
  File "<frozen importlib._bootstrap>", line 488, in _call_with_frames_removed
  File "/opt/airflow/dags/covid_gdp_dag.py", line 7, in <module>
    from common_data_loader import download_world_bank_data, download_kaggle_dataset, load_covid_data, load_gdp_data
  File "/opt/airflow/dags/common_data_loader.py", line 3, in <module>
    import kaggle
ModuleNotFoundError: No module named 'kaggle'
[2024-09-28T02:19:55.447+0000] {processor.py:927} WARNING - No viable dags retrieved from /opt/airflow/dags/covid_gdp_dag.py
[2024-09-28T02:19:55.467+0000] {processor.py:208} INFO - Processing /opt/airflow/dags/covid_gdp_dag.py took 0.057 seconds
[2024-09-28T02:20:25.735+0000] {processor.py:186} INFO - Started process (PID=256) to work on /opt/airflow/dags/covid_gdp_dag.py
[2024-09-28T02:20:25.736+0000] {processor.py:914} INFO - Processing file /opt/airflow/dags/covid_gdp_dag.py for tasks to queue
[2024-09-28T02:20:25.738+0000] {logging_mixin.py:190} INFO - [2024-09-28T02:20:25.738+0000] {dagbag.py:588} INFO - Filling up the DagBag from /opt/airflow/dags/covid_gdp_dag.py
[2024-09-28T02:20:25.769+0000] {logging_mixin.py:190} INFO - [2024-09-28T02:20:25.761+0000] {dagbag.py:387} ERROR - Failed to import: /opt/airflow/dags/covid_gdp_dag.py
Traceback (most recent call last):
  File "/home/airflow/.local/lib/python3.12/site-packages/airflow/models/dagbag.py", line 383, in parse
    loader.exec_module(new_module)
  File "<frozen importlib._bootstrap_external>", line 995, in exec_module
  File "<frozen importlib._bootstrap>", line 488, in _call_with_frames_removed
  File "/opt/airflow/dags/covid_gdp_dag.py", line 7, in <module>
    from common_data_loader import download_world_bank_data, download_kaggle_dataset, load_covid_data, load_gdp_data
  File "/opt/airflow/dags/common_data_loader.py", line 3, in <module>
    import kaggle
ModuleNotFoundError: No module named 'kaggle'
[2024-09-28T02:20:25.771+0000] {processor.py:927} WARNING - No viable dags retrieved from /opt/airflow/dags/covid_gdp_dag.py
[2024-09-28T02:20:25.800+0000] {processor.py:208} INFO - Processing /opt/airflow/dags/covid_gdp_dag.py took 0.069 seconds
[2024-09-28T02:20:56.518+0000] {processor.py:186} INFO - Started process (PID=319) to work on /opt/airflow/dags/covid_gdp_dag.py
[2024-09-28T02:20:56.520+0000] {processor.py:914} INFO - Processing file /opt/airflow/dags/covid_gdp_dag.py for tasks to queue
[2024-09-28T02:20:56.523+0000] {logging_mixin.py:190} INFO - [2024-09-28T02:20:56.523+0000] {dagbag.py:588} INFO - Filling up the DagBag from /opt/airflow/dags/covid_gdp_dag.py
[2024-09-28T02:20:56.552+0000] {logging_mixin.py:190} INFO - [2024-09-28T02:20:56.545+0000] {dagbag.py:387} ERROR - Failed to import: /opt/airflow/dags/covid_gdp_dag.py
Traceback (most recent call last):
  File "/home/airflow/.local/lib/python3.12/site-packages/airflow/models/dagbag.py", line 383, in parse
    loader.exec_module(new_module)
  File "<frozen importlib._bootstrap_external>", line 995, in exec_module
  File "<frozen importlib._bootstrap>", line 488, in _call_with_frames_removed
  File "/opt/airflow/dags/covid_gdp_dag.py", line 7, in <module>
    from common_data_loader import download_world_bank_data, download_kaggle_dataset, load_covid_data, load_gdp_data
  File "/opt/airflow/dags/common_data_loader.py", line 3, in <module>
    import kaggle
ModuleNotFoundError: No module named 'kaggle'
[2024-09-28T02:20:56.555+0000] {processor.py:927} WARNING - No viable dags retrieved from /opt/airflow/dags/covid_gdp_dag.py
[2024-09-28T02:20:56.592+0000] {processor.py:208} INFO - Processing /opt/airflow/dags/covid_gdp_dag.py took 0.081 seconds
[2024-09-28T02:21:27.015+0000] {processor.py:186} INFO - Started process (PID=382) to work on /opt/airflow/dags/covid_gdp_dag.py
[2024-09-28T02:21:27.016+0000] {processor.py:914} INFO - Processing file /opt/airflow/dags/covid_gdp_dag.py for tasks to queue
[2024-09-28T02:21:27.019+0000] {logging_mixin.py:190} INFO - [2024-09-28T02:21:27.019+0000] {dagbag.py:588} INFO - Filling up the DagBag from /opt/airflow/dags/covid_gdp_dag.py
[2024-09-28T02:21:27.041+0000] {logging_mixin.py:190} INFO - [2024-09-28T02:21:27.035+0000] {dagbag.py:387} ERROR - Failed to import: /opt/airflow/dags/covid_gdp_dag.py
Traceback (most recent call last):
  File "/home/airflow/.local/lib/python3.12/site-packages/airflow/models/dagbag.py", line 383, in parse
    loader.exec_module(new_module)
  File "<frozen importlib._bootstrap_external>", line 995, in exec_module
  File "<frozen importlib._bootstrap>", line 488, in _call_with_frames_removed
  File "/opt/airflow/dags/covid_gdp_dag.py", line 7, in <module>
    from common_data_loader import download_world_bank_data, download_kaggle_dataset, load_covid_data, load_gdp_data
  File "/opt/airflow/dags/common_data_loader.py", line 3, in <module>
    import kaggle
ModuleNotFoundError: No module named 'kaggle'
[2024-09-28T02:21:27.043+0000] {processor.py:927} WARNING - No viable dags retrieved from /opt/airflow/dags/covid_gdp_dag.py
[2024-09-28T02:21:27.071+0000] {processor.py:208} INFO - Processing /opt/airflow/dags/covid_gdp_dag.py took 0.060 seconds
[2024-09-28T02:21:57.457+0000] {processor.py:186} INFO - Started process (PID=445) to work on /opt/airflow/dags/covid_gdp_dag.py
[2024-09-28T02:21:57.458+0000] {processor.py:914} INFO - Processing file /opt/airflow/dags/covid_gdp_dag.py for tasks to queue
[2024-09-28T02:21:57.461+0000] {logging_mixin.py:190} INFO - [2024-09-28T02:21:57.461+0000] {dagbag.py:588} INFO - Filling up the DagBag from /opt/airflow/dags/covid_gdp_dag.py
[2024-09-28T02:21:57.481+0000] {logging_mixin.py:190} INFO - [2024-09-28T02:21:57.476+0000] {dagbag.py:387} ERROR - Failed to import: /opt/airflow/dags/covid_gdp_dag.py
Traceback (most recent call last):
  File "/home/airflow/.local/lib/python3.12/site-packages/airflow/models/dagbag.py", line 383, in parse
    loader.exec_module(new_module)
  File "<frozen importlib._bootstrap_external>", line 995, in exec_module
  File "<frozen importlib._bootstrap>", line 488, in _call_with_frames_removed
  File "/opt/airflow/dags/covid_gdp_dag.py", line 7, in <module>
    from common_data_loader import download_world_bank_data, download_kaggle_dataset, load_covid_data, load_gdp_data
  File "/opt/airflow/dags/common_data_loader.py", line 3, in <module>
    import kaggle
ModuleNotFoundError: No module named 'kaggle'
[2024-09-28T02:21:57.483+0000] {processor.py:927} WARNING - No viable dags retrieved from /opt/airflow/dags/covid_gdp_dag.py
[2024-09-28T02:21:57.507+0000] {processor.py:208} INFO - Processing /opt/airflow/dags/covid_gdp_dag.py took 0.054 seconds
[2024-09-28T02:22:27.852+0000] {processor.py:186} INFO - Started process (PID=508) to work on /opt/airflow/dags/covid_gdp_dag.py
[2024-09-28T02:22:27.853+0000] {processor.py:914} INFO - Processing file /opt/airflow/dags/covid_gdp_dag.py for tasks to queue
[2024-09-28T02:22:27.855+0000] {logging_mixin.py:190} INFO - [2024-09-28T02:22:27.855+0000] {dagbag.py:588} INFO - Filling up the DagBag from /opt/airflow/dags/covid_gdp_dag.py
[2024-09-28T02:22:27.875+0000] {logging_mixin.py:190} INFO - [2024-09-28T02:22:27.870+0000] {dagbag.py:387} ERROR - Failed to import: /opt/airflow/dags/covid_gdp_dag.py
Traceback (most recent call last):
  File "/home/airflow/.local/lib/python3.12/site-packages/airflow/models/dagbag.py", line 383, in parse
    loader.exec_module(new_module)
  File "<frozen importlib._bootstrap_external>", line 995, in exec_module
  File "<frozen importlib._bootstrap>", line 488, in _call_with_frames_removed
  File "/opt/airflow/dags/covid_gdp_dag.py", line 7, in <module>
    from common_data_loader import download_world_bank_data, download_kaggle_dataset, load_covid_data, load_gdp_data
  File "/opt/airflow/dags/common_data_loader.py", line 3, in <module>
    import kaggle
ModuleNotFoundError: No module named 'kaggle'
[2024-09-28T02:22:27.877+0000] {processor.py:927} WARNING - No viable dags retrieved from /opt/airflow/dags/covid_gdp_dag.py
[2024-09-28T02:22:27.944+0000] {processor.py:208} INFO - Processing /opt/airflow/dags/covid_gdp_dag.py took 0.097 seconds
[2024-09-28T02:22:58.973+0000] {processor.py:186} INFO - Started process (PID=572) to work on /opt/airflow/dags/covid_gdp_dag.py
[2024-09-28T02:22:58.975+0000] {processor.py:914} INFO - Processing file /opt/airflow/dags/covid_gdp_dag.py for tasks to queue
[2024-09-28T02:22:58.977+0000] {logging_mixin.py:190} INFO - [2024-09-28T02:22:58.977+0000] {dagbag.py:588} INFO - Filling up the DagBag from /opt/airflow/dags/covid_gdp_dag.py
[2024-09-28T02:22:59.001+0000] {logging_mixin.py:190} INFO - [2024-09-28T02:22:58.995+0000] {dagbag.py:387} ERROR - Failed to import: /opt/airflow/dags/covid_gdp_dag.py
Traceback (most recent call last):
  File "/home/airflow/.local/lib/python3.12/site-packages/airflow/models/dagbag.py", line 383, in parse
    loader.exec_module(new_module)
  File "<frozen importlib._bootstrap_external>", line 995, in exec_module
  File "<frozen importlib._bootstrap>", line 488, in _call_with_frames_removed
  File "/opt/airflow/dags/covid_gdp_dag.py", line 7, in <module>
    from common_data_loader import download_world_bank_data, download_kaggle_dataset, load_covid_data, load_gdp_data
  File "/opt/airflow/dags/common_data_loader.py", line 3, in <module>
    import kaggle
ModuleNotFoundError: No module named 'kaggle'
[2024-09-28T02:22:59.003+0000] {processor.py:927} WARNING - No viable dags retrieved from /opt/airflow/dags/covid_gdp_dag.py
[2024-09-28T02:22:59.024+0000] {processor.py:208} INFO - Processing /opt/airflow/dags/covid_gdp_dag.py took 0.055 seconds
[2024-09-28T02:23:29.308+0000] {processor.py:186} INFO - Started process (PID=635) to work on /opt/airflow/dags/covid_gdp_dag.py
[2024-09-28T02:23:29.309+0000] {processor.py:914} INFO - Processing file /opt/airflow/dags/covid_gdp_dag.py for tasks to queue
[2024-09-28T02:23:29.312+0000] {logging_mixin.py:190} INFO - [2024-09-28T02:23:29.312+0000] {dagbag.py:588} INFO - Filling up the DagBag from /opt/airflow/dags/covid_gdp_dag.py
[2024-09-28T02:23:29.334+0000] {logging_mixin.py:190} INFO - [2024-09-28T02:23:29.329+0000] {dagbag.py:387} ERROR - Failed to import: /opt/airflow/dags/covid_gdp_dag.py
Traceback (most recent call last):
  File "/home/airflow/.local/lib/python3.12/site-packages/airflow/models/dagbag.py", line 383, in parse
    loader.exec_module(new_module)
  File "<frozen importlib._bootstrap_external>", line 995, in exec_module
  File "<frozen importlib._bootstrap>", line 488, in _call_with_frames_removed
  File "/opt/airflow/dags/covid_gdp_dag.py", line 7, in <module>
    from common_data_loader import download_world_bank_data, download_kaggle_dataset, load_covid_data, load_gdp_data
  File "/opt/airflow/dags/common_data_loader.py", line 3, in <module>
    import kaggle
ModuleNotFoundError: No module named 'kaggle'
[2024-09-28T02:23:29.336+0000] {processor.py:927} WARNING - No viable dags retrieved from /opt/airflow/dags/covid_gdp_dag.py
[2024-09-28T02:23:29.388+0000] {processor.py:208} INFO - Processing /opt/airflow/dags/covid_gdp_dag.py took 0.084 seconds
[2024-09-28T02:24:00.126+0000] {processor.py:186} INFO - Started process (PID=698) to work on /opt/airflow/dags/covid_gdp_dag.py
[2024-09-28T02:24:00.129+0000] {processor.py:914} INFO - Processing file /opt/airflow/dags/covid_gdp_dag.py for tasks to queue
[2024-09-28T02:24:00.139+0000] {logging_mixin.py:190} INFO - [2024-09-28T02:24:00.138+0000] {dagbag.py:588} INFO - Filling up the DagBag from /opt/airflow/dags/covid_gdp_dag.py
[2024-09-28T02:24:00.178+0000] {logging_mixin.py:190} INFO - [2024-09-28T02:24:00.167+0000] {dagbag.py:387} ERROR - Failed to import: /opt/airflow/dags/covid_gdp_dag.py
Traceback (most recent call last):
  File "/home/airflow/.local/lib/python3.12/site-packages/airflow/models/dagbag.py", line 383, in parse
    loader.exec_module(new_module)
  File "<frozen importlib._bootstrap_external>", line 995, in exec_module
  File "<frozen importlib._bootstrap>", line 488, in _call_with_frames_removed
  File "/opt/airflow/dags/covid_gdp_dag.py", line 7, in <module>
    from common_data_loader import download_world_bank_data, download_kaggle_dataset, load_covid_data, load_gdp_data
  File "/opt/airflow/dags/common_data_loader.py", line 3, in <module>
    import kaggle
ModuleNotFoundError: No module named 'kaggle'
[2024-09-28T02:24:00.181+0000] {processor.py:927} WARNING - No viable dags retrieved from /opt/airflow/dags/covid_gdp_dag.py
[2024-09-28T02:24:00.235+0000] {processor.py:208} INFO - Processing /opt/airflow/dags/covid_gdp_dag.py took 0.124 seconds
[2024-09-28T02:24:30.464+0000] {processor.py:186} INFO - Started process (PID=761) to work on /opt/airflow/dags/covid_gdp_dag.py
[2024-09-28T02:24:30.465+0000] {processor.py:914} INFO - Processing file /opt/airflow/dags/covid_gdp_dag.py for tasks to queue
[2024-09-28T02:24:30.469+0000] {logging_mixin.py:190} INFO - [2024-09-28T02:24:30.467+0000] {dagbag.py:588} INFO - Filling up the DagBag from /opt/airflow/dags/covid_gdp_dag.py
[2024-09-28T02:24:30.491+0000] {logging_mixin.py:190} INFO - [2024-09-28T02:24:30.486+0000] {dagbag.py:387} ERROR - Failed to import: /opt/airflow/dags/covid_gdp_dag.py
Traceback (most recent call last):
  File "/home/airflow/.local/lib/python3.12/site-packages/airflow/models/dagbag.py", line 383, in parse
    loader.exec_module(new_module)
  File "<frozen importlib._bootstrap_external>", line 995, in exec_module
  File "<frozen importlib._bootstrap>", line 488, in _call_with_frames_removed
  File "/opt/airflow/dags/covid_gdp_dag.py", line 7, in <module>
    from common_data_loader import download_world_bank_data, download_kaggle_dataset, load_covid_data, load_gdp_data
  File "/opt/airflow/dags/common_data_loader.py", line 3, in <module>
    import kaggle
ModuleNotFoundError: No module named 'kaggle'
[2024-09-28T02:24:30.493+0000] {processor.py:927} WARNING - No viable dags retrieved from /opt/airflow/dags/covid_gdp_dag.py
[2024-09-28T02:24:30.514+0000] {processor.py:208} INFO - Processing /opt/airflow/dags/covid_gdp_dag.py took 0.055 seconds
[2024-09-28T02:25:01.141+0000] {processor.py:186} INFO - Started process (PID=824) to work on /opt/airflow/dags/covid_gdp_dag.py
[2024-09-28T02:25:01.142+0000] {processor.py:914} INFO - Processing file /opt/airflow/dags/covid_gdp_dag.py for tasks to queue
[2024-09-28T02:25:01.144+0000] {logging_mixin.py:190} INFO - [2024-09-28T02:25:01.144+0000] {dagbag.py:588} INFO - Filling up the DagBag from /opt/airflow/dags/covid_gdp_dag.py
[2024-09-28T02:25:01.196+0000] {logging_mixin.py:190} INFO - [2024-09-28T02:25:01.188+0000] {dagbag.py:387} ERROR - Failed to import: /opt/airflow/dags/covid_gdp_dag.py
Traceback (most recent call last):
  File "/home/airflow/.local/lib/python3.12/site-packages/airflow/models/dagbag.py", line 383, in parse
    loader.exec_module(new_module)
  File "<frozen importlib._bootstrap_external>", line 995, in exec_module
  File "<frozen importlib._bootstrap>", line 488, in _call_with_frames_removed
  File "/opt/airflow/dags/covid_gdp_dag.py", line 7, in <module>
    from common_data_loader import download_world_bank_data, download_kaggle_dataset, load_covid_data, load_gdp_data
  File "/opt/airflow/dags/common_data_loader.py", line 3, in <module>
    import kaggle
ModuleNotFoundError: No module named 'kaggle'
[2024-09-28T02:25:01.199+0000] {processor.py:927} WARNING - No viable dags retrieved from /opt/airflow/dags/covid_gdp_dag.py
[2024-09-28T02:25:01.226+0000] {processor.py:208} INFO - Processing /opt/airflow/dags/covid_gdp_dag.py took 0.090 seconds
[2024-09-28T02:25:31.423+0000] {processor.py:186} INFO - Started process (PID=887) to work on /opt/airflow/dags/covid_gdp_dag.py
[2024-09-28T02:25:31.424+0000] {processor.py:914} INFO - Processing file /opt/airflow/dags/covid_gdp_dag.py for tasks to queue
[2024-09-28T02:25:31.428+0000] {logging_mixin.py:190} INFO - [2024-09-28T02:25:31.427+0000] {dagbag.py:588} INFO - Filling up the DagBag from /opt/airflow/dags/covid_gdp_dag.py
[2024-09-28T02:25:31.454+0000] {logging_mixin.py:190} INFO - [2024-09-28T02:25:31.448+0000] {dagbag.py:387} ERROR - Failed to import: /opt/airflow/dags/covid_gdp_dag.py
Traceback (most recent call last):
  File "/home/airflow/.local/lib/python3.12/site-packages/airflow/models/dagbag.py", line 383, in parse
    loader.exec_module(new_module)
  File "<frozen importlib._bootstrap_external>", line 995, in exec_module
  File "<frozen importlib._bootstrap>", line 488, in _call_with_frames_removed
  File "/opt/airflow/dags/covid_gdp_dag.py", line 7, in <module>
    from common_data_loader import download_world_bank_data, download_kaggle_dataset, load_covid_data, load_gdp_data
  File "/opt/airflow/dags/common_data_loader.py", line 3, in <module>
    import kaggle
ModuleNotFoundError: No module named 'kaggle'
[2024-09-28T02:25:31.457+0000] {processor.py:927} WARNING - No viable dags retrieved from /opt/airflow/dags/covid_gdp_dag.py
[2024-09-28T02:25:31.485+0000] {processor.py:208} INFO - Processing /opt/airflow/dags/covid_gdp_dag.py took 0.069 seconds
[2024-09-28T02:26:01.827+0000] {processor.py:186} INFO - Started process (PID=950) to work on /opt/airflow/dags/covid_gdp_dag.py
[2024-09-28T02:26:01.829+0000] {processor.py:914} INFO - Processing file /opt/airflow/dags/covid_gdp_dag.py for tasks to queue
[2024-09-28T02:26:01.831+0000] {logging_mixin.py:190} INFO - [2024-09-28T02:26:01.830+0000] {dagbag.py:588} INFO - Filling up the DagBag from /opt/airflow/dags/covid_gdp_dag.py
[2024-09-28T02:26:01.853+0000] {logging_mixin.py:190} INFO - [2024-09-28T02:26:01.847+0000] {dagbag.py:387} ERROR - Failed to import: /opt/airflow/dags/covid_gdp_dag.py
Traceback (most recent call last):
  File "/home/airflow/.local/lib/python3.12/site-packages/airflow/models/dagbag.py", line 383, in parse
    loader.exec_module(new_module)
  File "<frozen importlib._bootstrap_external>", line 995, in exec_module
  File "<frozen importlib._bootstrap>", line 488, in _call_with_frames_removed
  File "/opt/airflow/dags/covid_gdp_dag.py", line 7, in <module>
    from common_data_loader import download_world_bank_data, download_kaggle_dataset, load_covid_data, load_gdp_data
  File "/opt/airflow/dags/common_data_loader.py", line 3, in <module>
    import kaggle
ModuleNotFoundError: No module named 'kaggle'
[2024-09-28T02:26:01.855+0000] {processor.py:927} WARNING - No viable dags retrieved from /opt/airflow/dags/covid_gdp_dag.py
[2024-09-28T02:26:01.877+0000] {processor.py:208} INFO - Processing /opt/airflow/dags/covid_gdp_dag.py took 0.055 seconds
[2024-09-28T02:45:58.087+0000] {processor.py:186} INFO - Started process (PID=66) to work on /opt/airflow/dags/covid_gdp_dag.py
[2024-09-28T02:45:58.091+0000] {processor.py:914} INFO - Processing file /opt/airflow/dags/covid_gdp_dag.py for tasks to queue
[2024-09-28T02:45:58.115+0000] {logging_mixin.py:190} INFO - [2024-09-28T02:45:58.113+0000] {dagbag.py:588} INFO - Filling up the DagBag from /opt/airflow/dags/covid_gdp_dag.py
[2024-09-28T02:45:58.245+0000] {logging_mixin.py:190} INFO - [2024-09-28T02:45:58.222+0000] {dagbag.py:387} ERROR - Failed to import: /opt/airflow/dags/covid_gdp_dag.py
Traceback (most recent call last):
  File "/home/airflow/.local/lib/python3.12/site-packages/airflow/models/dagbag.py", line 383, in parse
    loader.exec_module(new_module)
  File "<frozen importlib._bootstrap_external>", line 995, in exec_module
  File "<frozen importlib._bootstrap>", line 488, in _call_with_frames_removed
  File "/opt/airflow/dags/covid_gdp_dag.py", line 7, in <module>
    from common_data_loader import download_world_bank_data, download_kaggle_dataset, load_covid_data, load_gdp_data
  File "/opt/airflow/dags/common_data_loader.py", line 3, in <module>
    import kaggle
ModuleNotFoundError: No module named 'kaggle'
[2024-09-28T02:45:58.252+0000] {processor.py:927} WARNING - No viable dags retrieved from /opt/airflow/dags/covid_gdp_dag.py
[2024-09-28T02:45:58.468+0000] {processor.py:208} INFO - Processing /opt/airflow/dags/covid_gdp_dag.py took 0.423 seconds
[2024-09-28T02:46:28.703+0000] {processor.py:186} INFO - Started process (PID=129) to work on /opt/airflow/dags/covid_gdp_dag.py
[2024-09-28T02:46:28.705+0000] {processor.py:914} INFO - Processing file /opt/airflow/dags/covid_gdp_dag.py for tasks to queue
[2024-09-28T02:46:28.712+0000] {logging_mixin.py:190} INFO - [2024-09-28T02:46:28.711+0000] {dagbag.py:588} INFO - Filling up the DagBag from /opt/airflow/dags/covid_gdp_dag.py
[2024-09-28T02:46:28.886+0000] {logging_mixin.py:190} INFO - [2024-09-28T02:46:28.861+0000] {dagbag.py:387} ERROR - Failed to import: /opt/airflow/dags/covid_gdp_dag.py
Traceback (most recent call last):
  File "/home/airflow/.local/lib/python3.12/site-packages/airflow/models/dagbag.py", line 383, in parse
    loader.exec_module(new_module)
  File "<frozen importlib._bootstrap_external>", line 995, in exec_module
  File "<frozen importlib._bootstrap>", line 488, in _call_with_frames_removed
  File "/opt/airflow/dags/covid_gdp_dag.py", line 7, in <module>
    from common_data_loader import download_world_bank_data, download_kaggle_dataset, load_covid_data, load_gdp_data
  File "/opt/airflow/dags/common_data_loader.py", line 3, in <module>
    import kaggle
ModuleNotFoundError: No module named 'kaggle'
[2024-09-28T02:46:28.889+0000] {processor.py:927} WARNING - No viable dags retrieved from /opt/airflow/dags/covid_gdp_dag.py
[2024-09-28T02:46:28.947+0000] {processor.py:208} INFO - Processing /opt/airflow/dags/covid_gdp_dag.py took 0.259 seconds
[2024-09-28T02:46:59.400+0000] {processor.py:186} INFO - Started process (PID=192) to work on /opt/airflow/dags/covid_gdp_dag.py
[2024-09-28T02:46:59.401+0000] {processor.py:914} INFO - Processing file /opt/airflow/dags/covid_gdp_dag.py for tasks to queue
[2024-09-28T02:46:59.407+0000] {logging_mixin.py:190} INFO - [2024-09-28T02:46:59.406+0000] {dagbag.py:588} INFO - Filling up the DagBag from /opt/airflow/dags/covid_gdp_dag.py
[2024-09-28T02:46:59.458+0000] {logging_mixin.py:190} INFO - [2024-09-28T02:46:59.447+0000] {dagbag.py:387} ERROR - Failed to import: /opt/airflow/dags/covid_gdp_dag.py
Traceback (most recent call last):
  File "/home/airflow/.local/lib/python3.12/site-packages/airflow/models/dagbag.py", line 383, in parse
    loader.exec_module(new_module)
  File "<frozen importlib._bootstrap_external>", line 995, in exec_module
  File "<frozen importlib._bootstrap>", line 488, in _call_with_frames_removed
  File "/opt/airflow/dags/covid_gdp_dag.py", line 7, in <module>
    from common_data_loader import download_world_bank_data, download_kaggle_dataset, load_covid_data, load_gdp_data
  File "/opt/airflow/dags/common_data_loader.py", line 3, in <module>
    import kaggle
ModuleNotFoundError: No module named 'kaggle'
[2024-09-28T02:46:59.462+0000] {processor.py:927} WARNING - No viable dags retrieved from /opt/airflow/dags/covid_gdp_dag.py
[2024-09-28T02:46:59.568+0000] {processor.py:208} INFO - Processing /opt/airflow/dags/covid_gdp_dag.py took 0.180 seconds
[2024-09-28T02:47:30.459+0000] {processor.py:186} INFO - Started process (PID=256) to work on /opt/airflow/dags/covid_gdp_dag.py
[2024-09-28T02:47:30.461+0000] {processor.py:914} INFO - Processing file /opt/airflow/dags/covid_gdp_dag.py for tasks to queue
[2024-09-28T02:47:30.468+0000] {logging_mixin.py:190} INFO - [2024-09-28T02:47:30.468+0000] {dagbag.py:588} INFO - Filling up the DagBag from /opt/airflow/dags/covid_gdp_dag.py
[2024-09-28T02:47:30.507+0000] {logging_mixin.py:190} INFO - [2024-09-28T02:47:30.498+0000] {dagbag.py:387} ERROR - Failed to import: /opt/airflow/dags/covid_gdp_dag.py
Traceback (most recent call last):
  File "/home/airflow/.local/lib/python3.12/site-packages/airflow/models/dagbag.py", line 383, in parse
    loader.exec_module(new_module)
  File "<frozen importlib._bootstrap_external>", line 995, in exec_module
  File "<frozen importlib._bootstrap>", line 488, in _call_with_frames_removed
  File "/opt/airflow/dags/covid_gdp_dag.py", line 7, in <module>
    from common_data_loader import download_world_bank_data, download_kaggle_dataset, load_covid_data, load_gdp_data
  File "/opt/airflow/dags/common_data_loader.py", line 3, in <module>
    import kaggle
ModuleNotFoundError: No module named 'kaggle'
[2024-09-28T02:47:30.509+0000] {processor.py:927} WARNING - No viable dags retrieved from /opt/airflow/dags/covid_gdp_dag.py
[2024-09-28T02:47:30.545+0000] {processor.py:208} INFO - Processing /opt/airflow/dags/covid_gdp_dag.py took 0.098 seconds
[2024-09-28T02:48:00.678+0000] {processor.py:186} INFO - Started process (PID=319) to work on /opt/airflow/dags/covid_gdp_dag.py
[2024-09-28T02:48:00.679+0000] {processor.py:914} INFO - Processing file /opt/airflow/dags/covid_gdp_dag.py for tasks to queue
[2024-09-28T02:48:00.683+0000] {logging_mixin.py:190} INFO - [2024-09-28T02:48:00.682+0000] {dagbag.py:588} INFO - Filling up the DagBag from /opt/airflow/dags/covid_gdp_dag.py
[2024-09-28T02:48:00.710+0000] {logging_mixin.py:190} INFO - [2024-09-28T02:48:00.703+0000] {dagbag.py:387} ERROR - Failed to import: /opt/airflow/dags/covid_gdp_dag.py
Traceback (most recent call last):
  File "/home/airflow/.local/lib/python3.12/site-packages/airflow/models/dagbag.py", line 383, in parse
    loader.exec_module(new_module)
  File "<frozen importlib._bootstrap_external>", line 995, in exec_module
  File "<frozen importlib._bootstrap>", line 488, in _call_with_frames_removed
  File "/opt/airflow/dags/covid_gdp_dag.py", line 7, in <module>
    from common_data_loader import download_world_bank_data, download_kaggle_dataset, load_covid_data, load_gdp_data
  File "/opt/airflow/dags/common_data_loader.py", line 3, in <module>
    import kaggle
ModuleNotFoundError: No module named 'kaggle'
[2024-09-28T02:48:00.711+0000] {processor.py:927} WARNING - No viable dags retrieved from /opt/airflow/dags/covid_gdp_dag.py
[2024-09-28T02:48:00.760+0000] {processor.py:208} INFO - Processing /opt/airflow/dags/covid_gdp_dag.py took 0.087 seconds
[2024-09-28T02:48:31.608+0000] {processor.py:186} INFO - Started process (PID=382) to work on /opt/airflow/dags/covid_gdp_dag.py
[2024-09-28T02:48:31.609+0000] {processor.py:914} INFO - Processing file /opt/airflow/dags/covid_gdp_dag.py for tasks to queue
[2024-09-28T02:48:31.611+0000] {logging_mixin.py:190} INFO - [2024-09-28T02:48:31.611+0000] {dagbag.py:588} INFO - Filling up the DagBag from /opt/airflow/dags/covid_gdp_dag.py
[2024-09-28T02:48:31.635+0000] {logging_mixin.py:190} INFO - [2024-09-28T02:48:31.627+0000] {dagbag.py:387} ERROR - Failed to import: /opt/airflow/dags/covid_gdp_dag.py
Traceback (most recent call last):
  File "/home/airflow/.local/lib/python3.12/site-packages/airflow/models/dagbag.py", line 383, in parse
    loader.exec_module(new_module)
  File "<frozen importlib._bootstrap_external>", line 995, in exec_module
  File "<frozen importlib._bootstrap>", line 488, in _call_with_frames_removed
  File "/opt/airflow/dags/covid_gdp_dag.py", line 7, in <module>
    from common_data_loader import download_world_bank_data, download_kaggle_dataset, load_covid_data, load_gdp_data
  File "/opt/airflow/dags/common_data_loader.py", line 3, in <module>
    import kaggle
ModuleNotFoundError: No module named 'kaggle'
[2024-09-28T02:48:31.637+0000] {processor.py:927} WARNING - No viable dags retrieved from /opt/airflow/dags/covid_gdp_dag.py
[2024-09-28T02:48:31.670+0000] {processor.py:208} INFO - Processing /opt/airflow/dags/covid_gdp_dag.py took 0.067 seconds
[2024-09-28T02:49:02.599+0000] {processor.py:186} INFO - Started process (PID=445) to work on /opt/airflow/dags/covid_gdp_dag.py
[2024-09-28T02:49:02.600+0000] {processor.py:914} INFO - Processing file /opt/airflow/dags/covid_gdp_dag.py for tasks to queue
[2024-09-28T02:49:02.603+0000] {logging_mixin.py:190} INFO - [2024-09-28T02:49:02.603+0000] {dagbag.py:588} INFO - Filling up the DagBag from /opt/airflow/dags/covid_gdp_dag.py
[2024-09-28T02:49:02.631+0000] {logging_mixin.py:190} INFO - [2024-09-28T02:49:02.622+0000] {dagbag.py:387} ERROR - Failed to import: /opt/airflow/dags/covid_gdp_dag.py
Traceback (most recent call last):
  File "/home/airflow/.local/lib/python3.12/site-packages/airflow/models/dagbag.py", line 383, in parse
    loader.exec_module(new_module)
  File "<frozen importlib._bootstrap_external>", line 995, in exec_module
  File "<frozen importlib._bootstrap>", line 488, in _call_with_frames_removed
  File "/opt/airflow/dags/covid_gdp_dag.py", line 7, in <module>
    from common_data_loader import download_world_bank_data, download_kaggle_dataset, load_covid_data, load_gdp_data
  File "/opt/airflow/dags/common_data_loader.py", line 3, in <module>
    import kaggle
ModuleNotFoundError: No module named 'kaggle'
[2024-09-28T02:49:02.633+0000] {processor.py:927} WARNING - No viable dags retrieved from /opt/airflow/dags/covid_gdp_dag.py
[2024-09-28T02:49:02.677+0000] {processor.py:208} INFO - Processing /opt/airflow/dags/covid_gdp_dag.py took 0.085 seconds
[2024-09-28T02:49:33.481+0000] {processor.py:186} INFO - Started process (PID=508) to work on /opt/airflow/dags/covid_gdp_dag.py
[2024-09-28T02:49:33.482+0000] {processor.py:914} INFO - Processing file /opt/airflow/dags/covid_gdp_dag.py for tasks to queue
[2024-09-28T02:49:33.484+0000] {logging_mixin.py:190} INFO - [2024-09-28T02:49:33.484+0000] {dagbag.py:588} INFO - Filling up the DagBag from /opt/airflow/dags/covid_gdp_dag.py
[2024-09-28T02:49:33.508+0000] {logging_mixin.py:190} INFO - [2024-09-28T02:49:33.502+0000] {dagbag.py:387} ERROR - Failed to import: /opt/airflow/dags/covid_gdp_dag.py
Traceback (most recent call last):
  File "/home/airflow/.local/lib/python3.12/site-packages/airflow/models/dagbag.py", line 383, in parse
    loader.exec_module(new_module)
  File "<frozen importlib._bootstrap_external>", line 995, in exec_module
  File "<frozen importlib._bootstrap>", line 488, in _call_with_frames_removed
  File "/opt/airflow/dags/covid_gdp_dag.py", line 7, in <module>
    from common_data_loader import download_world_bank_data, download_kaggle_dataset, load_covid_data, load_gdp_data
  File "/opt/airflow/dags/common_data_loader.py", line 3, in <module>
    import kaggle
ModuleNotFoundError: No module named 'kaggle'
[2024-09-28T02:49:33.510+0000] {processor.py:927} WARNING - No viable dags retrieved from /opt/airflow/dags/covid_gdp_dag.py
[2024-09-28T02:49:33.545+0000] {processor.py:208} INFO - Processing /opt/airflow/dags/covid_gdp_dag.py took 0.068 seconds
[2024-09-28T02:50:03.939+0000] {processor.py:186} INFO - Started process (PID=572) to work on /opt/airflow/dags/covid_gdp_dag.py
[2024-09-28T02:50:03.940+0000] {processor.py:914} INFO - Processing file /opt/airflow/dags/covid_gdp_dag.py for tasks to queue
[2024-09-28T02:50:03.942+0000] {logging_mixin.py:190} INFO - [2024-09-28T02:50:03.942+0000] {dagbag.py:588} INFO - Filling up the DagBag from /opt/airflow/dags/covid_gdp_dag.py
[2024-09-28T02:50:03.963+0000] {logging_mixin.py:190} INFO - [2024-09-28T02:50:03.958+0000] {dagbag.py:387} ERROR - Failed to import: /opt/airflow/dags/covid_gdp_dag.py
Traceback (most recent call last):
  File "/home/airflow/.local/lib/python3.12/site-packages/airflow/models/dagbag.py", line 383, in parse
    loader.exec_module(new_module)
  File "<frozen importlib._bootstrap_external>", line 995, in exec_module
  File "<frozen importlib._bootstrap>", line 488, in _call_with_frames_removed
  File "/opt/airflow/dags/covid_gdp_dag.py", line 7, in <module>
    from common_data_loader import download_world_bank_data, download_kaggle_dataset, load_covid_data, load_gdp_data
  File "/opt/airflow/dags/common_data_loader.py", line 3, in <module>
    import kaggle
ModuleNotFoundError: No module named 'kaggle'
[2024-09-28T02:50:03.965+0000] {processor.py:927} WARNING - No viable dags retrieved from /opt/airflow/dags/covid_gdp_dag.py
[2024-09-28T02:50:04.004+0000] {processor.py:208} INFO - Processing /opt/airflow/dags/covid_gdp_dag.py took 0.071 seconds
[2024-09-28T02:50:34.963+0000] {processor.py:186} INFO - Started process (PID=635) to work on /opt/airflow/dags/covid_gdp_dag.py
[2024-09-28T02:50:34.964+0000] {processor.py:914} INFO - Processing file /opt/airflow/dags/covid_gdp_dag.py for tasks to queue
[2024-09-28T02:50:34.966+0000] {logging_mixin.py:190} INFO - [2024-09-28T02:50:34.966+0000] {dagbag.py:588} INFO - Filling up the DagBag from /opt/airflow/dags/covid_gdp_dag.py
[2024-09-28T02:50:34.995+0000] {logging_mixin.py:190} INFO - [2024-09-28T02:50:34.988+0000] {dagbag.py:387} ERROR - Failed to import: /opt/airflow/dags/covid_gdp_dag.py
Traceback (most recent call last):
  File "/home/airflow/.local/lib/python3.12/site-packages/airflow/models/dagbag.py", line 383, in parse
    loader.exec_module(new_module)
  File "<frozen importlib._bootstrap_external>", line 995, in exec_module
  File "<frozen importlib._bootstrap>", line 488, in _call_with_frames_removed
  File "/opt/airflow/dags/covid_gdp_dag.py", line 7, in <module>
    from common_data_loader import download_world_bank_data, download_kaggle_dataset, load_covid_data, load_gdp_data
  File "/opt/airflow/dags/common_data_loader.py", line 3, in <module>
    import kaggle
ModuleNotFoundError: No module named 'kaggle'
[2024-09-28T02:50:34.997+0000] {processor.py:927} WARNING - No viable dags retrieved from /opt/airflow/dags/covid_gdp_dag.py
[2024-09-28T02:50:35.053+0000] {processor.py:208} INFO - Processing /opt/airflow/dags/covid_gdp_dag.py took 0.095 seconds
[2024-09-28T02:51:05.471+0000] {processor.py:186} INFO - Started process (PID=698) to work on /opt/airflow/dags/covid_gdp_dag.py
[2024-09-28T02:51:05.472+0000] {processor.py:914} INFO - Processing file /opt/airflow/dags/covid_gdp_dag.py for tasks to queue
[2024-09-28T02:51:05.474+0000] {logging_mixin.py:190} INFO - [2024-09-28T02:51:05.474+0000] {dagbag.py:588} INFO - Filling up the DagBag from /opt/airflow/dags/covid_gdp_dag.py
[2024-09-28T02:51:05.498+0000] {logging_mixin.py:190} INFO - [2024-09-28T02:51:05.491+0000] {dagbag.py:387} ERROR - Failed to import: /opt/airflow/dags/covid_gdp_dag.py
Traceback (most recent call last):
  File "/home/airflow/.local/lib/python3.12/site-packages/airflow/models/dagbag.py", line 383, in parse
    loader.exec_module(new_module)
  File "<frozen importlib._bootstrap_external>", line 995, in exec_module
  File "<frozen importlib._bootstrap>", line 488, in _call_with_frames_removed
  File "/opt/airflow/dags/covid_gdp_dag.py", line 7, in <module>
    from common_data_loader import download_world_bank_data, download_kaggle_dataset, load_covid_data, load_gdp_data
  File "/opt/airflow/dags/common_data_loader.py", line 3, in <module>
    import kaggle
ModuleNotFoundError: No module named 'kaggle'
[2024-09-28T02:51:05.499+0000] {processor.py:927} WARNING - No viable dags retrieved from /opt/airflow/dags/covid_gdp_dag.py
[2024-09-28T02:51:05.523+0000] {processor.py:208} INFO - Processing /opt/airflow/dags/covid_gdp_dag.py took 0.058 seconds
[2024-09-28T02:51:36.165+0000] {processor.py:186} INFO - Started process (PID=761) to work on /opt/airflow/dags/covid_gdp_dag.py
[2024-09-28T02:51:36.166+0000] {processor.py:914} INFO - Processing file /opt/airflow/dags/covid_gdp_dag.py for tasks to queue
[2024-09-28T02:51:36.168+0000] {logging_mixin.py:190} INFO - [2024-09-28T02:51:36.168+0000] {dagbag.py:588} INFO - Filling up the DagBag from /opt/airflow/dags/covid_gdp_dag.py
[2024-09-28T02:51:36.197+0000] {logging_mixin.py:190} INFO - [2024-09-28T02:51:36.187+0000] {dagbag.py:387} ERROR - Failed to import: /opt/airflow/dags/covid_gdp_dag.py
Traceback (most recent call last):
  File "/home/airflow/.local/lib/python3.12/site-packages/airflow/models/dagbag.py", line 383, in parse
    loader.exec_module(new_module)
  File "<frozen importlib._bootstrap_external>", line 995, in exec_module
  File "<frozen importlib._bootstrap>", line 488, in _call_with_frames_removed
  File "/opt/airflow/dags/covid_gdp_dag.py", line 7, in <module>
    from common_data_loader import download_world_bank_data, download_kaggle_dataset, load_covid_data, load_gdp_data
  File "/opt/airflow/dags/common_data_loader.py", line 3, in <module>
    import kaggle
ModuleNotFoundError: No module named 'kaggle'
[2024-09-28T02:51:36.199+0000] {processor.py:927} WARNING - No viable dags retrieved from /opt/airflow/dags/covid_gdp_dag.py
[2024-09-28T02:51:36.220+0000] {processor.py:208} INFO - Processing /opt/airflow/dags/covid_gdp_dag.py took 0.060 seconds
[2024-09-28T02:52:07.065+0000] {processor.py:186} INFO - Started process (PID=825) to work on /opt/airflow/dags/covid_gdp_dag.py
[2024-09-28T02:52:07.067+0000] {processor.py:914} INFO - Processing file /opt/airflow/dags/covid_gdp_dag.py for tasks to queue
[2024-09-28T02:52:07.069+0000] {logging_mixin.py:190} INFO - [2024-09-28T02:52:07.069+0000] {dagbag.py:588} INFO - Filling up the DagBag from /opt/airflow/dags/covid_gdp_dag.py
[2024-09-28T02:52:07.096+0000] {logging_mixin.py:190} INFO - [2024-09-28T02:52:07.086+0000] {dagbag.py:387} ERROR - Failed to import: /opt/airflow/dags/covid_gdp_dag.py
Traceback (most recent call last):
  File "/home/airflow/.local/lib/python3.12/site-packages/airflow/models/dagbag.py", line 383, in parse
    loader.exec_module(new_module)
  File "<frozen importlib._bootstrap_external>", line 995, in exec_module
  File "<frozen importlib._bootstrap>", line 488, in _call_with_frames_removed
  File "/opt/airflow/dags/covid_gdp_dag.py", line 7, in <module>
    from common_data_loader import download_world_bank_data, download_kaggle_dataset, load_covid_data, load_gdp_data
  File "/opt/airflow/dags/common_data_loader.py", line 3, in <module>
    import kaggle
ModuleNotFoundError: No module named 'kaggle'
[2024-09-28T02:52:07.099+0000] {processor.py:927} WARNING - No viable dags retrieved from /opt/airflow/dags/covid_gdp_dag.py
[2024-09-28T02:52:07.135+0000] {processor.py:208} INFO - Processing /opt/airflow/dags/covid_gdp_dag.py took 0.075 seconds
[2024-09-28T03:30:30.804+0000] {processor.py:186} INFO - Started process (PID=832) to work on /opt/airflow/dags/covid_gdp_dag.py
[2024-09-28T03:30:30.808+0000] {processor.py:914} INFO - Processing file /opt/airflow/dags/covid_gdp_dag.py for tasks to queue
[2024-09-28T03:30:30.828+0000] {logging_mixin.py:190} INFO - [2024-09-28T03:30:30.827+0000] {dagbag.py:588} INFO - Filling up the DagBag from /opt/airflow/dags/covid_gdp_dag.py
[2024-09-28T03:30:30.965+0000] {logging_mixin.py:190} INFO - [2024-09-28T03:30:30.936+0000] {dagbag.py:387} ERROR - Failed to import: /opt/airflow/dags/covid_gdp_dag.py
Traceback (most recent call last):
  File "/home/airflow/.local/lib/python3.12/site-packages/airflow/models/dagbag.py", line 383, in parse
    loader.exec_module(new_module)
  File "<frozen importlib._bootstrap_external>", line 995, in exec_module
  File "<frozen importlib._bootstrap>", line 488, in _call_with_frames_removed
  File "/opt/airflow/dags/covid_gdp_dag.py", line 7, in <module>
    from common_data_loader import download_world_bank_data, download_kaggle_dataset, load_covid_data, load_gdp_data
  File "/opt/airflow/dags/common_data_loader.py", line 3, in <module>
    import kaggle
ModuleNotFoundError: No module named 'kaggle'
[2024-09-28T03:30:30.970+0000] {processor.py:927} WARNING - No viable dags retrieved from /opt/airflow/dags/covid_gdp_dag.py
[2024-09-28T03:30:31.038+0000] {processor.py:208} INFO - Processing /opt/airflow/dags/covid_gdp_dag.py took 0.265 seconds
[2024-09-28T03:34:11.800+0000] {processor.py:186} INFO - Started process (PID=889) to work on /opt/airflow/dags/covid_gdp_dag.py
[2024-09-28T03:34:11.802+0000] {processor.py:914} INFO - Processing file /opt/airflow/dags/covid_gdp_dag.py for tasks to queue
[2024-09-28T03:34:11.804+0000] {logging_mixin.py:190} INFO - [2024-09-28T03:34:11.803+0000] {dagbag.py:588} INFO - Filling up the DagBag from /opt/airflow/dags/covid_gdp_dag.py
[2024-09-28T03:34:11.827+0000] {logging_mixin.py:190} INFO - [2024-09-28T03:34:11.820+0000] {dagbag.py:387} ERROR - Failed to import: /opt/airflow/dags/covid_gdp_dag.py
Traceback (most recent call last):
  File "/home/airflow/.local/lib/python3.12/site-packages/airflow/models/dagbag.py", line 383, in parse
    loader.exec_module(new_module)
  File "<frozen importlib._bootstrap_external>", line 995, in exec_module
  File "<frozen importlib._bootstrap>", line 488, in _call_with_frames_removed
  File "/opt/airflow/dags/covid_gdp_dag.py", line 7, in <module>
    from common_data_loader import download_world_bank_data, download_kaggle_dataset, load_covid_data, load_gdp_data
  File "/opt/airflow/dags/common_data_loader.py", line 3, in <module>
    import kaggle
ModuleNotFoundError: No module named 'kaggle'
[2024-09-28T03:34:11.830+0000] {processor.py:927} WARNING - No viable dags retrieved from /opt/airflow/dags/covid_gdp_dag.py
[2024-09-28T03:34:11.850+0000] {processor.py:208} INFO - Processing /opt/airflow/dags/covid_gdp_dag.py took 0.054 seconds
[2024-09-28T03:34:42.069+0000] {processor.py:186} INFO - Started process (PID=950) to work on /opt/airflow/dags/covid_gdp_dag.py
[2024-09-28T03:34:42.070+0000] {processor.py:914} INFO - Processing file /opt/airflow/dags/covid_gdp_dag.py for tasks to queue
[2024-09-28T03:34:42.071+0000] {logging_mixin.py:190} INFO - [2024-09-28T03:34:42.071+0000] {dagbag.py:588} INFO - Filling up the DagBag from /opt/airflow/dags/covid_gdp_dag.py
[2024-09-28T03:34:42.094+0000] {logging_mixin.py:190} INFO - [2024-09-28T03:34:42.086+0000] {dagbag.py:387} ERROR - Failed to import: /opt/airflow/dags/covid_gdp_dag.py
Traceback (most recent call last):
  File "/home/airflow/.local/lib/python3.12/site-packages/airflow/models/dagbag.py", line 383, in parse
    loader.exec_module(new_module)
  File "<frozen importlib._bootstrap_external>", line 995, in exec_module
  File "<frozen importlib._bootstrap>", line 488, in _call_with_frames_removed
  File "/opt/airflow/dags/covid_gdp_dag.py", line 7, in <module>
    from common_data_loader import download_world_bank_data, download_kaggle_dataset, load_covid_data, load_gdp_data
  File "/opt/airflow/dags/common_data_loader.py", line 3, in <module>
    import kaggle
ModuleNotFoundError: No module named 'kaggle'
[2024-09-28T03:34:42.096+0000] {processor.py:927} WARNING - No viable dags retrieved from /opt/airflow/dags/covid_gdp_dag.py
[2024-09-28T03:34:42.118+0000] {processor.py:208} INFO - Processing /opt/airflow/dags/covid_gdp_dag.py took 0.055 seconds
[2024-09-28T03:40:03.415+0000] {processor.py:186} INFO - Started process (PID=64) to work on /opt/airflow/dags/covid_gdp_dag.py
[2024-09-28T03:40:03.425+0000] {processor.py:914} INFO - Processing file /opt/airflow/dags/covid_gdp_dag.py for tasks to queue
[2024-09-28T03:40:03.442+0000] {logging_mixin.py:190} INFO - [2024-09-28T03:40:03.441+0000] {dagbag.py:588} INFO - Filling up the DagBag from /opt/airflow/dags/covid_gdp_dag.py
[2024-09-28T03:40:03.853+0000] {logging_mixin.py:190} INFO - [2024-09-28T03:40:03.831+0000] {dagbag.py:387} ERROR - Failed to import: /opt/airflow/dags/covid_gdp_dag.py
Traceback (most recent call last):
  File "/home/airflow/.local/lib/python3.12/site-packages/airflow/models/dagbag.py", line 383, in parse
    loader.exec_module(new_module)
  File "<frozen importlib._bootstrap_external>", line 995, in exec_module
  File "<frozen importlib._bootstrap>", line 488, in _call_with_frames_removed
  File "/opt/airflow/dags/covid_gdp_dag.py", line 7, in <module>
    from common_data_loader import download_world_bank_data, download_kaggle_dataset, load_covid_data, load_gdp_data
  File "/opt/airflow/dags/common_data_loader.py", line 3, in <module>
    import kaggle
  File "/home/airflow/.local/lib/python3.12/site-packages/kaggle/__init__.py", line 23, in <module>
    api.authenticate()
  File "/home/airflow/.local/lib/python3.12/site-packages/kaggle/api/kaggle_api_extended.py", line 181, in authenticate
    raise IOError('Could not find {}. Make sure it\'s located in'
OSError: Could not find kaggle.json. Make sure it's located in /home/airflow/.kaggle. Or use the environment method.
[2024-09-28T03:40:03.855+0000] {processor.py:927} WARNING - No viable dags retrieved from /opt/airflow/dags/covid_gdp_dag.py
[2024-09-28T03:40:03.959+0000] {processor.py:208} INFO - Processing /opt/airflow/dags/covid_gdp_dag.py took 0.583 seconds
[2024-09-28T03:40:34.650+0000] {processor.py:186} INFO - Started process (PID=138) to work on /opt/airflow/dags/covid_gdp_dag.py
[2024-09-28T03:40:34.651+0000] {processor.py:914} INFO - Processing file /opt/airflow/dags/covid_gdp_dag.py for tasks to queue
[2024-09-28T03:40:34.658+0000] {logging_mixin.py:190} INFO - [2024-09-28T03:40:34.654+0000] {dagbag.py:588} INFO - Filling up the DagBag from /opt/airflow/dags/covid_gdp_dag.py
[2024-09-28T03:40:34.823+0000] {logging_mixin.py:190} INFO - [2024-09-28T03:40:34.810+0000] {dagbag.py:387} ERROR - Failed to import: /opt/airflow/dags/covid_gdp_dag.py
Traceback (most recent call last):
  File "/home/airflow/.local/lib/python3.12/site-packages/airflow/models/dagbag.py", line 383, in parse
    loader.exec_module(new_module)
  File "<frozen importlib._bootstrap_external>", line 995, in exec_module
  File "<frozen importlib._bootstrap>", line 488, in _call_with_frames_removed
  File "/opt/airflow/dags/covid_gdp_dag.py", line 7, in <module>
    from common_data_loader import download_world_bank_data, download_kaggle_dataset, load_covid_data, load_gdp_data
  File "/opt/airflow/dags/common_data_loader.py", line 3, in <module>
    import kaggle
  File "/home/airflow/.local/lib/python3.12/site-packages/kaggle/__init__.py", line 23, in <module>
    api.authenticate()
  File "/home/airflow/.local/lib/python3.12/site-packages/kaggle/api/kaggle_api_extended.py", line 181, in authenticate
    raise IOError('Could not find {}. Make sure it\'s located in'
OSError: Could not find kaggle.json. Make sure it's located in /home/airflow/.kaggle. Or use the environment method.
[2024-09-28T03:40:34.824+0000] {processor.py:927} WARNING - No viable dags retrieved from /opt/airflow/dags/covid_gdp_dag.py
[2024-09-28T03:40:34.849+0000] {processor.py:208} INFO - Processing /opt/airflow/dags/covid_gdp_dag.py took 0.204 seconds
[2024-09-28T03:41:04.928+0000] {processor.py:186} INFO - Started process (PID=213) to work on /opt/airflow/dags/covid_gdp_dag.py
[2024-09-28T03:41:04.929+0000] {processor.py:914} INFO - Processing file /opt/airflow/dags/covid_gdp_dag.py for tasks to queue
[2024-09-28T03:41:04.931+0000] {logging_mixin.py:190} INFO - [2024-09-28T03:41:04.931+0000] {dagbag.py:588} INFO - Filling up the DagBag from /opt/airflow/dags/covid_gdp_dag.py
[2024-09-28T03:41:05.055+0000] {logging_mixin.py:190} INFO - [2024-09-28T03:41:05.044+0000] {dagbag.py:387} ERROR - Failed to import: /opt/airflow/dags/covid_gdp_dag.py
Traceback (most recent call last):
  File "/home/airflow/.local/lib/python3.12/site-packages/airflow/models/dagbag.py", line 383, in parse
    loader.exec_module(new_module)
  File "<frozen importlib._bootstrap_external>", line 995, in exec_module
  File "<frozen importlib._bootstrap>", line 488, in _call_with_frames_removed
  File "/opt/airflow/dags/covid_gdp_dag.py", line 7, in <module>
    from common_data_loader import download_world_bank_data, download_kaggle_dataset, load_covid_data, load_gdp_data
  File "/opt/airflow/dags/common_data_loader.py", line 3, in <module>
    import kaggle
  File "/home/airflow/.local/lib/python3.12/site-packages/kaggle/__init__.py", line 23, in <module>
    api.authenticate()
  File "/home/airflow/.local/lib/python3.12/site-packages/kaggle/api/kaggle_api_extended.py", line 181, in authenticate
    raise IOError('Could not find {}. Make sure it\'s located in'
OSError: Could not find kaggle.json. Make sure it's located in /home/airflow/.kaggle. Or use the environment method.
[2024-09-28T03:41:05.056+0000] {processor.py:927} WARNING - No viable dags retrieved from /opt/airflow/dags/covid_gdp_dag.py
[2024-09-28T03:41:05.077+0000] {processor.py:208} INFO - Processing /opt/airflow/dags/covid_gdp_dag.py took 0.154 seconds
[2024-09-28T03:41:35.957+0000] {processor.py:186} INFO - Started process (PID=286) to work on /opt/airflow/dags/covid_gdp_dag.py
[2024-09-28T03:41:35.959+0000] {processor.py:914} INFO - Processing file /opt/airflow/dags/covid_gdp_dag.py for tasks to queue
[2024-09-28T03:41:35.964+0000] {logging_mixin.py:190} INFO - [2024-09-28T03:41:35.963+0000] {dagbag.py:588} INFO - Filling up the DagBag from /opt/airflow/dags/covid_gdp_dag.py
[2024-09-28T03:41:36.112+0000] {logging_mixin.py:190} INFO - [2024-09-28T03:41:36.101+0000] {dagbag.py:387} ERROR - Failed to import: /opt/airflow/dags/covid_gdp_dag.py
Traceback (most recent call last):
  File "/home/airflow/.local/lib/python3.12/site-packages/airflow/models/dagbag.py", line 383, in parse
    loader.exec_module(new_module)
  File "<frozen importlib._bootstrap_external>", line 995, in exec_module
  File "<frozen importlib._bootstrap>", line 488, in _call_with_frames_removed
  File "/opt/airflow/dags/covid_gdp_dag.py", line 7, in <module>
    from common_data_loader import download_world_bank_data, download_kaggle_dataset, load_covid_data, load_gdp_data
  File "/opt/airflow/dags/common_data_loader.py", line 3, in <module>
    import kaggle
  File "/home/airflow/.local/lib/python3.12/site-packages/kaggle/__init__.py", line 23, in <module>
    api.authenticate()
  File "/home/airflow/.local/lib/python3.12/site-packages/kaggle/api/kaggle_api_extended.py", line 181, in authenticate
    raise IOError('Could not find {}. Make sure it\'s located in'
OSError: Could not find kaggle.json. Make sure it's located in /home/airflow/.kaggle. Or use the environment method.
[2024-09-28T03:41:36.113+0000] {processor.py:927} WARNING - No viable dags retrieved from /opt/airflow/dags/covid_gdp_dag.py
[2024-09-28T03:41:36.149+0000] {processor.py:208} INFO - Processing /opt/airflow/dags/covid_gdp_dag.py took 0.202 seconds
[2024-09-28T03:42:06.384+0000] {processor.py:186} INFO - Started process (PID=360) to work on /opt/airflow/dags/covid_gdp_dag.py
[2024-09-28T03:42:06.385+0000] {processor.py:914} INFO - Processing file /opt/airflow/dags/covid_gdp_dag.py for tasks to queue
[2024-09-28T03:42:06.387+0000] {logging_mixin.py:190} INFO - [2024-09-28T03:42:06.387+0000] {dagbag.py:588} INFO - Filling up the DagBag from /opt/airflow/dags/covid_gdp_dag.py
[2024-09-28T03:42:06.504+0000] {logging_mixin.py:190} INFO - [2024-09-28T03:42:06.495+0000] {dagbag.py:387} ERROR - Failed to import: /opt/airflow/dags/covid_gdp_dag.py
Traceback (most recent call last):
  File "/home/airflow/.local/lib/python3.12/site-packages/airflow/models/dagbag.py", line 383, in parse
    loader.exec_module(new_module)
  File "<frozen importlib._bootstrap_external>", line 995, in exec_module
  File "<frozen importlib._bootstrap>", line 488, in _call_with_frames_removed
  File "/opt/airflow/dags/covid_gdp_dag.py", line 7, in <module>
    from common_data_loader import download_world_bank_data, download_kaggle_dataset, load_covid_data, load_gdp_data
  File "/opt/airflow/dags/common_data_loader.py", line 3, in <module>
    import kaggle
  File "/home/airflow/.local/lib/python3.12/site-packages/kaggle/__init__.py", line 23, in <module>
    api.authenticate()
  File "/home/airflow/.local/lib/python3.12/site-packages/kaggle/api/kaggle_api_extended.py", line 181, in authenticate
    raise IOError('Could not find {}. Make sure it\'s located in'
OSError: Could not find kaggle.json. Make sure it's located in /home/airflow/.kaggle. Or use the environment method.
[2024-09-28T03:42:06.505+0000] {processor.py:927} WARNING - No viable dags retrieved from /opt/airflow/dags/covid_gdp_dag.py
[2024-09-28T03:42:06.525+0000] {processor.py:208} INFO - Processing /opt/airflow/dags/covid_gdp_dag.py took 0.146 seconds
[2024-09-28T03:42:36.865+0000] {processor.py:186} INFO - Started process (PID=434) to work on /opt/airflow/dags/covid_gdp_dag.py
[2024-09-28T03:42:36.866+0000] {processor.py:914} INFO - Processing file /opt/airflow/dags/covid_gdp_dag.py for tasks to queue
[2024-09-28T03:42:36.869+0000] {logging_mixin.py:190} INFO - [2024-09-28T03:42:36.868+0000] {dagbag.py:588} INFO - Filling up the DagBag from /opt/airflow/dags/covid_gdp_dag.py
[2024-09-28T03:42:36.961+0000] {logging_mixin.py:190} INFO - [2024-09-28T03:42:36.951+0000] {dagbag.py:387} ERROR - Failed to import: /opt/airflow/dags/covid_gdp_dag.py
Traceback (most recent call last):
  File "/home/airflow/.local/lib/python3.12/site-packages/airflow/models/dagbag.py", line 383, in parse
    loader.exec_module(new_module)
  File "<frozen importlib._bootstrap_external>", line 995, in exec_module
  File "<frozen importlib._bootstrap>", line 488, in _call_with_frames_removed
  File "/opt/airflow/dags/covid_gdp_dag.py", line 7, in <module>
    from common_data_loader import download_world_bank_data, download_kaggle_dataset, load_covid_data, load_gdp_data
  File "/opt/airflow/dags/common_data_loader.py", line 3, in <module>
    import kaggle
  File "/home/airflow/.local/lib/python3.12/site-packages/kaggle/__init__.py", line 23, in <module>
    api.authenticate()
  File "/home/airflow/.local/lib/python3.12/site-packages/kaggle/api/kaggle_api_extended.py", line 181, in authenticate
    raise IOError('Could not find {}. Make sure it\'s located in'
OSError: Could not find kaggle.json. Make sure it's located in /home/airflow/.kaggle. Or use the environment method.
[2024-09-28T03:42:36.962+0000] {processor.py:927} WARNING - No viable dags retrieved from /opt/airflow/dags/covid_gdp_dag.py
[2024-09-28T03:42:36.987+0000] {processor.py:208} INFO - Processing /opt/airflow/dags/covid_gdp_dag.py took 0.128 seconds
[2024-09-28T03:43:07.513+0000] {processor.py:186} INFO - Started process (PID=508) to work on /opt/airflow/dags/covid_gdp_dag.py
[2024-09-28T03:43:07.515+0000] {processor.py:914} INFO - Processing file /opt/airflow/dags/covid_gdp_dag.py for tasks to queue
[2024-09-28T03:43:07.518+0000] {logging_mixin.py:190} INFO - [2024-09-28T03:43:07.517+0000] {dagbag.py:588} INFO - Filling up the DagBag from /opt/airflow/dags/covid_gdp_dag.py
[2024-09-28T03:43:07.606+0000] {logging_mixin.py:190} INFO - [2024-09-28T03:43:07.598+0000] {dagbag.py:387} ERROR - Failed to import: /opt/airflow/dags/covid_gdp_dag.py
Traceback (most recent call last):
  File "/home/airflow/.local/lib/python3.12/site-packages/airflow/models/dagbag.py", line 383, in parse
    loader.exec_module(new_module)
  File "<frozen importlib._bootstrap_external>", line 995, in exec_module
  File "<frozen importlib._bootstrap>", line 488, in _call_with_frames_removed
  File "/opt/airflow/dags/covid_gdp_dag.py", line 7, in <module>
    from common_data_loader import download_world_bank_data, download_kaggle_dataset, load_covid_data, load_gdp_data
  File "/opt/airflow/dags/common_data_loader.py", line 3, in <module>
    import kaggle
  File "/home/airflow/.local/lib/python3.12/site-packages/kaggle/__init__.py", line 23, in <module>
    api.authenticate()
  File "/home/airflow/.local/lib/python3.12/site-packages/kaggle/api/kaggle_api_extended.py", line 181, in authenticate
    raise IOError('Could not find {}. Make sure it\'s located in'
OSError: Could not find kaggle.json. Make sure it's located in /home/airflow/.kaggle. Or use the environment method.
[2024-09-28T03:43:07.607+0000] {processor.py:927} WARNING - No viable dags retrieved from /opt/airflow/dags/covid_gdp_dag.py
[2024-09-28T03:43:07.630+0000] {processor.py:208} INFO - Processing /opt/airflow/dags/covid_gdp_dag.py took 0.122 seconds
[2024-09-28T03:43:37.974+0000] {processor.py:186} INFO - Started process (PID=582) to work on /opt/airflow/dags/covid_gdp_dag.py
[2024-09-28T03:43:37.975+0000] {processor.py:914} INFO - Processing file /opt/airflow/dags/covid_gdp_dag.py for tasks to queue
[2024-09-28T03:43:37.978+0000] {logging_mixin.py:190} INFO - [2024-09-28T03:43:37.978+0000] {dagbag.py:588} INFO - Filling up the DagBag from /opt/airflow/dags/covid_gdp_dag.py
[2024-09-28T03:43:38.069+0000] {logging_mixin.py:190} INFO - [2024-09-28T03:43:38.061+0000] {dagbag.py:387} ERROR - Failed to import: /opt/airflow/dags/covid_gdp_dag.py
Traceback (most recent call last):
  File "/home/airflow/.local/lib/python3.12/site-packages/airflow/models/dagbag.py", line 383, in parse
    loader.exec_module(new_module)
  File "<frozen importlib._bootstrap_external>", line 995, in exec_module
  File "<frozen importlib._bootstrap>", line 488, in _call_with_frames_removed
  File "/opt/airflow/dags/covid_gdp_dag.py", line 7, in <module>
    from common_data_loader import download_world_bank_data, download_kaggle_dataset, load_covid_data, load_gdp_data
  File "/opt/airflow/dags/common_data_loader.py", line 3, in <module>
    import kaggle
  File "/home/airflow/.local/lib/python3.12/site-packages/kaggle/__init__.py", line 23, in <module>
    api.authenticate()
  File "/home/airflow/.local/lib/python3.12/site-packages/kaggle/api/kaggle_api_extended.py", line 181, in authenticate
    raise IOError('Could not find {}. Make sure it\'s located in'
OSError: Could not find kaggle.json. Make sure it's located in /home/airflow/.kaggle. Or use the environment method.
[2024-09-28T03:43:38.070+0000] {processor.py:927} WARNING - No viable dags retrieved from /opt/airflow/dags/covid_gdp_dag.py
[2024-09-28T03:43:38.097+0000] {processor.py:208} INFO - Processing /opt/airflow/dags/covid_gdp_dag.py took 0.128 seconds
[2024-09-28T03:44:08.554+0000] {processor.py:186} INFO - Started process (PID=662) to work on /opt/airflow/dags/covid_gdp_dag.py
[2024-09-28T03:44:08.556+0000] {processor.py:914} INFO - Processing file /opt/airflow/dags/covid_gdp_dag.py for tasks to queue
[2024-09-28T03:44:08.562+0000] {logging_mixin.py:190} INFO - [2024-09-28T03:44:08.561+0000] {dagbag.py:588} INFO - Filling up the DagBag from /opt/airflow/dags/covid_gdp_dag.py
[2024-09-28T03:44:08.656+0000] {logging_mixin.py:190} INFO - [2024-09-28T03:44:08.644+0000] {dagbag.py:387} ERROR - Failed to import: /opt/airflow/dags/covid_gdp_dag.py
Traceback (most recent call last):
  File "/home/airflow/.local/lib/python3.12/site-packages/airflow/models/dagbag.py", line 383, in parse
    loader.exec_module(new_module)
  File "<frozen importlib._bootstrap_external>", line 995, in exec_module
  File "<frozen importlib._bootstrap>", line 488, in _call_with_frames_removed
  File "/opt/airflow/dags/covid_gdp_dag.py", line 7, in <module>
    from common_data_loader import download_world_bank_data, download_kaggle_dataset, load_covid_data, load_gdp_data
  File "/opt/airflow/dags/common_data_loader.py", line 3, in <module>
    import kaggle
  File "/home/airflow/.local/lib/python3.12/site-packages/kaggle/__init__.py", line 23, in <module>
    api.authenticate()
  File "/home/airflow/.local/lib/python3.12/site-packages/kaggle/api/kaggle_api_extended.py", line 181, in authenticate
    raise IOError('Could not find {}. Make sure it\'s located in'
OSError: Could not find kaggle.json. Make sure it's located in /home/airflow/.kaggle. Or use the environment method.
[2024-09-28T03:44:08.658+0000] {processor.py:927} WARNING - No viable dags retrieved from /opt/airflow/dags/covid_gdp_dag.py
[2024-09-28T03:44:08.679+0000] {processor.py:208} INFO - Processing /opt/airflow/dags/covid_gdp_dag.py took 0.130 seconds
[2024-09-28T03:44:38.849+0000] {processor.py:186} INFO - Started process (PID=736) to work on /opt/airflow/dags/covid_gdp_dag.py
[2024-09-28T03:44:38.850+0000] {processor.py:914} INFO - Processing file /opt/airflow/dags/covid_gdp_dag.py for tasks to queue
[2024-09-28T03:44:38.852+0000] {logging_mixin.py:190} INFO - [2024-09-28T03:44:38.852+0000] {dagbag.py:588} INFO - Filling up the DagBag from /opt/airflow/dags/covid_gdp_dag.py
[2024-09-28T03:44:38.936+0000] {logging_mixin.py:190} INFO - [2024-09-28T03:44:38.927+0000] {dagbag.py:387} ERROR - Failed to import: /opt/airflow/dags/covid_gdp_dag.py
Traceback (most recent call last):
  File "/home/airflow/.local/lib/python3.12/site-packages/airflow/models/dagbag.py", line 383, in parse
    loader.exec_module(new_module)
  File "<frozen importlib._bootstrap_external>", line 995, in exec_module
  File "<frozen importlib._bootstrap>", line 488, in _call_with_frames_removed
  File "/opt/airflow/dags/covid_gdp_dag.py", line 7, in <module>
    from common_data_loader import download_world_bank_data, download_kaggle_dataset, load_covid_data, load_gdp_data
  File "/opt/airflow/dags/common_data_loader.py", line 3, in <module>
    import kaggle
  File "/home/airflow/.local/lib/python3.12/site-packages/kaggle/__init__.py", line 23, in <module>
    api.authenticate()
  File "/home/airflow/.local/lib/python3.12/site-packages/kaggle/api/kaggle_api_extended.py", line 181, in authenticate
    raise IOError('Could not find {}. Make sure it\'s located in'
OSError: Could not find kaggle.json. Make sure it's located in /home/airflow/.kaggle. Or use the environment method.
[2024-09-28T03:44:38.937+0000] {processor.py:927} WARNING - No viable dags retrieved from /opt/airflow/dags/covid_gdp_dag.py
[2024-09-28T03:44:38.958+0000] {processor.py:208} INFO - Processing /opt/airflow/dags/covid_gdp_dag.py took 0.114 seconds
[2024-09-28T03:45:09.031+0000] {processor.py:186} INFO - Started process (PID=810) to work on /opt/airflow/dags/covid_gdp_dag.py
[2024-09-28T03:45:09.032+0000] {processor.py:914} INFO - Processing file /opt/airflow/dags/covid_gdp_dag.py for tasks to queue
[2024-09-28T03:45:09.036+0000] {logging_mixin.py:190} INFO - [2024-09-28T03:45:09.035+0000] {dagbag.py:588} INFO - Filling up the DagBag from /opt/airflow/dags/covid_gdp_dag.py
[2024-09-28T03:45:09.118+0000] {logging_mixin.py:190} INFO - [2024-09-28T03:45:09.109+0000] {dagbag.py:387} ERROR - Failed to import: /opt/airflow/dags/covid_gdp_dag.py
Traceback (most recent call last):
  File "/home/airflow/.local/lib/python3.12/site-packages/airflow/models/dagbag.py", line 383, in parse
    loader.exec_module(new_module)
  File "<frozen importlib._bootstrap_external>", line 995, in exec_module
  File "<frozen importlib._bootstrap>", line 488, in _call_with_frames_removed
  File "/opt/airflow/dags/covid_gdp_dag.py", line 7, in <module>
    from common_data_loader import download_world_bank_data, download_kaggle_dataset, load_covid_data, load_gdp_data
  File "/opt/airflow/dags/common_data_loader.py", line 3, in <module>
    import kaggle
  File "/home/airflow/.local/lib/python3.12/site-packages/kaggle/__init__.py", line 23, in <module>
    api.authenticate()
  File "/home/airflow/.local/lib/python3.12/site-packages/kaggle/api/kaggle_api_extended.py", line 181, in authenticate
    raise IOError('Could not find {}. Make sure it\'s located in'
OSError: Could not find kaggle.json. Make sure it's located in /home/airflow/.kaggle. Or use the environment method.
[2024-09-28T03:45:09.119+0000] {processor.py:927} WARNING - No viable dags retrieved from /opt/airflow/dags/covid_gdp_dag.py
[2024-09-28T03:45:09.142+0000] {processor.py:208} INFO - Processing /opt/airflow/dags/covid_gdp_dag.py took 0.115 seconds
[2024-09-28T03:45:39.332+0000] {processor.py:186} INFO - Started process (PID=885) to work on /opt/airflow/dags/covid_gdp_dag.py
[2024-09-28T03:45:39.333+0000] {processor.py:914} INFO - Processing file /opt/airflow/dags/covid_gdp_dag.py for tasks to queue
[2024-09-28T03:45:39.335+0000] {logging_mixin.py:190} INFO - [2024-09-28T03:45:39.334+0000] {dagbag.py:588} INFO - Filling up the DagBag from /opt/airflow/dags/covid_gdp_dag.py
[2024-09-28T03:45:39.417+0000] {logging_mixin.py:190} INFO - [2024-09-28T03:45:39.408+0000] {dagbag.py:387} ERROR - Failed to import: /opt/airflow/dags/covid_gdp_dag.py
Traceback (most recent call last):
  File "/home/airflow/.local/lib/python3.12/site-packages/airflow/models/dagbag.py", line 383, in parse
    loader.exec_module(new_module)
  File "<frozen importlib._bootstrap_external>", line 995, in exec_module
  File "<frozen importlib._bootstrap>", line 488, in _call_with_frames_removed
  File "/opt/airflow/dags/covid_gdp_dag.py", line 7, in <module>
    from common_data_loader import download_world_bank_data, download_kaggle_dataset, load_covid_data, load_gdp_data
  File "/opt/airflow/dags/common_data_loader.py", line 3, in <module>
    import kaggle
  File "/home/airflow/.local/lib/python3.12/site-packages/kaggle/__init__.py", line 23, in <module>
    api.authenticate()
  File "/home/airflow/.local/lib/python3.12/site-packages/kaggle/api/kaggle_api_extended.py", line 181, in authenticate
    raise IOError('Could not find {}. Make sure it\'s located in'
OSError: Could not find kaggle.json. Make sure it's located in /home/airflow/.kaggle. Or use the environment method.
[2024-09-28T03:45:39.418+0000] {processor.py:927} WARNING - No viable dags retrieved from /opt/airflow/dags/covid_gdp_dag.py
[2024-09-28T03:45:39.465+0000] {processor.py:208} INFO - Processing /opt/airflow/dags/covid_gdp_dag.py took 0.138 seconds
[2024-09-28T03:46:09.946+0000] {processor.py:186} INFO - Started process (PID=959) to work on /opt/airflow/dags/covid_gdp_dag.py
[2024-09-28T03:46:09.947+0000] {processor.py:914} INFO - Processing file /opt/airflow/dags/covid_gdp_dag.py for tasks to queue
[2024-09-28T03:46:09.950+0000] {logging_mixin.py:190} INFO - [2024-09-28T03:46:09.950+0000] {dagbag.py:588} INFO - Filling up the DagBag from /opt/airflow/dags/covid_gdp_dag.py
[2024-09-28T03:46:10.220+0000] {logging_mixin.py:190} INFO - [2024-09-28T03:46:10.211+0000] {dagbag.py:387} ERROR - Failed to import: /opt/airflow/dags/covid_gdp_dag.py
Traceback (most recent call last):
  File "/home/airflow/.local/lib/python3.12/site-packages/airflow/models/dagbag.py", line 383, in parse
    loader.exec_module(new_module)
  File "<frozen importlib._bootstrap_external>", line 995, in exec_module
  File "<frozen importlib._bootstrap>", line 488, in _call_with_frames_removed
  File "/opt/airflow/dags/covid_gdp_dag.py", line 7, in <module>
    from common_data_loader import download_world_bank_data, download_kaggle_dataset, load_covid_data, load_gdp_data
  File "/opt/airflow/dags/common_data_loader.py", line 3, in <module>
    import kaggle
  File "/home/airflow/.local/lib/python3.12/site-packages/kaggle/__init__.py", line 23, in <module>
    api.authenticate()
  File "/home/airflow/.local/lib/python3.12/site-packages/kaggle/api/kaggle_api_extended.py", line 181, in authenticate
    raise IOError('Could not find {}. Make sure it\'s located in'
OSError: Could not find kaggle.json. Make sure it's located in /home/airflow/.kaggle. Or use the environment method.
[2024-09-28T03:46:10.221+0000] {processor.py:927} WARNING - No viable dags retrieved from /opt/airflow/dags/covid_gdp_dag.py
[2024-09-28T03:46:10.261+0000] {processor.py:208} INFO - Processing /opt/airflow/dags/covid_gdp_dag.py took 0.321 seconds
[2024-09-28T03:46:40.322+0000] {processor.py:186} INFO - Started process (PID=1033) to work on /opt/airflow/dags/covid_gdp_dag.py
[2024-09-28T03:46:40.323+0000] {processor.py:914} INFO - Processing file /opt/airflow/dags/covid_gdp_dag.py for tasks to queue
[2024-09-28T03:46:40.326+0000] {logging_mixin.py:190} INFO - [2024-09-28T03:46:40.326+0000] {dagbag.py:588} INFO - Filling up the DagBag from /opt/airflow/dags/covid_gdp_dag.py
[2024-09-28T03:46:40.450+0000] {logging_mixin.py:190} INFO - [2024-09-28T03:46:40.438+0000] {dagbag.py:387} ERROR - Failed to import: /opt/airflow/dags/covid_gdp_dag.py
Traceback (most recent call last):
  File "/home/airflow/.local/lib/python3.12/site-packages/airflow/models/dagbag.py", line 383, in parse
    loader.exec_module(new_module)
  File "<frozen importlib._bootstrap_external>", line 995, in exec_module
  File "<frozen importlib._bootstrap>", line 488, in _call_with_frames_removed
  File "/opt/airflow/dags/covid_gdp_dag.py", line 7, in <module>
    from common_data_loader import download_world_bank_data, download_kaggle_dataset, load_covid_data, load_gdp_data
  File "/opt/airflow/dags/common_data_loader.py", line 3, in <module>
    import kaggle
  File "/home/airflow/.local/lib/python3.12/site-packages/kaggle/__init__.py", line 23, in <module>
    api.authenticate()
  File "/home/airflow/.local/lib/python3.12/site-packages/kaggle/api/kaggle_api_extended.py", line 181, in authenticate
    raise IOError('Could not find {}. Make sure it\'s located in'
OSError: Could not find kaggle.json. Make sure it's located in /home/airflow/.kaggle. Or use the environment method.
[2024-09-28T03:46:40.451+0000] {processor.py:927} WARNING - No viable dags retrieved from /opt/airflow/dags/covid_gdp_dag.py
[2024-09-28T03:46:40.480+0000] {processor.py:208} INFO - Processing /opt/airflow/dags/covid_gdp_dag.py took 0.164 seconds
[2024-09-28T03:47:10.597+0000] {processor.py:186} INFO - Started process (PID=1107) to work on /opt/airflow/dags/covid_gdp_dag.py
[2024-09-28T03:47:10.599+0000] {processor.py:914} INFO - Processing file /opt/airflow/dags/covid_gdp_dag.py for tasks to queue
[2024-09-28T03:47:10.603+0000] {logging_mixin.py:190} INFO - [2024-09-28T03:47:10.602+0000] {dagbag.py:588} INFO - Filling up the DagBag from /opt/airflow/dags/covid_gdp_dag.py
[2024-09-28T03:47:10.744+0000] {logging_mixin.py:190} INFO - [2024-09-28T03:47:10.733+0000] {dagbag.py:387} ERROR - Failed to import: /opt/airflow/dags/covid_gdp_dag.py
Traceback (most recent call last):
  File "/home/airflow/.local/lib/python3.12/site-packages/airflow/models/dagbag.py", line 383, in parse
    loader.exec_module(new_module)
  File "<frozen importlib._bootstrap_external>", line 995, in exec_module
  File "<frozen importlib._bootstrap>", line 488, in _call_with_frames_removed
  File "/opt/airflow/dags/covid_gdp_dag.py", line 7, in <module>
    from common_data_loader import download_world_bank_data, download_kaggle_dataset, load_covid_data, load_gdp_data
  File "/opt/airflow/dags/common_data_loader.py", line 3, in <module>
    import kaggle
  File "/home/airflow/.local/lib/python3.12/site-packages/kaggle/__init__.py", line 23, in <module>
    api.authenticate()
  File "/home/airflow/.local/lib/python3.12/site-packages/kaggle/api/kaggle_api_extended.py", line 181, in authenticate
    raise IOError('Could not find {}. Make sure it\'s located in'
OSError: Could not find kaggle.json. Make sure it's located in /home/airflow/.kaggle. Or use the environment method.
[2024-09-28T03:47:10.746+0000] {processor.py:927} WARNING - No viable dags retrieved from /opt/airflow/dags/covid_gdp_dag.py
[2024-09-28T03:47:10.778+0000] {processor.py:208} INFO - Processing /opt/airflow/dags/covid_gdp_dag.py took 0.192 seconds
[2024-09-28T03:47:40.892+0000] {processor.py:186} INFO - Started process (PID=1181) to work on /opt/airflow/dags/covid_gdp_dag.py
[2024-09-28T03:47:40.894+0000] {processor.py:914} INFO - Processing file /opt/airflow/dags/covid_gdp_dag.py for tasks to queue
[2024-09-28T03:47:40.897+0000] {logging_mixin.py:190} INFO - [2024-09-28T03:47:40.897+0000] {dagbag.py:588} INFO - Filling up the DagBag from /opt/airflow/dags/covid_gdp_dag.py
[2024-09-28T03:47:41.401+0000] {logging_mixin.py:190} INFO - [2024-09-28T03:47:41.384+0000] {dagbag.py:387} ERROR - Failed to import: /opt/airflow/dags/covid_gdp_dag.py
Traceback (most recent call last):
  File "/home/airflow/.local/lib/python3.12/site-packages/airflow/models/dagbag.py", line 383, in parse
    loader.exec_module(new_module)
  File "<frozen importlib._bootstrap_external>", line 995, in exec_module
  File "<frozen importlib._bootstrap>", line 488, in _call_with_frames_removed
  File "/opt/airflow/dags/covid_gdp_dag.py", line 7, in <module>
    from common_data_loader import download_world_bank_data, download_kaggle_dataset, load_covid_data, load_gdp_data
  File "/opt/airflow/dags/common_data_loader.py", line 3, in <module>
    import kaggle
  File "/home/airflow/.local/lib/python3.12/site-packages/kaggle/__init__.py", line 23, in <module>
    api.authenticate()
  File "/home/airflow/.local/lib/python3.12/site-packages/kaggle/api/kaggle_api_extended.py", line 181, in authenticate
    raise IOError('Could not find {}. Make sure it\'s located in'
OSError: Could not find kaggle.json. Make sure it's located in /home/airflow/.kaggle. Or use the environment method.
[2024-09-28T03:47:41.403+0000] {processor.py:927} WARNING - No viable dags retrieved from /opt/airflow/dags/covid_gdp_dag.py
[2024-09-28T03:47:41.915+0000] {processor.py:208} INFO - Processing /opt/airflow/dags/covid_gdp_dag.py took 1.029 seconds
[2024-09-28T03:48:12.737+0000] {processor.py:186} INFO - Started process (PID=1256) to work on /opt/airflow/dags/covid_gdp_dag.py
[2024-09-28T03:48:12.739+0000] {processor.py:914} INFO - Processing file /opt/airflow/dags/covid_gdp_dag.py for tasks to queue
[2024-09-28T03:48:12.742+0000] {logging_mixin.py:190} INFO - [2024-09-28T03:48:12.742+0000] {dagbag.py:588} INFO - Filling up the DagBag from /opt/airflow/dags/covid_gdp_dag.py
[2024-09-28T03:48:12.880+0000] {logging_mixin.py:190} INFO - [2024-09-28T03:48:12.867+0000] {dagbag.py:387} ERROR - Failed to import: /opt/airflow/dags/covid_gdp_dag.py
Traceback (most recent call last):
  File "/home/airflow/.local/lib/python3.12/site-packages/airflow/models/dagbag.py", line 383, in parse
    loader.exec_module(new_module)
  File "<frozen importlib._bootstrap_external>", line 995, in exec_module
  File "<frozen importlib._bootstrap>", line 488, in _call_with_frames_removed
  File "/opt/airflow/dags/covid_gdp_dag.py", line 7, in <module>
    from common_data_loader import download_world_bank_data, download_kaggle_dataset, load_covid_data, load_gdp_data
  File "/opt/airflow/dags/common_data_loader.py", line 3, in <module>
    import kaggle
  File "/home/airflow/.local/lib/python3.12/site-packages/kaggle/__init__.py", line 23, in <module>
    api.authenticate()
  File "/home/airflow/.local/lib/python3.12/site-packages/kaggle/api/kaggle_api_extended.py", line 181, in authenticate
    raise IOError('Could not find {}. Make sure it\'s located in'
OSError: Could not find kaggle.json. Make sure it's located in /home/airflow/.kaggle. Or use the environment method.
[2024-09-28T03:48:12.882+0000] {processor.py:927} WARNING - No viable dags retrieved from /opt/airflow/dags/covid_gdp_dag.py
[2024-09-28T03:48:12.912+0000] {processor.py:208} INFO - Processing /opt/airflow/dags/covid_gdp_dag.py took 0.182 seconds
[2024-09-28T03:48:43.579+0000] {processor.py:186} INFO - Started process (PID=1330) to work on /opt/airflow/dags/covid_gdp_dag.py
[2024-09-28T03:48:43.580+0000] {processor.py:914} INFO - Processing file /opt/airflow/dags/covid_gdp_dag.py for tasks to queue
[2024-09-28T03:48:43.583+0000] {logging_mixin.py:190} INFO - [2024-09-28T03:48:43.583+0000] {dagbag.py:588} INFO - Filling up the DagBag from /opt/airflow/dags/covid_gdp_dag.py
[2024-09-28T03:48:43.677+0000] {logging_mixin.py:190} INFO - [2024-09-28T03:48:43.666+0000] {dagbag.py:387} ERROR - Failed to import: /opt/airflow/dags/covid_gdp_dag.py
Traceback (most recent call last):
  File "/home/airflow/.local/lib/python3.12/site-packages/airflow/models/dagbag.py", line 383, in parse
    loader.exec_module(new_module)
  File "<frozen importlib._bootstrap_external>", line 995, in exec_module
  File "<frozen importlib._bootstrap>", line 488, in _call_with_frames_removed
  File "/opt/airflow/dags/covid_gdp_dag.py", line 7, in <module>
    from common_data_loader import download_world_bank_data, download_kaggle_dataset, load_covid_data, load_gdp_data
  File "/opt/airflow/dags/common_data_loader.py", line 3, in <module>
    import kaggle
  File "/home/airflow/.local/lib/python3.12/site-packages/kaggle/__init__.py", line 23, in <module>
    api.authenticate()
  File "/home/airflow/.local/lib/python3.12/site-packages/kaggle/api/kaggle_api_extended.py", line 181, in authenticate
    raise IOError('Could not find {}. Make sure it\'s located in'
OSError: Could not find kaggle.json. Make sure it's located in /home/airflow/.kaggle. Or use the environment method.
[2024-09-28T03:48:43.678+0000] {processor.py:927} WARNING - No viable dags retrieved from /opt/airflow/dags/covid_gdp_dag.py
[2024-09-28T03:48:43.707+0000] {processor.py:208} INFO - Processing /opt/airflow/dags/covid_gdp_dag.py took 0.133 seconds
[2024-09-28T03:49:14.028+0000] {processor.py:186} INFO - Started process (PID=1404) to work on /opt/airflow/dags/covid_gdp_dag.py
[2024-09-28T03:49:14.029+0000] {processor.py:914} INFO - Processing file /opt/airflow/dags/covid_gdp_dag.py for tasks to queue
[2024-09-28T03:49:14.033+0000] {logging_mixin.py:190} INFO - [2024-09-28T03:49:14.032+0000] {dagbag.py:588} INFO - Filling up the DagBag from /opt/airflow/dags/covid_gdp_dag.py
[2024-09-28T03:49:14.191+0000] {logging_mixin.py:190} INFO - [2024-09-28T03:49:14.174+0000] {dagbag.py:387} ERROR - Failed to import: /opt/airflow/dags/covid_gdp_dag.py
Traceback (most recent call last):
  File "/home/airflow/.local/lib/python3.12/site-packages/airflow/models/dagbag.py", line 383, in parse
    loader.exec_module(new_module)
  File "<frozen importlib._bootstrap_external>", line 995, in exec_module
  File "<frozen importlib._bootstrap>", line 488, in _call_with_frames_removed
  File "/opt/airflow/dags/covid_gdp_dag.py", line 7, in <module>
    from common_data_loader import download_world_bank_data, download_kaggle_dataset, load_covid_data, load_gdp_data
  File "/opt/airflow/dags/common_data_loader.py", line 3, in <module>
    import kaggle
  File "/home/airflow/.local/lib/python3.12/site-packages/kaggle/__init__.py", line 23, in <module>
    api.authenticate()
  File "/home/airflow/.local/lib/python3.12/site-packages/kaggle/api/kaggle_api_extended.py", line 181, in authenticate
    raise IOError('Could not find {}. Make sure it\'s located in'
OSError: Could not find kaggle.json. Make sure it's located in /home/airflow/.kaggle. Or use the environment method.
[2024-09-28T03:49:14.193+0000] {processor.py:927} WARNING - No viable dags retrieved from /opt/airflow/dags/covid_gdp_dag.py
[2024-09-28T03:49:14.229+0000] {processor.py:208} INFO - Processing /opt/airflow/dags/covid_gdp_dag.py took 0.211 seconds
[2024-09-28T03:49:44.333+0000] {processor.py:186} INFO - Started process (PID=1478) to work on /opt/airflow/dags/covid_gdp_dag.py
[2024-09-28T03:49:44.334+0000] {processor.py:914} INFO - Processing file /opt/airflow/dags/covid_gdp_dag.py for tasks to queue
[2024-09-28T03:49:44.337+0000] {logging_mixin.py:190} INFO - [2024-09-28T03:49:44.337+0000] {dagbag.py:588} INFO - Filling up the DagBag from /opt/airflow/dags/covid_gdp_dag.py
[2024-09-28T03:49:44.446+0000] {logging_mixin.py:190} INFO - [2024-09-28T03:49:44.434+0000] {dagbag.py:387} ERROR - Failed to import: /opt/airflow/dags/covid_gdp_dag.py
Traceback (most recent call last):
  File "/home/airflow/.local/lib/python3.12/site-packages/airflow/models/dagbag.py", line 383, in parse
    loader.exec_module(new_module)
  File "<frozen importlib._bootstrap_external>", line 995, in exec_module
  File "<frozen importlib._bootstrap>", line 488, in _call_with_frames_removed
  File "/opt/airflow/dags/covid_gdp_dag.py", line 7, in <module>
    from common_data_loader import download_world_bank_data, download_kaggle_dataset, load_covid_data, load_gdp_data
  File "/opt/airflow/dags/common_data_loader.py", line 3, in <module>
    import kaggle
  File "/home/airflow/.local/lib/python3.12/site-packages/kaggle/__init__.py", line 23, in <module>
    api.authenticate()
  File "/home/airflow/.local/lib/python3.12/site-packages/kaggle/api/kaggle_api_extended.py", line 181, in authenticate
    raise IOError('Could not find {}. Make sure it\'s located in'
OSError: Could not find kaggle.json. Make sure it's located in /home/airflow/.kaggle. Or use the environment method.
[2024-09-28T03:49:44.447+0000] {processor.py:927} WARNING - No viable dags retrieved from /opt/airflow/dags/covid_gdp_dag.py
[2024-09-28T03:49:44.480+0000] {processor.py:208} INFO - Processing /opt/airflow/dags/covid_gdp_dag.py took 0.154 seconds
[2024-09-28T03:50:14.611+0000] {processor.py:186} INFO - Started process (PID=1552) to work on /opt/airflow/dags/covid_gdp_dag.py
[2024-09-28T03:50:14.612+0000] {processor.py:914} INFO - Processing file /opt/airflow/dags/covid_gdp_dag.py for tasks to queue
[2024-09-28T03:50:14.614+0000] {logging_mixin.py:190} INFO - [2024-09-28T03:50:14.613+0000] {dagbag.py:588} INFO - Filling up the DagBag from /opt/airflow/dags/covid_gdp_dag.py
[2024-09-28T03:50:14.710+0000] {logging_mixin.py:190} INFO - [2024-09-28T03:50:14.703+0000] {dagbag.py:387} ERROR - Failed to import: /opt/airflow/dags/covid_gdp_dag.py
Traceback (most recent call last):
  File "/home/airflow/.local/lib/python3.12/site-packages/airflow/models/dagbag.py", line 383, in parse
    loader.exec_module(new_module)
  File "<frozen importlib._bootstrap_external>", line 995, in exec_module
  File "<frozen importlib._bootstrap>", line 488, in _call_with_frames_removed
  File "/opt/airflow/dags/covid_gdp_dag.py", line 7, in <module>
    from common_data_loader import download_world_bank_data, download_kaggle_dataset, load_covid_data, load_gdp_data
  File "/opt/airflow/dags/common_data_loader.py", line 3, in <module>
    import kaggle
  File "/home/airflow/.local/lib/python3.12/site-packages/kaggle/__init__.py", line 23, in <module>
    api.authenticate()
  File "/home/airflow/.local/lib/python3.12/site-packages/kaggle/api/kaggle_api_extended.py", line 181, in authenticate
    raise IOError('Could not find {}. Make sure it\'s located in'
OSError: Could not find kaggle.json. Make sure it's located in /home/airflow/.kaggle. Or use the environment method.
[2024-09-28T03:50:14.711+0000] {processor.py:927} WARNING - No viable dags retrieved from /opt/airflow/dags/covid_gdp_dag.py
[2024-09-28T03:50:14.732+0000] {processor.py:208} INFO - Processing /opt/airflow/dags/covid_gdp_dag.py took 0.126 seconds
[2024-09-28T03:53:29.801+0000] {processor.py:186} INFO - Started process (PID=62) to work on /opt/airflow/dags/covid_gdp_dag.py
[2024-09-28T03:53:29.804+0000] {processor.py:914} INFO - Processing file /opt/airflow/dags/covid_gdp_dag.py for tasks to queue
[2024-09-28T03:53:29.815+0000] {logging_mixin.py:190} INFO - [2024-09-28T03:53:29.814+0000] {dagbag.py:588} INFO - Filling up the DagBag from /opt/airflow/dags/covid_gdp_dag.py
[2024-09-28T03:53:31.318+0000] {logging_mixin.py:190} INFO - [2024-09-28T03:53:31.298+0000] {dagbag.py:387} ERROR - Failed to import: /opt/airflow/dags/covid_gdp_dag.py
Traceback (most recent call last):
  File "/home/airflow/.local/lib/python3.12/site-packages/airflow/models/dagbag.py", line 383, in parse
    loader.exec_module(new_module)
  File "<frozen importlib._bootstrap_external>", line 995, in exec_module
  File "<frozen importlib._bootstrap>", line 488, in _call_with_frames_removed
  File "/opt/airflow/dags/covid_gdp_dag.py", line 7, in <module>
    from common_data_loader import download_world_bank_data, download_kaggle_dataset, load_covid_data, load_gdp_data
  File "/opt/airflow/dags/common_data_loader.py", line 3, in <module>
    import kaggle
  File "/home/airflow/.local/lib/python3.12/site-packages/kaggle/__init__.py", line 23, in <module>
    api.authenticate()
  File "/home/airflow/.local/lib/python3.12/site-packages/kaggle/api/kaggle_api_extended.py", line 181, in authenticate
    raise IOError('Could not find {}. Make sure it\'s located in'
OSError: Could not find kaggle.json. Make sure it's located in /home/airflow/.kaggle. Or use the environment method.
[2024-09-28T03:53:31.320+0000] {processor.py:927} WARNING - No viable dags retrieved from /opt/airflow/dags/covid_gdp_dag.py
[2024-09-28T03:53:31.382+0000] {processor.py:208} INFO - Processing /opt/airflow/dags/covid_gdp_dag.py took 1.607 seconds
[2024-09-28T03:54:01.545+0000] {processor.py:186} INFO - Started process (PID=136) to work on /opt/airflow/dags/covid_gdp_dag.py
[2024-09-28T03:54:01.546+0000] {processor.py:914} INFO - Processing file /opt/airflow/dags/covid_gdp_dag.py for tasks to queue
[2024-09-28T03:54:01.619+0000] {logging_mixin.py:190} INFO - [2024-09-28T03:54:01.619+0000] {dagbag.py:588} INFO - Filling up the DagBag from /opt/airflow/dags/covid_gdp_dag.py
[2024-09-28T03:54:01.899+0000] {logging_mixin.py:190} INFO - [2024-09-28T03:54:01.886+0000] {dagbag.py:387} ERROR - Failed to import: /opt/airflow/dags/covid_gdp_dag.py
Traceback (most recent call last):
  File "/home/airflow/.local/lib/python3.12/site-packages/airflow/models/dagbag.py", line 383, in parse
    loader.exec_module(new_module)
  File "<frozen importlib._bootstrap_external>", line 995, in exec_module
  File "<frozen importlib._bootstrap>", line 488, in _call_with_frames_removed
  File "/opt/airflow/dags/covid_gdp_dag.py", line 7, in <module>
    from common_data_loader import download_world_bank_data, download_kaggle_dataset, load_covid_data, load_gdp_data
  File "/opt/airflow/dags/common_data_loader.py", line 3, in <module>
    import kaggle
  File "/home/airflow/.local/lib/python3.12/site-packages/kaggle/__init__.py", line 23, in <module>
    api.authenticate()
  File "/home/airflow/.local/lib/python3.12/site-packages/kaggle/api/kaggle_api_extended.py", line 181, in authenticate
    raise IOError('Could not find {}. Make sure it\'s located in'
OSError: Could not find kaggle.json. Make sure it's located in /home/airflow/.kaggle. Or use the environment method.
[2024-09-28T03:54:01.900+0000] {processor.py:927} WARNING - No viable dags retrieved from /opt/airflow/dags/covid_gdp_dag.py
[2024-09-28T03:54:01.937+0000] {processor.py:208} INFO - Processing /opt/airflow/dags/covid_gdp_dag.py took 0.400 seconds
[2024-09-28T03:54:32.779+0000] {processor.py:186} INFO - Started process (PID=217) to work on /opt/airflow/dags/covid_gdp_dag.py
[2024-09-28T03:54:32.780+0000] {processor.py:914} INFO - Processing file /opt/airflow/dags/covid_gdp_dag.py for tasks to queue
[2024-09-28T03:54:32.784+0000] {logging_mixin.py:190} INFO - [2024-09-28T03:54:32.783+0000] {dagbag.py:588} INFO - Filling up the DagBag from /opt/airflow/dags/covid_gdp_dag.py
[2024-09-28T03:54:32.916+0000] {logging_mixin.py:190} INFO - [2024-09-28T03:54:32.902+0000] {dagbag.py:387} ERROR - Failed to import: /opt/airflow/dags/covid_gdp_dag.py
Traceback (most recent call last):
  File "/home/airflow/.local/lib/python3.12/site-packages/airflow/models/dagbag.py", line 383, in parse
    loader.exec_module(new_module)
  File "<frozen importlib._bootstrap_external>", line 995, in exec_module
  File "<frozen importlib._bootstrap>", line 488, in _call_with_frames_removed
  File "/opt/airflow/dags/covid_gdp_dag.py", line 7, in <module>
    from common_data_loader import download_world_bank_data, download_kaggle_dataset, load_covid_data, load_gdp_data
  File "/opt/airflow/dags/common_data_loader.py", line 3, in <module>
    import kaggle
  File "/home/airflow/.local/lib/python3.12/site-packages/kaggle/__init__.py", line 23, in <module>
    api.authenticate()
  File "/home/airflow/.local/lib/python3.12/site-packages/kaggle/api/kaggle_api_extended.py", line 181, in authenticate
    raise IOError('Could not find {}. Make sure it\'s located in'
OSError: Could not find kaggle.json. Make sure it's located in /home/airflow/.kaggle. Or use the environment method.
[2024-09-28T03:54:32.917+0000] {processor.py:927} WARNING - No viable dags retrieved from /opt/airflow/dags/covid_gdp_dag.py
[2024-09-28T03:54:32.946+0000] {processor.py:208} INFO - Processing /opt/airflow/dags/covid_gdp_dag.py took 0.174 seconds
[2024-09-28T03:55:03.945+0000] {processor.py:186} INFO - Started process (PID=291) to work on /opt/airflow/dags/covid_gdp_dag.py
[2024-09-28T03:55:03.946+0000] {processor.py:914} INFO - Processing file /opt/airflow/dags/covid_gdp_dag.py for tasks to queue
[2024-09-28T03:55:03.949+0000] {logging_mixin.py:190} INFO - [2024-09-28T03:55:03.948+0000] {dagbag.py:588} INFO - Filling up the DagBag from /opt/airflow/dags/covid_gdp_dag.py
[2024-09-28T03:55:04.074+0000] {logging_mixin.py:190} INFO - [2024-09-28T03:55:04.065+0000] {dagbag.py:387} ERROR - Failed to import: /opt/airflow/dags/covid_gdp_dag.py
Traceback (most recent call last):
  File "/home/airflow/.local/lib/python3.12/site-packages/airflow/models/dagbag.py", line 383, in parse
    loader.exec_module(new_module)
  File "<frozen importlib._bootstrap_external>", line 995, in exec_module
  File "<frozen importlib._bootstrap>", line 488, in _call_with_frames_removed
  File "/opt/airflow/dags/covid_gdp_dag.py", line 7, in <module>
    from common_data_loader import download_world_bank_data, download_kaggle_dataset, load_covid_data, load_gdp_data
  File "/opt/airflow/dags/common_data_loader.py", line 3, in <module>
    import kaggle
  File "/home/airflow/.local/lib/python3.12/site-packages/kaggle/__init__.py", line 23, in <module>
    api.authenticate()
  File "/home/airflow/.local/lib/python3.12/site-packages/kaggle/api/kaggle_api_extended.py", line 181, in authenticate
    raise IOError('Could not find {}. Make sure it\'s located in'
OSError: Could not find kaggle.json. Make sure it's located in /home/airflow/.kaggle. Or use the environment method.
[2024-09-28T03:55:04.075+0000] {processor.py:927} WARNING - No viable dags retrieved from /opt/airflow/dags/covid_gdp_dag.py
[2024-09-28T03:55:04.101+0000] {processor.py:208} INFO - Processing /opt/airflow/dags/covid_gdp_dag.py took 0.162 seconds
[2024-09-28T03:55:28.757+0000] {processor.py:186} INFO - Started process (PID=359) to work on /opt/airflow/dags/covid_gdp_dag.py
[2024-09-28T03:55:28.759+0000] {processor.py:914} INFO - Processing file /opt/airflow/dags/covid_gdp_dag.py for tasks to queue
[2024-09-28T03:55:28.764+0000] {logging_mixin.py:190} INFO - [2024-09-28T03:55:28.764+0000] {dagbag.py:588} INFO - Filling up the DagBag from /opt/airflow/dags/covid_gdp_dag.py
[2024-09-28T03:55:28.791+0000] {logging_mixin.py:190} INFO - [2024-09-28T03:55:28.788+0000] {dagbag.py:387} ERROR - Failed to import: /opt/airflow/dags/covid_gdp_dag.py
Traceback (most recent call last):
  File "/home/airflow/.local/lib/python3.12/site-packages/airflow/models/dagbag.py", line 383, in parse
    loader.exec_module(new_module)
  File "<frozen importlib._bootstrap_external>", line 991, in exec_module
  File "<frozen importlib._bootstrap_external>", line 1129, in get_code
  File "<frozen importlib._bootstrap_external>", line 1059, in source_to_code
  File "<frozen importlib._bootstrap>", line 488, in _call_with_frames_removed
  File "/opt/airflow/dags/covid_gdp_dag.py", line 5
    import 
           ^
SyntaxError: invalid syntax
[2024-09-28T03:55:28.792+0000] {processor.py:927} WARNING - No viable dags retrieved from /opt/airflow/dags/covid_gdp_dag.py
[2024-09-28T03:55:28.829+0000] {processor.py:208} INFO - Processing /opt/airflow/dags/covid_gdp_dag.py took 0.080 seconds
[2024-09-28T03:55:29.812+0000] {processor.py:186} INFO - Started process (PID=360) to work on /opt/airflow/dags/covid_gdp_dag.py
[2024-09-28T03:55:29.813+0000] {processor.py:914} INFO - Processing file /opt/airflow/dags/covid_gdp_dag.py for tasks to queue
[2024-09-28T03:55:29.817+0000] {logging_mixin.py:190} INFO - [2024-09-28T03:55:29.817+0000] {dagbag.py:588} INFO - Filling up the DagBag from /opt/airflow/dags/covid_gdp_dag.py
[2024-09-28T03:55:29.943+0000] {logging_mixin.py:190} INFO - [2024-09-28T03:55:29.934+0000] {dagbag.py:387} ERROR - Failed to import: /opt/airflow/dags/covid_gdp_dag.py
Traceback (most recent call last):
  File "/home/airflow/.local/lib/python3.12/site-packages/airflow/models/dagbag.py", line 383, in parse
    loader.exec_module(new_module)
  File "<frozen importlib._bootstrap_external>", line 995, in exec_module
  File "<frozen importlib._bootstrap>", line 488, in _call_with_frames_removed
  File "/opt/airflow/dags/covid_gdp_dag.py", line 7, in <module>
    from common_data_loader import download_world_bank_data, download_kaggle_dataset, load_covid_data, load_gdp_data
  File "/opt/airflow/dags/common_data_loader.py", line 3, in <module>
    import kaggle
  File "/home/airflow/.local/lib/python3.12/site-packages/kaggle/__init__.py", line 23, in <module>
    api.authenticate()
  File "/home/airflow/.local/lib/python3.12/site-packages/kaggle/api/kaggle_api_extended.py", line 181, in authenticate
    raise IOError('Could not find {}. Make sure it\'s located in'
OSError: Could not find kaggle.json. Make sure it's located in /home/airflow/.kaggle. Or use the environment method.
[2024-09-28T03:55:29.946+0000] {logging_mixin.py:190} WARNING - /opt/airflow/dags/covid_gdp_dag.py:33 SyntaxWarning: invalid escape sequence '\D'
[2024-09-28T03:55:29.947+0000] {logging_mixin.py:190} WARNING - /opt/airflow/dags/covid_gdp_dag.py:33 SyntaxWarning: invalid escape sequence '\D'
[2024-09-28T03:55:29.948+0000] {logging_mixin.py:190} WARNING - /opt/airflow/dags/covid_gdp_dag.py:43 SyntaxWarning: invalid escape sequence '\D'
[2024-09-28T03:55:29.949+0000] {processor.py:927} WARNING - No viable dags retrieved from /opt/airflow/dags/covid_gdp_dag.py
[2024-09-28T03:55:29.975+0000] {processor.py:208} INFO - Processing /opt/airflow/dags/covid_gdp_dag.py took 0.170 seconds
[2024-09-28T03:55:34.955+0000] {processor.py:186} INFO - Started process (PID=378) to work on /opt/airflow/dags/covid_gdp_dag.py
[2024-09-28T03:55:34.956+0000] {processor.py:914} INFO - Processing file /opt/airflow/dags/covid_gdp_dag.py for tasks to queue
[2024-09-28T03:55:34.960+0000] {logging_mixin.py:190} INFO - [2024-09-28T03:55:34.959+0000] {dagbag.py:588} INFO - Filling up the DagBag from /opt/airflow/dags/covid_gdp_dag.py
[2024-09-28T03:55:35.279+0000] {logging_mixin.py:190} INFO - [2024-09-28T03:55:35.264+0000] {dagbag.py:387} ERROR - Failed to import: /opt/airflow/dags/covid_gdp_dag.py
Traceback (most recent call last):
  File "/home/airflow/.local/lib/python3.12/site-packages/airflow/models/dagbag.py", line 383, in parse
    loader.exec_module(new_module)
  File "<frozen importlib._bootstrap_external>", line 995, in exec_module
  File "<frozen importlib._bootstrap>", line 488, in _call_with_frames_removed
  File "/opt/airflow/dags/covid_gdp_dag.py", line 7, in <module>
    from common_data_loader import download_world_bank_data, download_kaggle_dataset, load_covid_data, load_gdp_data
  File "/opt/airflow/dags/common_data_loader.py", line 3, in <module>
    import kaggle
  File "/home/airflow/.local/lib/python3.12/site-packages/kaggle/__init__.py", line 23, in <module>
    api.authenticate()
  File "/home/airflow/.local/lib/python3.12/site-packages/kaggle/api/kaggle_api_extended.py", line 181, in authenticate
    raise IOError('Could not find {}. Make sure it\'s located in'
OSError: Could not find kaggle.json. Make sure it's located in /home/airflow/.kaggle. Or use the environment method.
[2024-09-28T03:55:35.285+0000] {logging_mixin.py:190} WARNING - /opt/airflow/dags/covid_gdp_dag.py:35 SyntaxWarning: invalid escape sequence '\D'
[2024-09-28T03:55:35.287+0000] {logging_mixin.py:190} WARNING - /opt/airflow/dags/covid_gdp_dag.py:35 SyntaxWarning: invalid escape sequence '\D'
[2024-09-28T03:55:35.288+0000] {logging_mixin.py:190} WARNING - /opt/airflow/dags/covid_gdp_dag.py:45 SyntaxWarning: invalid escape sequence '\D'
[2024-09-28T03:55:35.289+0000] {processor.py:927} WARNING - No viable dags retrieved from /opt/airflow/dags/covid_gdp_dag.py
[2024-09-28T03:55:35.315+0000] {processor.py:208} INFO - Processing /opt/airflow/dags/covid_gdp_dag.py took 0.368 seconds
[2024-09-28T03:55:39.560+0000] {processor.py:186} INFO - Started process (PID=418) to work on /opt/airflow/dags/covid_gdp_dag.py
[2024-09-28T03:55:39.561+0000] {processor.py:914} INFO - Processing file /opt/airflow/dags/covid_gdp_dag.py for tasks to queue
[2024-09-28T03:55:39.563+0000] {logging_mixin.py:190} INFO - [2024-09-28T03:55:39.563+0000] {dagbag.py:588} INFO - Filling up the DagBag from /opt/airflow/dags/covid_gdp_dag.py
[2024-09-28T03:55:39.681+0000] {logging_mixin.py:190} INFO - [2024-09-28T03:55:39.671+0000] {dagbag.py:387} ERROR - Failed to import: /opt/airflow/dags/covid_gdp_dag.py
Traceback (most recent call last):
  File "/home/airflow/.local/lib/python3.12/site-packages/airflow/models/dagbag.py", line 383, in parse
    loader.exec_module(new_module)
  File "<frozen importlib._bootstrap_external>", line 995, in exec_module
  File "<frozen importlib._bootstrap>", line 488, in _call_with_frames_removed
  File "/opt/airflow/dags/covid_gdp_dag.py", line 7, in <module>
    from common_data_loader import download_world_bank_data, download_kaggle_dataset, load_covid_data, load_gdp_data
  File "/opt/airflow/dags/common_data_loader.py", line 3, in <module>
    import kaggle
  File "/home/airflow/.local/lib/python3.12/site-packages/kaggle/__init__.py", line 23, in <module>
    api.authenticate()
  File "/home/airflow/.local/lib/python3.12/site-packages/kaggle/api/kaggle_api_extended.py", line 181, in authenticate
    raise IOError('Could not find {}. Make sure it\'s located in'
OSError: Could not find kaggle.json. Make sure it's located in /home/airflow/.kaggle. Or use the environment method.
[2024-09-28T03:55:39.684+0000] {logging_mixin.py:190} WARNING - /opt/airflow/dags/covid_gdp_dag.py:35 SyntaxWarning: invalid escape sequence '\D'
[2024-09-28T03:55:39.686+0000] {logging_mixin.py:190} WARNING - /opt/airflow/dags/covid_gdp_dag.py:35 SyntaxWarning: invalid escape sequence '\D'
[2024-09-28T03:55:39.687+0000] {logging_mixin.py:190} WARNING - /opt/airflow/dags/covid_gdp_dag.py:45 SyntaxWarning: invalid escape sequence '\D'
[2024-09-28T03:55:39.688+0000] {processor.py:927} WARNING - No viable dags retrieved from /opt/airflow/dags/covid_gdp_dag.py
[2024-09-28T03:55:39.715+0000] {processor.py:208} INFO - Processing /opt/airflow/dags/covid_gdp_dag.py took 0.160 seconds
[2024-09-28T03:55:41.444+0000] {processor.py:186} INFO - Started process (PID=439) to work on /opt/airflow/dags/covid_gdp_dag.py
[2024-09-28T03:55:41.446+0000] {processor.py:914} INFO - Processing file /opt/airflow/dags/covid_gdp_dag.py for tasks to queue
[2024-09-28T03:55:41.449+0000] {logging_mixin.py:190} INFO - [2024-09-28T03:55:41.448+0000] {dagbag.py:588} INFO - Filling up the DagBag from /opt/airflow/dags/covid_gdp_dag.py
[2024-09-28T03:55:41.472+0000] {logging_mixin.py:190} INFO - [2024-09-28T03:55:41.471+0000] {dagbag.py:387} ERROR - Failed to import: /opt/airflow/dags/covid_gdp_dag.py
Traceback (most recent call last):
  File "/home/airflow/.local/lib/python3.12/site-packages/airflow/models/dagbag.py", line 383, in parse
    loader.exec_module(new_module)
  File "<frozen importlib._bootstrap_external>", line 991, in exec_module
  File "<frozen importlib._bootstrap_external>", line 1129, in get_code
  File "<frozen importlib._bootstrap_external>", line 1059, in source_to_code
  File "<frozen importlib._bootstrap>", line 488, in _call_with_frames_removed
  File "/opt/airflow/dags/covid_gdp_dag.py", line 12
    os.environ[]
               ^
SyntaxError: invalid syntax
[2024-09-28T03:55:41.474+0000] {processor.py:927} WARNING - No viable dags retrieved from /opt/airflow/dags/covid_gdp_dag.py
[2024-09-28T03:55:41.503+0000] {processor.py:208} INFO - Processing /opt/airflow/dags/covid_gdp_dag.py took 0.066 seconds
[2024-09-28T03:55:43.318+0000] {processor.py:186} INFO - Started process (PID=459) to work on /opt/airflow/dags/covid_gdp_dag.py
[2024-09-28T03:55:43.320+0000] {processor.py:914} INFO - Processing file /opt/airflow/dags/covid_gdp_dag.py for tasks to queue
[2024-09-28T03:55:43.323+0000] {logging_mixin.py:190} INFO - [2024-09-28T03:55:43.322+0000] {dagbag.py:588} INFO - Filling up the DagBag from /opt/airflow/dags/covid_gdp_dag.py
[2024-09-28T03:55:43.448+0000] {logging_mixin.py:190} INFO - [2024-09-28T03:55:43.436+0000] {dagbag.py:387} ERROR - Failed to import: /opt/airflow/dags/covid_gdp_dag.py
Traceback (most recent call last):
  File "/home/airflow/.local/lib/python3.12/site-packages/airflow/models/dagbag.py", line 383, in parse
    loader.exec_module(new_module)
  File "<frozen importlib._bootstrap_external>", line 995, in exec_module
  File "<frozen importlib._bootstrap>", line 488, in _call_with_frames_removed
  File "/opt/airflow/dags/covid_gdp_dag.py", line 7, in <module>
    from common_data_loader import download_world_bank_data, download_kaggle_dataset, load_covid_data, load_gdp_data
  File "/opt/airflow/dags/common_data_loader.py", line 3, in <module>
    import kaggle
  File "/home/airflow/.local/lib/python3.12/site-packages/kaggle/__init__.py", line 23, in <module>
    api.authenticate()
  File "/home/airflow/.local/lib/python3.12/site-packages/kaggle/api/kaggle_api_extended.py", line 181, in authenticate
    raise IOError('Could not find {}. Make sure it\'s located in'
OSError: Could not find kaggle.json. Make sure it's located in /home/airflow/.kaggle. Or use the environment method.
[2024-09-28T03:55:43.451+0000] {logging_mixin.py:190} WARNING - /opt/airflow/dags/covid_gdp_dag.py:35 SyntaxWarning: invalid escape sequence '\D'
[2024-09-28T03:55:43.452+0000] {logging_mixin.py:190} WARNING - /opt/airflow/dags/covid_gdp_dag.py:35 SyntaxWarning: invalid escape sequence '\D'
[2024-09-28T03:55:43.454+0000] {logging_mixin.py:190} WARNING - /opt/airflow/dags/covid_gdp_dag.py:45 SyntaxWarning: invalid escape sequence '\D'
[2024-09-28T03:55:43.455+0000] {processor.py:927} WARNING - No viable dags retrieved from /opt/airflow/dags/covid_gdp_dag.py
[2024-09-28T03:55:43.486+0000] {processor.py:208} INFO - Processing /opt/airflow/dags/covid_gdp_dag.py took 0.174 seconds
[2024-09-28T03:55:46.366+0000] {processor.py:186} INFO - Started process (PID=471) to work on /opt/airflow/dags/covid_gdp_dag.py
[2024-09-28T03:55:46.367+0000] {processor.py:914} INFO - Processing file /opt/airflow/dags/covid_gdp_dag.py for tasks to queue
[2024-09-28T03:55:46.370+0000] {logging_mixin.py:190} INFO - [2024-09-28T03:55:46.369+0000] {dagbag.py:588} INFO - Filling up the DagBag from /opt/airflow/dags/covid_gdp_dag.py
[2024-09-28T03:55:46.474+0000] {logging_mixin.py:190} INFO - [2024-09-28T03:55:46.466+0000] {dagbag.py:387} ERROR - Failed to import: /opt/airflow/dags/covid_gdp_dag.py
Traceback (most recent call last):
  File "/home/airflow/.local/lib/python3.12/site-packages/airflow/models/dagbag.py", line 383, in parse
    loader.exec_module(new_module)
  File "<frozen importlib._bootstrap_external>", line 995, in exec_module
  File "<frozen importlib._bootstrap>", line 488, in _call_with_frames_removed
  File "/opt/airflow/dags/covid_gdp_dag.py", line 7, in <module>
    from common_data_loader import download_world_bank_data, download_kaggle_dataset, load_covid_data, load_gdp_data
  File "/opt/airflow/dags/common_data_loader.py", line 3, in <module>
    import kaggle
  File "/home/airflow/.local/lib/python3.12/site-packages/kaggle/__init__.py", line 23, in <module>
    api.authenticate()
  File "/home/airflow/.local/lib/python3.12/site-packages/kaggle/api/kaggle_api_extended.py", line 181, in authenticate
    raise IOError('Could not find {}. Make sure it\'s located in'
OSError: Could not find kaggle.json. Make sure it's located in /home/airflow/.kaggle. Or use the environment method.
[2024-09-28T03:55:46.477+0000] {logging_mixin.py:190} WARNING - /opt/airflow/dags/covid_gdp_dag.py:35 SyntaxWarning: invalid escape sequence '\D'
[2024-09-28T03:55:46.478+0000] {logging_mixin.py:190} WARNING - /opt/airflow/dags/covid_gdp_dag.py:35 SyntaxWarning: invalid escape sequence '\D'
[2024-09-28T03:55:46.480+0000] {logging_mixin.py:190} WARNING - /opt/airflow/dags/covid_gdp_dag.py:45 SyntaxWarning: invalid escape sequence '\D'
[2024-09-28T03:55:46.480+0000] {processor.py:927} WARNING - No viable dags retrieved from /opt/airflow/dags/covid_gdp_dag.py
[2024-09-28T03:55:46.505+0000] {processor.py:208} INFO - Processing /opt/airflow/dags/covid_gdp_dag.py took 0.144 seconds
[2024-09-28T03:55:49.412+0000] {processor.py:186} INFO - Started process (PID=483) to work on /opt/airflow/dags/covid_gdp_dag.py
[2024-09-28T03:55:49.413+0000] {processor.py:914} INFO - Processing file /opt/airflow/dags/covid_gdp_dag.py for tasks to queue
[2024-09-28T03:55:49.438+0000] {logging_mixin.py:190} INFO - [2024-09-28T03:55:49.437+0000] {dagbag.py:588} INFO - Filling up the DagBag from /opt/airflow/dags/covid_gdp_dag.py
[2024-09-28T03:55:49.584+0000] {logging_mixin.py:190} INFO - [2024-09-28T03:55:49.574+0000] {dagbag.py:387} ERROR - Failed to import: /opt/airflow/dags/covid_gdp_dag.py
Traceback (most recent call last):
  File "/home/airflow/.local/lib/python3.12/site-packages/airflow/models/dagbag.py", line 383, in parse
    loader.exec_module(new_module)
  File "<frozen importlib._bootstrap_external>", line 995, in exec_module
  File "<frozen importlib._bootstrap>", line 488, in _call_with_frames_removed
  File "/opt/airflow/dags/covid_gdp_dag.py", line 7, in <module>
    from common_data_loader import download_world_bank_data, download_kaggle_dataset, load_covid_data, load_gdp_data
  File "/opt/airflow/dags/common_data_loader.py", line 3, in <module>
    import kaggle
  File "/home/airflow/.local/lib/python3.12/site-packages/kaggle/__init__.py", line 23, in <module>
    api.authenticate()
  File "/home/airflow/.local/lib/python3.12/site-packages/kaggle/api/kaggle_api_extended.py", line 181, in authenticate
    raise IOError('Could not find {}. Make sure it\'s located in'
OSError: Could not find kaggle.json. Make sure it's located in /home/airflow/.kaggle. Or use the environment method.
[2024-09-28T03:55:49.587+0000] {logging_mixin.py:190} WARNING - /opt/airflow/dags/covid_gdp_dag.py:35 SyntaxWarning: invalid escape sequence '\D'
[2024-09-28T03:55:49.588+0000] {logging_mixin.py:190} WARNING - /opt/airflow/dags/covid_gdp_dag.py:35 SyntaxWarning: invalid escape sequence '\D'
[2024-09-28T03:55:49.589+0000] {logging_mixin.py:190} WARNING - /opt/airflow/dags/covid_gdp_dag.py:45 SyntaxWarning: invalid escape sequence '\D'
[2024-09-28T03:55:49.589+0000] {processor.py:927} WARNING - No viable dags retrieved from /opt/airflow/dags/covid_gdp_dag.py
[2024-09-28T03:55:49.610+0000] {processor.py:208} INFO - Processing /opt/airflow/dags/covid_gdp_dag.py took 0.204 seconds
[2024-09-28T03:55:51.625+0000] {processor.py:186} INFO - Started process (PID=495) to work on /opt/airflow/dags/covid_gdp_dag.py
[2024-09-28T03:55:51.626+0000] {processor.py:914} INFO - Processing file /opt/airflow/dags/covid_gdp_dag.py for tasks to queue
[2024-09-28T03:55:51.636+0000] {logging_mixin.py:190} INFO - [2024-09-28T03:55:51.634+0000] {dagbag.py:588} INFO - Filling up the DagBag from /opt/airflow/dags/covid_gdp_dag.py
[2024-09-28T03:55:51.805+0000] {logging_mixin.py:190} INFO - [2024-09-28T03:55:51.798+0000] {dagbag.py:387} ERROR - Failed to import: /opt/airflow/dags/covid_gdp_dag.py
Traceback (most recent call last):
  File "/home/airflow/.local/lib/python3.12/site-packages/airflow/models/dagbag.py", line 383, in parse
    loader.exec_module(new_module)
  File "<frozen importlib._bootstrap_external>", line 995, in exec_module
  File "<frozen importlib._bootstrap>", line 488, in _call_with_frames_removed
  File "/opt/airflow/dags/covid_gdp_dag.py", line 7, in <module>
    from common_data_loader import download_world_bank_data, download_kaggle_dataset, load_covid_data, load_gdp_data
  File "/opt/airflow/dags/common_data_loader.py", line 3, in <module>
    import kaggle
  File "/home/airflow/.local/lib/python3.12/site-packages/kaggle/__init__.py", line 23, in <module>
    api.authenticate()
  File "/home/airflow/.local/lib/python3.12/site-packages/kaggle/api/kaggle_api_extended.py", line 181, in authenticate
    raise IOError('Could not find {}. Make sure it\'s located in'
OSError: Could not find kaggle.json. Make sure it's located in /home/airflow/.kaggle. Or use the environment method.
[2024-09-28T03:55:51.808+0000] {logging_mixin.py:190} WARNING - /opt/airflow/dags/covid_gdp_dag.py:35 SyntaxWarning: invalid escape sequence '\D'
[2024-09-28T03:55:51.809+0000] {logging_mixin.py:190} WARNING - /opt/airflow/dags/covid_gdp_dag.py:35 SyntaxWarning: invalid escape sequence '\D'
[2024-09-28T03:55:51.810+0000] {logging_mixin.py:190} WARNING - /opt/airflow/dags/covid_gdp_dag.py:45 SyntaxWarning: invalid escape sequence '\D'
[2024-09-28T03:55:51.811+0000] {processor.py:927} WARNING - No viable dags retrieved from /opt/airflow/dags/covid_gdp_dag.py
[2024-09-28T03:55:51.835+0000] {processor.py:208} INFO - Processing /opt/airflow/dags/covid_gdp_dag.py took 0.216 seconds
[2024-09-28T03:55:53.719+0000] {processor.py:186} INFO - Started process (PID=507) to work on /opt/airflow/dags/covid_gdp_dag.py
[2024-09-28T03:55:53.721+0000] {processor.py:914} INFO - Processing file /opt/airflow/dags/covid_gdp_dag.py for tasks to queue
[2024-09-28T03:55:53.725+0000] {logging_mixin.py:190} INFO - [2024-09-28T03:55:53.724+0000] {dagbag.py:588} INFO - Filling up the DagBag from /opt/airflow/dags/covid_gdp_dag.py
[2024-09-28T03:55:53.822+0000] {logging_mixin.py:190} INFO - [2024-09-28T03:55:53.814+0000] {dagbag.py:387} ERROR - Failed to import: /opt/airflow/dags/covid_gdp_dag.py
Traceback (most recent call last):
  File "/home/airflow/.local/lib/python3.12/site-packages/airflow/models/dagbag.py", line 383, in parse
    loader.exec_module(new_module)
  File "<frozen importlib._bootstrap_external>", line 995, in exec_module
  File "<frozen importlib._bootstrap>", line 488, in _call_with_frames_removed
  File "/opt/airflow/dags/covid_gdp_dag.py", line 7, in <module>
    from common_data_loader import download_world_bank_data, download_kaggle_dataset, load_covid_data, load_gdp_data
  File "/opt/airflow/dags/common_data_loader.py", line 3, in <module>
    import kaggle
  File "/home/airflow/.local/lib/python3.12/site-packages/kaggle/__init__.py", line 23, in <module>
    api.authenticate()
  File "/home/airflow/.local/lib/python3.12/site-packages/kaggle/api/kaggle_api_extended.py", line 181, in authenticate
    raise IOError('Could not find {}. Make sure it\'s located in'
OSError: Could not find kaggle.json. Make sure it's located in /home/airflow/.kaggle. Or use the environment method.
[2024-09-28T03:55:53.824+0000] {logging_mixin.py:190} WARNING - /opt/airflow/dags/covid_gdp_dag.py:35 SyntaxWarning: invalid escape sequence '\D'
[2024-09-28T03:55:53.826+0000] {logging_mixin.py:190} WARNING - /opt/airflow/dags/covid_gdp_dag.py:35 SyntaxWarning: invalid escape sequence '\D'
[2024-09-28T03:55:53.827+0000] {logging_mixin.py:190} WARNING - /opt/airflow/dags/covid_gdp_dag.py:45 SyntaxWarning: invalid escape sequence '\D'
[2024-09-28T03:55:53.828+0000] {processor.py:927} WARNING - No viable dags retrieved from /opt/airflow/dags/covid_gdp_dag.py
[2024-09-28T03:55:53.855+0000] {processor.py:208} INFO - Processing /opt/airflow/dags/covid_gdp_dag.py took 0.141 seconds
[2024-09-28T03:55:56.935+0000] {processor.py:186} INFO - Started process (PID=519) to work on /opt/airflow/dags/covid_gdp_dag.py
[2024-09-28T03:55:56.936+0000] {processor.py:914} INFO - Processing file /opt/airflow/dags/covid_gdp_dag.py for tasks to queue
[2024-09-28T03:55:56.939+0000] {logging_mixin.py:190} INFO - [2024-09-28T03:55:56.939+0000] {dagbag.py:588} INFO - Filling up the DagBag from /opt/airflow/dags/covid_gdp_dag.py
[2024-09-28T03:55:56.956+0000] {logging_mixin.py:190} INFO - [2024-09-28T03:55:56.955+0000] {dagbag.py:387} ERROR - Failed to import: /opt/airflow/dags/covid_gdp_dag.py
Traceback (most recent call last):
  File "/home/airflow/.local/lib/python3.12/site-packages/airflow/models/dagbag.py", line 383, in parse
    loader.exec_module(new_module)
  File "<frozen importlib._bootstrap_external>", line 991, in exec_module
  File "<frozen importlib._bootstrap_external>", line 1129, in get_code
  File "<frozen importlib._bootstrap_external>", line 1059, in source_to_code
  File "<frozen importlib._bootstrap>", line 488, in _call_with_frames_removed
  File "/opt/airflow/dags/covid_gdp_dag.py", line 12
    os.environ['KAGGLE_CONFIG_DIR'] = 
                                      ^
SyntaxError: invalid syntax
[2024-09-28T03:55:56.957+0000] {processor.py:927} WARNING - No viable dags retrieved from /opt/airflow/dags/covid_gdp_dag.py
[2024-09-28T03:55:56.979+0000] {processor.py:208} INFO - Processing /opt/airflow/dags/covid_gdp_dag.py took 0.049 seconds
[2024-09-28T03:55:58.988+0000] {processor.py:186} INFO - Started process (PID=520) to work on /opt/airflow/dags/covid_gdp_dag.py
[2024-09-28T03:55:58.993+0000] {processor.py:914} INFO - Processing file /opt/airflow/dags/covid_gdp_dag.py for tasks to queue
[2024-09-28T03:55:59.001+0000] {logging_mixin.py:190} INFO - [2024-09-28T03:55:58.999+0000] {dagbag.py:588} INFO - Filling up the DagBag from /opt/airflow/dags/covid_gdp_dag.py
[2024-09-28T03:55:59.154+0000] {logging_mixin.py:190} INFO - [2024-09-28T03:55:59.148+0000] {dagbag.py:387} ERROR - Failed to import: /opt/airflow/dags/covid_gdp_dag.py
Traceback (most recent call last):
  File "/home/airflow/.local/lib/python3.12/site-packages/airflow/models/dagbag.py", line 383, in parse
    loader.exec_module(new_module)
  File "<frozen importlib._bootstrap_external>", line 995, in exec_module
  File "<frozen importlib._bootstrap>", line 488, in _call_with_frames_removed
  File "/opt/airflow/dags/covid_gdp_dag.py", line 7, in <module>
    from common_data_loader import download_world_bank_data, download_kaggle_dataset, load_covid_data, load_gdp_data
  File "/opt/airflow/dags/common_data_loader.py", line 3, in <module>
    import kaggle
  File "/home/airflow/.local/lib/python3.12/site-packages/kaggle/__init__.py", line 23, in <module>
    api.authenticate()
  File "/home/airflow/.local/lib/python3.12/site-packages/kaggle/api/kaggle_api_extended.py", line 181, in authenticate
    raise IOError('Could not find {}. Make sure it\'s located in'
OSError: Could not find kaggle.json. Make sure it's located in /home/airflow/.kaggle. Or use the environment method.
[2024-09-28T03:55:59.156+0000] {logging_mixin.py:190} WARNING - /opt/airflow/dags/covid_gdp_dag.py:35 SyntaxWarning: invalid escape sequence '\D'
[2024-09-28T03:55:59.157+0000] {logging_mixin.py:190} WARNING - /opt/airflow/dags/covid_gdp_dag.py:35 SyntaxWarning: invalid escape sequence '\D'
[2024-09-28T03:55:59.158+0000] {logging_mixin.py:190} WARNING - /opt/airflow/dags/covid_gdp_dag.py:45 SyntaxWarning: invalid escape sequence '\D'
[2024-09-28T03:55:59.159+0000] {processor.py:927} WARNING - No viable dags retrieved from /opt/airflow/dags/covid_gdp_dag.py
[2024-09-28T03:55:59.180+0000] {processor.py:208} INFO - Processing /opt/airflow/dags/covid_gdp_dag.py took 0.199 seconds
[2024-09-28T03:56:03.095+0000] {processor.py:186} INFO - Started process (PID=538) to work on /opt/airflow/dags/covid_gdp_dag.py
[2024-09-28T03:56:03.096+0000] {processor.py:914} INFO - Processing file /opt/airflow/dags/covid_gdp_dag.py for tasks to queue
[2024-09-28T03:56:03.098+0000] {logging_mixin.py:190} INFO - [2024-09-28T03:56:03.098+0000] {dagbag.py:588} INFO - Filling up the DagBag from /opt/airflow/dags/covid_gdp_dag.py
[2024-09-28T03:56:03.187+0000] {logging_mixin.py:190} INFO - [2024-09-28T03:56:03.179+0000] {dagbag.py:387} ERROR - Failed to import: /opt/airflow/dags/covid_gdp_dag.py
Traceback (most recent call last):
  File "/home/airflow/.local/lib/python3.12/site-packages/airflow/models/dagbag.py", line 383, in parse
    loader.exec_module(new_module)
  File "<frozen importlib._bootstrap_external>", line 995, in exec_module
  File "<frozen importlib._bootstrap>", line 488, in _call_with_frames_removed
  File "/opt/airflow/dags/covid_gdp_dag.py", line 7, in <module>
    from common_data_loader import download_world_bank_data, download_kaggle_dataset, load_covid_data, load_gdp_data
  File "/opt/airflow/dags/common_data_loader.py", line 3, in <module>
    import kaggle
  File "/home/airflow/.local/lib/python3.12/site-packages/kaggle/__init__.py", line 23, in <module>
    api.authenticate()
  File "/home/airflow/.local/lib/python3.12/site-packages/kaggle/api/kaggle_api_extended.py", line 181, in authenticate
    raise IOError('Could not find {}. Make sure it\'s located in'
OSError: Could not find kaggle.json. Make sure it's located in /home/airflow/.kaggle. Or use the environment method.
[2024-09-28T03:56:03.190+0000] {logging_mixin.py:190} WARNING - /opt/airflow/dags/covid_gdp_dag.py:35 SyntaxWarning: invalid escape sequence '\D'
[2024-09-28T03:56:03.191+0000] {logging_mixin.py:190} WARNING - /opt/airflow/dags/covid_gdp_dag.py:35 SyntaxWarning: invalid escape sequence '\D'
[2024-09-28T03:56:03.192+0000] {logging_mixin.py:190} WARNING - /opt/airflow/dags/covid_gdp_dag.py:45 SyntaxWarning: invalid escape sequence '\D'
[2024-09-28T03:56:03.192+0000] {processor.py:927} WARNING - No viable dags retrieved from /opt/airflow/dags/covid_gdp_dag.py
[2024-09-28T03:56:03.217+0000] {processor.py:208} INFO - Processing /opt/airflow/dags/covid_gdp_dag.py took 0.127 seconds
[2024-09-28T03:56:04.271+0000] {processor.py:186} INFO - Started process (PID=550) to work on /opt/airflow/dags/covid_gdp_dag.py
[2024-09-28T03:56:04.272+0000] {processor.py:914} INFO - Processing file /opt/airflow/dags/covid_gdp_dag.py for tasks to queue
[2024-09-28T03:56:04.276+0000] {logging_mixin.py:190} INFO - [2024-09-28T03:56:04.275+0000] {dagbag.py:588} INFO - Filling up the DagBag from /opt/airflow/dags/covid_gdp_dag.py
[2024-09-28T03:56:04.378+0000] {logging_mixin.py:190} INFO - [2024-09-28T03:56:04.370+0000] {dagbag.py:387} ERROR - Failed to import: /opt/airflow/dags/covid_gdp_dag.py
Traceback (most recent call last):
  File "/home/airflow/.local/lib/python3.12/site-packages/airflow/models/dagbag.py", line 383, in parse
    loader.exec_module(new_module)
  File "<frozen importlib._bootstrap_external>", line 995, in exec_module
  File "<frozen importlib._bootstrap>", line 488, in _call_with_frames_removed
  File "/opt/airflow/dags/covid_gdp_dag.py", line 7, in <module>
    from common_data_loader import download_world_bank_data, download_kaggle_dataset, load_covid_data, load_gdp_data
  File "/opt/airflow/dags/common_data_loader.py", line 3, in <module>
    import kaggle
  File "/home/airflow/.local/lib/python3.12/site-packages/kaggle/__init__.py", line 23, in <module>
    api.authenticate()
  File "/home/airflow/.local/lib/python3.12/site-packages/kaggle/api/kaggle_api_extended.py", line 181, in authenticate
    raise IOError('Could not find {}. Make sure it\'s located in'
OSError: Could not find kaggle.json. Make sure it's located in /home/airflow/.kaggle. Or use the environment method.
[2024-09-28T03:56:04.381+0000] {logging_mixin.py:190} WARNING - /opt/airflow/dags/covid_gdp_dag.py:35 SyntaxWarning: invalid escape sequence '\D'
[2024-09-28T03:56:04.383+0000] {logging_mixin.py:190} WARNING - /opt/airflow/dags/covid_gdp_dag.py:35 SyntaxWarning: invalid escape sequence '\D'
[2024-09-28T03:56:04.384+0000] {logging_mixin.py:190} WARNING - /opt/airflow/dags/covid_gdp_dag.py:45 SyntaxWarning: invalid escape sequence '\D'
[2024-09-28T03:56:04.386+0000] {processor.py:927} WARNING - No viable dags retrieved from /opt/airflow/dags/covid_gdp_dag.py
[2024-09-28T03:56:04.463+0000] {processor.py:208} INFO - Processing /opt/airflow/dags/covid_gdp_dag.py took 0.196 seconds
[2024-09-28T03:56:05.796+0000] {processor.py:186} INFO - Started process (PID=566) to work on /opt/airflow/dags/covid_gdp_dag.py
[2024-09-28T03:56:05.811+0000] {processor.py:914} INFO - Processing file /opt/airflow/dags/covid_gdp_dag.py for tasks to queue
[2024-09-28T03:56:05.814+0000] {logging_mixin.py:190} INFO - [2024-09-28T03:56:05.813+0000] {dagbag.py:588} INFO - Filling up the DagBag from /opt/airflow/dags/covid_gdp_dag.py
[2024-09-28T03:56:05.945+0000] {logging_mixin.py:190} INFO - [2024-09-28T03:56:05.934+0000] {dagbag.py:387} ERROR - Failed to import: /opt/airflow/dags/covid_gdp_dag.py
Traceback (most recent call last):
  File "/home/airflow/.local/lib/python3.12/site-packages/airflow/models/dagbag.py", line 383, in parse
    loader.exec_module(new_module)
  File "<frozen importlib._bootstrap_external>", line 995, in exec_module
  File "<frozen importlib._bootstrap>", line 488, in _call_with_frames_removed
  File "/opt/airflow/dags/covid_gdp_dag.py", line 7, in <module>
    from common_data_loader import download_world_bank_data, download_kaggle_dataset, load_covid_data, load_gdp_data
  File "/opt/airflow/dags/common_data_loader.py", line 3, in <module>
    import kaggle
  File "/home/airflow/.local/lib/python3.12/site-packages/kaggle/__init__.py", line 23, in <module>
    api.authenticate()
  File "/home/airflow/.local/lib/python3.12/site-packages/kaggle/api/kaggle_api_extended.py", line 181, in authenticate
    raise IOError('Could not find {}. Make sure it\'s located in'
OSError: Could not find kaggle.json. Make sure it's located in /home/airflow/.kaggle. Or use the environment method.
[2024-09-28T03:56:05.952+0000] {logging_mixin.py:190} WARNING - /opt/airflow/dags/covid_gdp_dag.py:35 SyntaxWarning: invalid escape sequence '\D'
[2024-09-28T03:56:05.954+0000] {logging_mixin.py:190} WARNING - /opt/airflow/dags/covid_gdp_dag.py:35 SyntaxWarning: invalid escape sequence '\D'
[2024-09-28T03:56:05.955+0000] {logging_mixin.py:190} WARNING - /opt/airflow/dags/covid_gdp_dag.py:45 SyntaxWarning: invalid escape sequence '\D'
[2024-09-28T03:56:05.956+0000] {processor.py:927} WARNING - No viable dags retrieved from /opt/airflow/dags/covid_gdp_dag.py
[2024-09-28T03:56:05.984+0000] {processor.py:208} INFO - Processing /opt/airflow/dags/covid_gdp_dag.py took 0.201 seconds
[2024-09-28T03:56:21.482+0000] {processor.py:186} INFO - Started process (PID=630) to work on /opt/airflow/dags/covid_gdp_dag.py
[2024-09-28T03:56:21.483+0000] {processor.py:914} INFO - Processing file /opt/airflow/dags/covid_gdp_dag.py for tasks to queue
[2024-09-28T03:56:21.486+0000] {logging_mixin.py:190} INFO - [2024-09-28T03:56:21.486+0000] {dagbag.py:588} INFO - Filling up the DagBag from /opt/airflow/dags/covid_gdp_dag.py
[2024-09-28T03:56:21.501+0000] {logging_mixin.py:190} INFO - [2024-09-28T03:56:21.500+0000] {dagbag.py:387} ERROR - Failed to import: /opt/airflow/dags/covid_gdp_dag.py
Traceback (most recent call last):
  File "/home/airflow/.local/lib/python3.12/site-packages/airflow/models/dagbag.py", line 383, in parse
    loader.exec_module(new_module)
  File "<frozen importlib._bootstrap_external>", line 991, in exec_module
  File "<frozen importlib._bootstrap_external>", line 1129, in get_code
  File "<frozen importlib._bootstrap_external>", line 1059, in source_to_code
  File "<frozen importlib._bootstrap>", line 488, in _call_with_frames_removed
  File "/opt/airflow/dags/covid_gdp_dag.py", line 12
    os.environ['KAGGLE_CONFIG_DIR'] = '"C:\Users\gjpra\.kaggle"'
                                      ^^^^^^^^^^^^^^^^^^^^^^^^^^
SyntaxError: (unicode error) 'unicodeescape' codec can't decode bytes in position 3-4: truncated \UXXXXXXXX escape
[2024-09-28T03:56:21.502+0000] {processor.py:927} WARNING - No viable dags retrieved from /opt/airflow/dags/covid_gdp_dag.py
[2024-09-28T03:56:21.524+0000] {processor.py:208} INFO - Processing /opt/airflow/dags/covid_gdp_dag.py took 0.047 seconds
[2024-09-28T03:56:23.606+0000] {processor.py:186} INFO - Started process (PID=631) to work on /opt/airflow/dags/covid_gdp_dag.py
[2024-09-28T03:56:23.608+0000] {processor.py:914} INFO - Processing file /opt/airflow/dags/covid_gdp_dag.py for tasks to queue
[2024-09-28T03:56:23.611+0000] {logging_mixin.py:190} INFO - [2024-09-28T03:56:23.611+0000] {dagbag.py:588} INFO - Filling up the DagBag from /opt/airflow/dags/covid_gdp_dag.py
[2024-09-28T03:56:23.635+0000] {logging_mixin.py:190} INFO - [2024-09-28T03:56:23.634+0000] {dagbag.py:387} ERROR - Failed to import: /opt/airflow/dags/covid_gdp_dag.py
Traceback (most recent call last):
  File "/home/airflow/.local/lib/python3.12/site-packages/airflow/models/dagbag.py", line 383, in parse
    loader.exec_module(new_module)
  File "<frozen importlib._bootstrap_external>", line 991, in exec_module
  File "<frozen importlib._bootstrap_external>", line 1129, in get_code
  File "<frozen importlib._bootstrap_external>", line 1059, in source_to_code
  File "<frozen importlib._bootstrap>", line 488, in _call_with_frames_removed
  File "/opt/airflow/dags/covid_gdp_dag.py", line 12
    os.environ['KAGGLE_CONFIG_DIR'] = 'C:\Users\gjpra\.kaggle"'
                                      ^^^^^^^^^^^^^^^^^^^^^^^^^
SyntaxError: (unicode error) 'unicodeescape' codec can't decode bytes in position 2-3: truncated \UXXXXXXXX escape
[2024-09-28T03:56:23.636+0000] {processor.py:927} WARNING - No viable dags retrieved from /opt/airflow/dags/covid_gdp_dag.py
[2024-09-28T03:56:23.659+0000] {processor.py:208} INFO - Processing /opt/airflow/dags/covid_gdp_dag.py took 0.060 seconds
[2024-09-28T03:56:25.633+0000] {processor.py:186} INFO - Started process (PID=632) to work on /opt/airflow/dags/covid_gdp_dag.py
[2024-09-28T03:56:25.634+0000] {processor.py:914} INFO - Processing file /opt/airflow/dags/covid_gdp_dag.py for tasks to queue
[2024-09-28T03:56:25.637+0000] {logging_mixin.py:190} INFO - [2024-09-28T03:56:25.636+0000] {dagbag.py:588} INFO - Filling up the DagBag from /opt/airflow/dags/covid_gdp_dag.py
[2024-09-28T03:56:25.651+0000] {logging_mixin.py:190} INFO - [2024-09-28T03:56:25.650+0000] {dagbag.py:387} ERROR - Failed to import: /opt/airflow/dags/covid_gdp_dag.py
Traceback (most recent call last):
  File "/home/airflow/.local/lib/python3.12/site-packages/airflow/models/dagbag.py", line 383, in parse
    loader.exec_module(new_module)
  File "<frozen importlib._bootstrap_external>", line 991, in exec_module
  File "<frozen importlib._bootstrap_external>", line 1129, in get_code
  File "<frozen importlib._bootstrap_external>", line 1059, in source_to_code
  File "<frozen importlib._bootstrap>", line 488, in _call_with_frames_removed
  File "/opt/airflow/dags/covid_gdp_dag.py", line 12
    os.environ['KAGGLE_CONFIG_DIR'] = 'C:\Users\gjpra\.kaggle'
                                      ^^^^^^^^^^^^^^^^^^^^^^^^
SyntaxError: (unicode error) 'unicodeescape' codec can't decode bytes in position 2-3: truncated \UXXXXXXXX escape
[2024-09-28T03:56:25.652+0000] {processor.py:927} WARNING - No viable dags retrieved from /opt/airflow/dags/covid_gdp_dag.py
[2024-09-28T03:56:25.677+0000] {processor.py:208} INFO - Processing /opt/airflow/dags/covid_gdp_dag.py took 0.050 seconds
[2024-09-28T03:56:43.256+0000] {processor.py:186} INFO - Started process (PID=681) to work on /opt/airflow/dags/covid_gdp_dag.py
[2024-09-28T03:56:43.257+0000] {processor.py:914} INFO - Processing file /opt/airflow/dags/covid_gdp_dag.py for tasks to queue
[2024-09-28T03:56:43.260+0000] {logging_mixin.py:190} INFO - [2024-09-28T03:56:43.260+0000] {dagbag.py:588} INFO - Filling up the DagBag from /opt/airflow/dags/covid_gdp_dag.py
[2024-09-28T03:56:43.280+0000] {logging_mixin.py:190} INFO - [2024-09-28T03:56:43.279+0000] {dagbag.py:387} ERROR - Failed to import: /opt/airflow/dags/covid_gdp_dag.py
Traceback (most recent call last):
  File "/home/airflow/.local/lib/python3.12/site-packages/airflow/models/dagbag.py", line 383, in parse
    loader.exec_module(new_module)
  File "<frozen importlib._bootstrap_external>", line 991, in exec_module
  File "<frozen importlib._bootstrap_external>", line 1129, in get_code
  File "<frozen importlib._bootstrap_external>", line 1059, in source_to_code
  File "<frozen importlib._bootstrap>", line 488, in _call_with_frames_removed
  File "/opt/airflow/dags/covid_gdp_dag.py", line 12
    os.environ['KAGGLE_CONFIG_DIR'] = 'C:\Users\gjpra\.kaggle'
                                      ^^^^^^^^^^^^^^^^^^^^^^^^
SyntaxError: (unicode error) 'unicodeescape' codec can't decode bytes in position 2-3: truncated \UXXXXXXXX escape
[2024-09-28T03:56:43.282+0000] {processor.py:927} WARNING - No viable dags retrieved from /opt/airflow/dags/covid_gdp_dag.py
[2024-09-28T03:56:43.318+0000] {processor.py:208} INFO - Processing /opt/airflow/dags/covid_gdp_dag.py took 0.068 seconds
[2024-09-28T04:03:02.056+0000] {processor.py:186} INFO - Started process (PID=63) to work on /opt/airflow/dags/covid_gdp_dag.py
[2024-09-28T04:03:02.058+0000] {processor.py:914} INFO - Processing file /opt/airflow/dags/covid_gdp_dag.py for tasks to queue
[2024-09-28T04:03:02.065+0000] {logging_mixin.py:190} INFO - [2024-09-28T04:03:02.064+0000] {dagbag.py:588} INFO - Filling up the DagBag from /opt/airflow/dags/covid_gdp_dag.py
[2024-09-28T04:03:02.095+0000] {logging_mixin.py:190} INFO - [2024-09-28T04:03:02.093+0000] {dagbag.py:387} ERROR - Failed to import: /opt/airflow/dags/covid_gdp_dag.py
Traceback (most recent call last):
  File "/home/airflow/.local/lib/python3.12/site-packages/airflow/models/dagbag.py", line 383, in parse
    loader.exec_module(new_module)
  File "<frozen importlib._bootstrap_external>", line 991, in exec_module
  File "<frozen importlib._bootstrap_external>", line 1129, in get_code
  File "<frozen importlib._bootstrap_external>", line 1059, in source_to_code
  File "<frozen importlib._bootstrap>", line 488, in _call_with_frames_removed
  File "/opt/airflow/dags/covid_gdp_dag.py", line 12
    os.environ['KAGGLE_CONFIG_DIR'] = 'C:\Users\gjpra\.kaggle'
                                      ^^^^^^^^^^^^^^^^^^^^^^^^
SyntaxError: (unicode error) 'unicodeescape' codec can't decode bytes in position 2-3: truncated \UXXXXXXXX escape
[2024-09-28T04:03:02.097+0000] {processor.py:927} WARNING - No viable dags retrieved from /opt/airflow/dags/covid_gdp_dag.py
[2024-09-28T04:03:02.189+0000] {processor.py:208} INFO - Processing /opt/airflow/dags/covid_gdp_dag.py took 0.161 seconds
[2024-09-28T04:03:32.382+0000] {processor.py:186} INFO - Started process (PID=126) to work on /opt/airflow/dags/covid_gdp_dag.py
[2024-09-28T04:03:32.383+0000] {processor.py:914} INFO - Processing file /opt/airflow/dags/covid_gdp_dag.py for tasks to queue
[2024-09-28T04:03:32.385+0000] {logging_mixin.py:190} INFO - [2024-09-28T04:03:32.385+0000] {dagbag.py:588} INFO - Filling up the DagBag from /opt/airflow/dags/covid_gdp_dag.py
[2024-09-28T04:03:32.412+0000] {logging_mixin.py:190} INFO - [2024-09-28T04:03:32.405+0000] {dagbag.py:387} ERROR - Failed to import: /opt/airflow/dags/covid_gdp_dag.py
Traceback (most recent call last):
  File "/home/airflow/.local/lib/python3.12/site-packages/airflow/models/dagbag.py", line 383, in parse
    loader.exec_module(new_module)
  File "<frozen importlib._bootstrap_external>", line 991, in exec_module
  File "<frozen importlib._bootstrap_external>", line 1129, in get_code
  File "<frozen importlib._bootstrap_external>", line 1059, in source_to_code
  File "<frozen importlib._bootstrap>", line 488, in _call_with_frames_removed
  File "/opt/airflow/dags/covid_gdp_dag.py", line 12
    os.environ['KAGGLE_CONFIG_DIR'] = 'C:\Users\gjpra\.kaggle'
                                      ^^^^^^^^^^^^^^^^^^^^^^^^
SyntaxError: (unicode error) 'unicodeescape' codec can't decode bytes in position 2-3: truncated \UXXXXXXXX escape
[2024-09-28T04:03:32.413+0000] {processor.py:927} WARNING - No viable dags retrieved from /opt/airflow/dags/covid_gdp_dag.py
[2024-09-28T04:03:32.438+0000] {processor.py:208} INFO - Processing /opt/airflow/dags/covid_gdp_dag.py took 0.062 seconds
[2024-09-28T04:04:02.633+0000] {processor.py:186} INFO - Started process (PID=189) to work on /opt/airflow/dags/covid_gdp_dag.py
[2024-09-28T04:04:02.634+0000] {processor.py:914} INFO - Processing file /opt/airflow/dags/covid_gdp_dag.py for tasks to queue
[2024-09-28T04:04:02.639+0000] {logging_mixin.py:190} INFO - [2024-09-28T04:04:02.638+0000] {dagbag.py:588} INFO - Filling up the DagBag from /opt/airflow/dags/covid_gdp_dag.py
[2024-09-28T04:04:02.658+0000] {logging_mixin.py:190} INFO - [2024-09-28T04:04:02.657+0000] {dagbag.py:387} ERROR - Failed to import: /opt/airflow/dags/covid_gdp_dag.py
Traceback (most recent call last):
  File "/home/airflow/.local/lib/python3.12/site-packages/airflow/models/dagbag.py", line 383, in parse
    loader.exec_module(new_module)
  File "<frozen importlib._bootstrap_external>", line 991, in exec_module
  File "<frozen importlib._bootstrap_external>", line 1129, in get_code
  File "<frozen importlib._bootstrap_external>", line 1059, in source_to_code
  File "<frozen importlib._bootstrap>", line 488, in _call_with_frames_removed
  File "/opt/airflow/dags/covid_gdp_dag.py", line 12
    os.environ['KAGGLE_CONFIG_DIR'] = 'C:\Users\gjpra\.kaggle'
                                      ^^^^^^^^^^^^^^^^^^^^^^^^
SyntaxError: (unicode error) 'unicodeescape' codec can't decode bytes in position 2-3: truncated \UXXXXXXXX escape
[2024-09-28T04:04:02.659+0000] {processor.py:927} WARNING - No viable dags retrieved from /opt/airflow/dags/covid_gdp_dag.py
[2024-09-28T04:04:02.789+0000] {processor.py:208} INFO - Processing /opt/airflow/dags/covid_gdp_dag.py took 0.164 seconds
[2024-09-28T04:04:33.144+0000] {processor.py:186} INFO - Started process (PID=252) to work on /opt/airflow/dags/covid_gdp_dag.py
[2024-09-28T04:04:33.145+0000] {processor.py:914} INFO - Processing file /opt/airflow/dags/covid_gdp_dag.py for tasks to queue
[2024-09-28T04:04:33.148+0000] {logging_mixin.py:190} INFO - [2024-09-28T04:04:33.147+0000] {dagbag.py:588} INFO - Filling up the DagBag from /opt/airflow/dags/covid_gdp_dag.py
[2024-09-28T04:04:33.161+0000] {logging_mixin.py:190} INFO - [2024-09-28T04:04:33.160+0000] {dagbag.py:387} ERROR - Failed to import: /opt/airflow/dags/covid_gdp_dag.py
Traceback (most recent call last):
  File "/home/airflow/.local/lib/python3.12/site-packages/airflow/models/dagbag.py", line 383, in parse
    loader.exec_module(new_module)
  File "<frozen importlib._bootstrap_external>", line 991, in exec_module
  File "<frozen importlib._bootstrap_external>", line 1129, in get_code
  File "<frozen importlib._bootstrap_external>", line 1059, in source_to_code
  File "<frozen importlib._bootstrap>", line 488, in _call_with_frames_removed
  File "/opt/airflow/dags/covid_gdp_dag.py", line 12
    os.environ['KAGGLE_CONFIG_DIR'] = 'C:\Users\gjpra\.kaggle'
                                      ^^^^^^^^^^^^^^^^^^^^^^^^
SyntaxError: (unicode error) 'unicodeescape' codec can't decode bytes in position 2-3: truncated \UXXXXXXXX escape
[2024-09-28T04:04:33.162+0000] {processor.py:927} WARNING - No viable dags retrieved from /opt/airflow/dags/covid_gdp_dag.py
[2024-09-28T04:04:33.189+0000] {processor.py:208} INFO - Processing /opt/airflow/dags/covid_gdp_dag.py took 0.050 seconds
[2024-09-28T04:04:46.087+0000] {processor.py:186} INFO - Started process (PID=315) to work on /opt/airflow/dags/covid_gdp_dag.py
[2024-09-28T04:04:46.088+0000] {processor.py:914} INFO - Processing file /opt/airflow/dags/covid_gdp_dag.py for tasks to queue
[2024-09-28T04:04:46.091+0000] {logging_mixin.py:190} INFO - [2024-09-28T04:04:46.091+0000] {dagbag.py:588} INFO - Filling up the DagBag from /opt/airflow/dags/covid_gdp_dag.py
[2024-09-28T04:04:46.318+0000] {logging_mixin.py:190} INFO - [2024-09-28T04:04:46.306+0000] {dagbag.py:387} ERROR - Failed to import: /opt/airflow/dags/covid_gdp_dag.py
Traceback (most recent call last):
  File "/home/airflow/.local/lib/python3.12/site-packages/airflow/models/dagbag.py", line 383, in parse
    loader.exec_module(new_module)
  File "<frozen importlib._bootstrap_external>", line 995, in exec_module
  File "<frozen importlib._bootstrap>", line 488, in _call_with_frames_removed
  File "/opt/airflow/dags/covid_gdp_dag.py", line 7, in <module>
    from common_data_loader import download_world_bank_data, download_kaggle_dataset, load_covid_data, load_gdp_data
  File "/opt/airflow/dags/common_data_loader.py", line 3, in <module>
    import kaggle
  File "/home/airflow/.local/lib/python3.12/site-packages/kaggle/__init__.py", line 23, in <module>
    api.authenticate()
  File "/home/airflow/.local/lib/python3.12/site-packages/kaggle/api/kaggle_api_extended.py", line 181, in authenticate
    raise IOError('Could not find {}. Make sure it\'s located in'
OSError: Could not find kaggle.json. Make sure it's located in /home/airflow/.kaggle. Or use the environment method.
[2024-09-28T04:04:46.321+0000] {logging_mixin.py:190} WARNING - /opt/airflow/dags/covid_gdp_dag.py:36 SyntaxWarning: invalid escape sequence '\D'
[2024-09-28T04:04:46.323+0000] {logging_mixin.py:190} WARNING - /opt/airflow/dags/covid_gdp_dag.py:36 SyntaxWarning: invalid escape sequence '\D'
[2024-09-28T04:04:46.324+0000] {logging_mixin.py:190} WARNING - /opt/airflow/dags/covid_gdp_dag.py:46 SyntaxWarning: invalid escape sequence '\D'
[2024-09-28T04:04:46.325+0000] {processor.py:927} WARNING - No viable dags retrieved from /opt/airflow/dags/covid_gdp_dag.py
[2024-09-28T04:04:46.349+0000] {processor.py:208} INFO - Processing /opt/airflow/dags/covid_gdp_dag.py took 0.268 seconds
[2024-09-28T04:04:47.140+0000] {processor.py:186} INFO - Started process (PID=327) to work on /opt/airflow/dags/covid_gdp_dag.py
[2024-09-28T04:04:47.142+0000] {processor.py:914} INFO - Processing file /opt/airflow/dags/covid_gdp_dag.py for tasks to queue
[2024-09-28T04:04:47.145+0000] {logging_mixin.py:190} INFO - [2024-09-28T04:04:47.145+0000] {dagbag.py:588} INFO - Filling up the DagBag from /opt/airflow/dags/covid_gdp_dag.py
[2024-09-28T04:04:47.273+0000] {logging_mixin.py:190} INFO - [2024-09-28T04:04:47.262+0000] {dagbag.py:387} ERROR - Failed to import: /opt/airflow/dags/covid_gdp_dag.py
Traceback (most recent call last):
  File "/home/airflow/.local/lib/python3.12/site-packages/airflow/models/dagbag.py", line 383, in parse
    loader.exec_module(new_module)
  File "<frozen importlib._bootstrap_external>", line 995, in exec_module
  File "<frozen importlib._bootstrap>", line 488, in _call_with_frames_removed
  File "/opt/airflow/dags/covid_gdp_dag.py", line 7, in <module>
    from common_data_loader import download_world_bank_data, download_kaggle_dataset, load_covid_data, load_gdp_data
  File "/opt/airflow/dags/common_data_loader.py", line 3, in <module>
    import kaggle
  File "/home/airflow/.local/lib/python3.12/site-packages/kaggle/__init__.py", line 23, in <module>
    api.authenticate()
  File "/home/airflow/.local/lib/python3.12/site-packages/kaggle/api/kaggle_api_extended.py", line 181, in authenticate
    raise IOError('Could not find {}. Make sure it\'s located in'
OSError: Could not find kaggle.json. Make sure it's located in /home/airflow/.kaggle. Or use the environment method.
[2024-09-28T04:04:47.276+0000] {logging_mixin.py:190} WARNING - /opt/airflow/dags/covid_gdp_dag.py:35 SyntaxWarning: invalid escape sequence '\D'
[2024-09-28T04:04:47.278+0000] {logging_mixin.py:190} WARNING - /opt/airflow/dags/covid_gdp_dag.py:35 SyntaxWarning: invalid escape sequence '\D'
[2024-09-28T04:04:47.279+0000] {logging_mixin.py:190} WARNING - /opt/airflow/dags/covid_gdp_dag.py:45 SyntaxWarning: invalid escape sequence '\D'
[2024-09-28T04:04:47.280+0000] {processor.py:927} WARNING - No viable dags retrieved from /opt/airflow/dags/covid_gdp_dag.py
[2024-09-28T04:04:47.329+0000] {processor.py:208} INFO - Processing /opt/airflow/dags/covid_gdp_dag.py took 0.195 seconds
[2024-09-28T04:05:49.296+0000] {processor.py:186} INFO - Started process (PID=56) to work on /opt/airflow/dags/covid_gdp_dag.py
[2024-09-28T04:05:49.297+0000] {processor.py:914} INFO - Processing file /opt/airflow/dags/covid_gdp_dag.py for tasks to queue
[2024-09-28T04:05:49.301+0000] {logging_mixin.py:190} INFO - [2024-09-28T04:05:49.301+0000] {dagbag.py:588} INFO - Filling up the DagBag from /opt/airflow/dags/covid_gdp_dag.py
[2024-09-28T04:05:49.578+0000] {logging_mixin.py:190} INFO - [2024-09-28T04:05:49.534+0000] {dagbag.py:387} ERROR - Failed to import: /opt/airflow/dags/covid_gdp_dag.py
Traceback (most recent call last):
  File "/home/airflow/.local/lib/python3.12/site-packages/airflow/models/dagbag.py", line 383, in parse
    loader.exec_module(new_module)
  File "<frozen importlib._bootstrap_external>", line 995, in exec_module
  File "<frozen importlib._bootstrap>", line 488, in _call_with_frames_removed
  File "/opt/airflow/dags/covid_gdp_dag.py", line 7, in <module>
    from common_data_loader import download_world_bank_data, download_kaggle_dataset, load_covid_data, load_gdp_data
  File "/opt/airflow/dags/common_data_loader.py", line 3, in <module>
    import kaggle
  File "/home/airflow/.local/lib/python3.12/site-packages/kaggle/__init__.py", line 23, in <module>
    api.authenticate()
  File "/home/airflow/.local/lib/python3.12/site-packages/kaggle/api/kaggle_api_extended.py", line 181, in authenticate
    raise IOError('Could not find {}. Make sure it\'s located in'
OSError: Could not find kaggle.json. Make sure it's located in /home/airflow/.kaggle. Or use the environment method.
[2024-09-28T04:05:49.579+0000] {processor.py:927} WARNING - No viable dags retrieved from /opt/airflow/dags/covid_gdp_dag.py
[2024-09-28T04:05:49.624+0000] {processor.py:208} INFO - Processing /opt/airflow/dags/covid_gdp_dag.py took 0.336 seconds
[2024-09-28T04:06:19.698+0000] {processor.py:186} INFO - Started process (PID=130) to work on /opt/airflow/dags/covid_gdp_dag.py
[2024-09-28T04:06:19.700+0000] {processor.py:914} INFO - Processing file /opt/airflow/dags/covid_gdp_dag.py for tasks to queue
[2024-09-28T04:06:19.702+0000] {logging_mixin.py:190} INFO - [2024-09-28T04:06:19.702+0000] {dagbag.py:588} INFO - Filling up the DagBag from /opt/airflow/dags/covid_gdp_dag.py
[2024-09-28T04:06:19.800+0000] {logging_mixin.py:190} INFO - [2024-09-28T04:06:19.792+0000] {dagbag.py:387} ERROR - Failed to import: /opt/airflow/dags/covid_gdp_dag.py
Traceback (most recent call last):
  File "/home/airflow/.local/lib/python3.12/site-packages/airflow/models/dagbag.py", line 383, in parse
    loader.exec_module(new_module)
  File "<frozen importlib._bootstrap_external>", line 995, in exec_module
  File "<frozen importlib._bootstrap>", line 488, in _call_with_frames_removed
  File "/opt/airflow/dags/covid_gdp_dag.py", line 7, in <module>
    from common_data_loader import download_world_bank_data, download_kaggle_dataset, load_covid_data, load_gdp_data
  File "/opt/airflow/dags/common_data_loader.py", line 3, in <module>
    import kaggle
  File "/home/airflow/.local/lib/python3.12/site-packages/kaggle/__init__.py", line 23, in <module>
    api.authenticate()
  File "/home/airflow/.local/lib/python3.12/site-packages/kaggle/api/kaggle_api_extended.py", line 181, in authenticate
    raise IOError('Could not find {}. Make sure it\'s located in'
OSError: Could not find kaggle.json. Make sure it's located in /home/airflow/.kaggle. Or use the environment method.
[2024-09-28T04:06:19.801+0000] {processor.py:927} WARNING - No viable dags retrieved from /opt/airflow/dags/covid_gdp_dag.py
[2024-09-28T04:06:19.828+0000] {processor.py:208} INFO - Processing /opt/airflow/dags/covid_gdp_dag.py took 0.135 seconds
[2024-09-28T04:06:50.139+0000] {processor.py:186} INFO - Started process (PID=204) to work on /opt/airflow/dags/covid_gdp_dag.py
[2024-09-28T04:06:50.140+0000] {processor.py:914} INFO - Processing file /opt/airflow/dags/covid_gdp_dag.py for tasks to queue
[2024-09-28T04:06:50.143+0000] {logging_mixin.py:190} INFO - [2024-09-28T04:06:50.142+0000] {dagbag.py:588} INFO - Filling up the DagBag from /opt/airflow/dags/covid_gdp_dag.py
[2024-09-28T04:06:50.251+0000] {logging_mixin.py:190} INFO - [2024-09-28T04:06:50.242+0000] {dagbag.py:387} ERROR - Failed to import: /opt/airflow/dags/covid_gdp_dag.py
Traceback (most recent call last):
  File "/home/airflow/.local/lib/python3.12/site-packages/airflow/models/dagbag.py", line 383, in parse
    loader.exec_module(new_module)
  File "<frozen importlib._bootstrap_external>", line 995, in exec_module
  File "<frozen importlib._bootstrap>", line 488, in _call_with_frames_removed
  File "/opt/airflow/dags/covid_gdp_dag.py", line 7, in <module>
    from common_data_loader import download_world_bank_data, download_kaggle_dataset, load_covid_data, load_gdp_data
  File "/opt/airflow/dags/common_data_loader.py", line 3, in <module>
    import kaggle
  File "/home/airflow/.local/lib/python3.12/site-packages/kaggle/__init__.py", line 23, in <module>
    api.authenticate()
  File "/home/airflow/.local/lib/python3.12/site-packages/kaggle/api/kaggle_api_extended.py", line 181, in authenticate
    raise IOError('Could not find {}. Make sure it\'s located in'
OSError: Could not find kaggle.json. Make sure it's located in /home/airflow/.kaggle. Or use the environment method.
[2024-09-28T04:06:50.252+0000] {processor.py:927} WARNING - No viable dags retrieved from /opt/airflow/dags/covid_gdp_dag.py
[2024-09-28T04:06:50.276+0000] {processor.py:208} INFO - Processing /opt/airflow/dags/covid_gdp_dag.py took 0.142 seconds
[2024-09-28T04:07:21.271+0000] {processor.py:186} INFO - Started process (PID=278) to work on /opt/airflow/dags/covid_gdp_dag.py
[2024-09-28T04:07:21.272+0000] {processor.py:914} INFO - Processing file /opt/airflow/dags/covid_gdp_dag.py for tasks to queue
[2024-09-28T04:07:21.274+0000] {logging_mixin.py:190} INFO - [2024-09-28T04:07:21.274+0000] {dagbag.py:588} INFO - Filling up the DagBag from /opt/airflow/dags/covid_gdp_dag.py
[2024-09-28T04:07:21.366+0000] {logging_mixin.py:190} INFO - [2024-09-28T04:07:21.358+0000] {dagbag.py:387} ERROR - Failed to import: /opt/airflow/dags/covid_gdp_dag.py
Traceback (most recent call last):
  File "/home/airflow/.local/lib/python3.12/site-packages/airflow/models/dagbag.py", line 383, in parse
    loader.exec_module(new_module)
  File "<frozen importlib._bootstrap_external>", line 995, in exec_module
  File "<frozen importlib._bootstrap>", line 488, in _call_with_frames_removed
  File "/opt/airflow/dags/covid_gdp_dag.py", line 7, in <module>
    from common_data_loader import download_world_bank_data, download_kaggle_dataset, load_covid_data, load_gdp_data
  File "/opt/airflow/dags/common_data_loader.py", line 3, in <module>
    import kaggle
  File "/home/airflow/.local/lib/python3.12/site-packages/kaggle/__init__.py", line 23, in <module>
    api.authenticate()
  File "/home/airflow/.local/lib/python3.12/site-packages/kaggle/api/kaggle_api_extended.py", line 181, in authenticate
    raise IOError('Could not find {}. Make sure it\'s located in'
OSError: Could not find kaggle.json. Make sure it's located in /home/airflow/.kaggle. Or use the environment method.
[2024-09-28T04:07:21.368+0000] {processor.py:927} WARNING - No viable dags retrieved from /opt/airflow/dags/covid_gdp_dag.py
[2024-09-28T04:07:21.390+0000] {processor.py:208} INFO - Processing /opt/airflow/dags/covid_gdp_dag.py took 0.124 seconds
[2024-09-28T04:07:51.495+0000] {processor.py:186} INFO - Started process (PID=352) to work on /opt/airflow/dags/covid_gdp_dag.py
[2024-09-28T04:07:51.496+0000] {processor.py:914} INFO - Processing file /opt/airflow/dags/covid_gdp_dag.py for tasks to queue
[2024-09-28T04:07:51.498+0000] {logging_mixin.py:190} INFO - [2024-09-28T04:07:51.498+0000] {dagbag.py:588} INFO - Filling up the DagBag from /opt/airflow/dags/covid_gdp_dag.py
[2024-09-28T04:07:51.580+0000] {logging_mixin.py:190} INFO - [2024-09-28T04:07:51.571+0000] {dagbag.py:387} ERROR - Failed to import: /opt/airflow/dags/covid_gdp_dag.py
Traceback (most recent call last):
  File "/home/airflow/.local/lib/python3.12/site-packages/airflow/models/dagbag.py", line 383, in parse
    loader.exec_module(new_module)
  File "<frozen importlib._bootstrap_external>", line 995, in exec_module
  File "<frozen importlib._bootstrap>", line 488, in _call_with_frames_removed
  File "/opt/airflow/dags/covid_gdp_dag.py", line 7, in <module>
    from common_data_loader import download_world_bank_data, download_kaggle_dataset, load_covid_data, load_gdp_data
  File "/opt/airflow/dags/common_data_loader.py", line 3, in <module>
    import kaggle
  File "/home/airflow/.local/lib/python3.12/site-packages/kaggle/__init__.py", line 23, in <module>
    api.authenticate()
  File "/home/airflow/.local/lib/python3.12/site-packages/kaggle/api/kaggle_api_extended.py", line 181, in authenticate
    raise IOError('Could not find {}. Make sure it\'s located in'
OSError: Could not find kaggle.json. Make sure it's located in /home/airflow/.kaggle. Or use the environment method.
[2024-09-28T04:07:51.581+0000] {processor.py:927} WARNING - No viable dags retrieved from /opt/airflow/dags/covid_gdp_dag.py
[2024-09-28T04:07:51.604+0000] {processor.py:208} INFO - Processing /opt/airflow/dags/covid_gdp_dag.py took 0.114 seconds
